Workbook

Sheet Resumo
A1: Jalecon v2 · Resumo comparativo
A2: Cenário: | B2: =Premissas!$D$3
A3: Troque o cenário na aba Premissas, célula C3. Valores em reais nominais.
A5: Modelo A: software por assinatura
A6: Indicador | B6: Ano 1 | C6: Ano 2 | D6: Ano 3 | E6: Ano 4 | F6: Ano 5 | G6: Ano 6 | H6: Ano 7
A7: Clientes ativos (fim do ano) | B7: ='Modelo A'!N39 | C7: ='Modelo A'!Z39 | D7: ='Modelo A'!AL39 | E7: ='Modelo A'!AX39 | F7: ='Modelo A'!BJ39 | G7: ='Modelo A'!BV39 | H7: ='Modelo A'!CH39
A8: Receita bruta | B8: =SUMIF('Modelo A'!$C$3:$CH$3,1,'Modelo A'!$C$45:$CH$45) | C8: =SUMIF('Modelo A'!$C$3:$CH$3,2,'Modelo A'!$C$45:$CH$45) | D8: =SUMIF('Modelo A'!$C$3:$CH$3,3,'Modelo A'!$C$45:$CH$45) | E8: =SUMIF('Modelo A'!$C$3:$CH$3,4,'Modelo A'!$C$45:$CH$45) | F8: =SUMIF('Modelo A'!$C$3:$CH$3,5,'Modelo A'!$C$45:$CH$45) | G8: =SUMIF('Modelo A'!$C$3:$CH$3,6,'Modelo A'!$C$45:$CH$45) | H8: =SUMIF('Modelo A'!$C$3:$CH$3,7,'Modelo A'!$C$45:$CH$45)
A9: Receita recorrente anualizada (fim do ano) | B9: ='Modelo A'!N47 | C9: ='Modelo A'!Z47 | D9: ='Modelo A'!AL47 | E9: ='Modelo A'!AX47 | F9: ='Modelo A'!BJ47 | G9: ='Modelo A'!BV47 | H9: ='Modelo A'!CH47
A10: Lucro bruto | B10: =SUMIF('Modelo A'!$C$3:$CH$3,1,'Modelo A'!$C$57:$CH$57) | C10: =SUMIF('Modelo A'!$C$3:$CH$3,2,'Modelo A'!$C$57:$CH$57) | D10: =SUMIF('Modelo A'!$C$3:$CH$3,3,'Modelo A'!$C$57:$CH$57) | E10: =SUMIF('Modelo A'!$C$3:$CH$3,4,'Modelo A'!$C$57:$CH$57) | F10: =SUMIF('Modelo A'!$C$3:$CH$3,5,'Modelo A'!$C$57:$CH$57) | G10: =SUMIF('Modelo A'!$C$3:$CH$3,6,'Modelo A'!$C$57:$CH$57) | H10: =SUMIF('Modelo A'!$C$3:$CH$3,7,'Modelo A'!$C$57:$CH$57)
A11: Margem bruta (sobre a receita líquida) | B11: =IFERROR(SUMIF('Modelo A'!$C$3:$CH$3,1,'Modelo A'!$C$57:$CH$57)/SUMIF('Modelo A'!$C$3:$CH$3,1,'Modelo A'!$C$50:$CH$50),0) | C11: =IFERROR(SUMIF('Modelo A'!$C$3:$CH$3,2,'Modelo A'!$C$57:$CH$57)/SUMIF('Modelo A'!$C$3:$CH$3,2,'Modelo A'!$C$50:$CH$50),0) | D11: =IFERROR(SUMIF('Modelo A'!$C$3:$CH$3,3,'Modelo A'!$C$57:$CH$57)/SUMIF('Modelo A'!$C$3:$CH$3,3,'Modelo A'!$C$50:$CH$50),0) | E11: =IFERROR(SUMIF('Modelo A'!$C$3:$CH$3,4,'Modelo A'!$C$57:$CH$57)/SUMIF('Modelo A'!$C$3:$CH$3,4,'Modelo A'!$C$50:$CH$50),0) | F11: =IFERROR(SUMIF('Modelo A'!$C$3:$CH$3,5,'Modelo A'!$C$57:$CH$57)/SUMIF('Modelo A'!$C$3:$CH$3,5,'Modelo A'!$C$50:$CH$50),0) | G11: =IFERROR(SUMIF('Modelo A'!$C$3:$CH$3,6,'Modelo A'!$C$57:$CH$57)/SUMIF('Modelo A'!$C$3:$CH$3,6,'Modelo A'!$C$50:$CH$50),0) | H11: =IFERROR(SUMIF('Modelo A'!$C$3:$CH$3,7,'Modelo A'!$C$57:$CH$57)/SUMIF('Modelo A'!$C$3:$CH$3,7,'Modelo A'!$C$50:$CH$50),0)
A12: EBITDA | B12: =SUMIF('Modelo A'!$C$3:$CH$3,1,'Modelo A'!$C$73:$CH$73) | C12: =SUMIF('Modelo A'!$C$3:$CH$3,2,'Modelo A'!$C$73:$CH$73) | D12: =SUMIF('Modelo A'!$C$3:$CH$3,3,'Modelo A'!$C$73:$CH$73) | E12: =SUMIF('Modelo A'!$C$3:$CH$3,4,'Modelo A'!$C$73:$CH$73) | F12: =SUMIF('Modelo A'!$C$3:$CH$3,5,'Modelo A'!$C$73:$CH$73) | G12: =SUMIF('Modelo A'!$C$3:$CH$3,6,'Modelo A'!$C$73:$CH$73) | H12: =SUMIF('Modelo A'!$C$3:$CH$3,7,'Modelo A'!$C$73:$CH$73)
A13: Caixa acumulado sem captação (fim do ano) | B13: ='Modelo A'!N74 | C13: ='Modelo A'!Z74 | D13: ='Modelo A'!AL74 | E13: ='Modelo A'!AX74 | F13: ='Modelo A'!BJ74 | G13: ='Modelo A'!BV74 | H13: ='Modelo A'!CH74
A14: Pessoas (fim do ano) | B14: ='Modelo A'!N77 | C14: ='Modelo A'!Z77 | D14: ='Modelo A'!AL77 | E14: ='Modelo A'!AX77 | F14: ='Modelo A'!BJ77 | G14: ='Modelo A'!BV77 | H14: ='Modelo A'!CH77
A15: Participação no mercado endereçável (fim do ano) | B15: ='Modelo A'!N41 | C15: ='Modelo A'!Z41 | D15: ='Modelo A'!AL41 | E15: ='Modelo A'!AX41 | F15: ='Modelo A'!BJ41 | G15: ='Modelo A'!BV41 | H15: ='Modelo A'!CH41
A17: Modelo B: agência operada por agentes
A18: Indicador | B18: Ano 1 | C18: Ano 2 | D18: Ano 3 | E18: Ano 4 | F18: Ano 5 | G18: Ano 6 | H18: Ano 7
A19: Clientes ativos (fim do ano) | B19: ='Modelo B'!N33 | C19: ='Modelo B'!Z33 | D19: ='Modelo B'!AL33 | E19: ='Modelo B'!AX33 | F19: ='Modelo B'!BJ33 | G19: ='Modelo B'!BV33 | H19: ='Modelo B'!CH33
A20: Receita bruta | B20: =SUMIF('Modelo B'!$C$3:$CH$3,1,'Modelo B'!$C$39:$CH$39) | C20: =SUMIF('Modelo B'!$C$3:$CH$3,2,'Modelo B'!$C$39:$CH$39) | D20: =SUMIF('Modelo B'!$C$3:$CH$3,3,'Modelo B'!$C$39:$CH$39) | E20: =SUMIF('Modelo B'!$C$3:$CH$3,4,'Modelo B'!$C$39:$CH$39) | F20: =SUMIF('Modelo B'!$C$3:$CH$3,5,'Modelo B'!$C$39:$CH$39) | G20: =SUMIF('Modelo B'!$C$3:$CH$3,6,'Modelo B'!$C$39:$CH$39) | H20: =SUMIF('Modelo B'!$C$3:$CH$3,7,'Modelo B'!$C$39:$CH$39)
A21: Receita recorrente anualizada (fim do ano) | B21: ='Modelo B'!N41 | C21: ='Modelo B'!Z41 | D21: ='Modelo B'!AL41 | E21: ='Modelo B'!AX41 | F21: ='Modelo B'!BJ41 | G21: ='Modelo B'!BV41 | H21: ='Modelo B'!CH41
A22: Lucro bruto | B22: =SUMIF('Modelo B'!$C$3:$CH$3,1,'Modelo B'!$C$51:$CH$51) | C22: =SUMIF('Modelo B'!$C$3:$CH$3,2,'Modelo B'!$C$51:$CH$51) | D22: =SUMIF('Modelo B'!$C$3:$CH$3,3,'Modelo B'!$C$51:$CH$51) | E22: =SUMIF('Modelo B'!$C$3:$CH$3,4,'Modelo B'!$C$51:$CH$51) | F22: =SUMIF('Modelo B'!$C$3:$CH$3,5,'Modelo B'!$C$51:$CH$51) | G22: =SUMIF('Modelo B'!$C$3:$CH$3,6,'Modelo B'!$C$51:$CH$51) | H22: =SUMIF('Modelo B'!$C$3:$CH$3,7,'Modelo B'!$C$51:$CH$51)
A23: Margem bruta (sobre a receita líquida) | B23: =IFERROR(SUMIF('Modelo B'!$C$3:$CH$3,1,'Modelo B'!$C$51:$CH$51)/SUMIF('Modelo B'!$C$3:$CH$3,1,'Modelo B'!$C$44:$CH$44),0) | C23: =IFERROR(SUMIF('Modelo B'!$C$3:$CH$3,2,'Modelo B'!$C$51:$CH$51)/SUMIF('Modelo B'!$C$3:$CH$3,2,'Modelo B'!$C$44:$CH$44),0) | D23: =IFERROR(SUMIF('Modelo B'!$C$3:$CH$3,3,'Modelo B'!$C$51:$CH$51)/SUMIF('Modelo B'!$C$3:$CH$3,3,'Modelo B'!$C$44:$CH$44),0) | E23: =IFERROR(SUMIF('Modelo B'!$C$3:$CH$3,4,'Modelo B'!$C$51:$CH$51)/SUMIF('Modelo B'!$C$3:$CH$3,4,'Modelo B'!$C$44:$CH$44),0) | F23: =IFERROR(SUMIF('Modelo B'!$C$3:$CH$3,5,'Modelo B'!$C$51:$CH$51)/SUMIF('Modelo B'!$C$3:$CH$3,5,'Modelo B'!$C$44:$CH$44),0) | G23: =IFERROR(SUMIF('Modelo B'!$C$3:$CH$3,6,'Modelo B'!$C$51:$CH$51)/SUMIF('Modelo B'!$C$3:$CH$3,6,'Modelo B'!$C$44:$CH$44),0) | H23: =IFERROR(SUMIF('Modelo B'!$C$3:$CH$3,7,'Modelo B'!$C$51:$CH$51)/SUMIF('Modelo B'!$C$3:$CH$3,7,'Modelo B'!$C$44:$CH$44),0)
A24: EBITDA | B24: =SUMIF('Modelo B'!$C$3:$CH$3,1,'Modelo B'!$C$67:$CH$67) | C24: =SUMIF('Modelo B'!$C$3:$CH$3,2,'Modelo B'!$C$67:$CH$67) | D24: =SUMIF('Modelo B'!$C$3:$CH$3,3,'Modelo B'!$C$67:$CH$67) | E24: =SUMIF('Modelo B'!$C$3:$CH$3,4,'Modelo B'!$C$67:$CH$67) | F24: =SUMIF('Modelo B'!$C$3:$CH$3,5,'Modelo B'!$C$67:$CH$67) | G24: =SUMIF('Modelo B'!$C$3:$CH$3,6,'Modelo B'!$C$67:$CH$67) | H24: =SUMIF('Modelo B'!$C$3:$CH$3,7,'Modelo B'!$C$67:$CH$67)
A25: Caixa acumulado sem captação (fim do ano) | B25: ='Modelo B'!N68 | C25: ='Modelo B'!Z68 | D25: ='Modelo B'!AL68 | E25: ='Modelo B'!AX68 | F25: ='Modelo B'!BJ68 | G25: ='Modelo B'!BV68 | H25: ='Modelo B'!CH68
A26: Pessoas (fim do ano) | B26: ='Modelo B'!N71 | C26: ='Modelo B'!Z71 | D26: ='Modelo B'!AL71 | E26: ='Modelo B'!AX71 | F26: ='Modelo B'!BJ71 | G26: ='Modelo B'!BV71 | H26: ='Modelo B'!CH71
A27: Participação no mercado endereçável (fim do ano) | B27: ='Modelo B'!N35 | C27: ='Modelo B'!Z35 | D27: ='Modelo B'!AL35 | E27: ='Modelo B'!AX35 | F27: ='Modelo B'!BJ35 | G27: ='Modelo B'!BV35 | H27: ='Modelo B'!CH35
A29: Indicadores-chave e critérios de corte
A30: Indicador | B30: Modelo A | C30: Modelo B | D30: Critério | E30: A passa? | F30: B passa?
A31: Receita recorrente anualizada no ano 5 | B31: =INDEX('Modelo A'!$C$47:$CH$47,1,60) | C31: =INDEX('Modelo B'!$C$41:$CH$41,1,60)
A32: Receita recorrente anualizada no ano 7 | B32: =INDEX('Modelo A'!$C$47:$CH$47,1,84) | C32: =INDEX('Modelo B'!$C$41:$CH$41,1,84)
A33: Mês de equilíbrio (EBITDA positivo daí em diante) | B33: =IFERROR(1/(1/MIN('Modelo A'!$C$75:$CH$75)),"não chega") | C33: =IFERROR(1/(1/MIN('Modelo B'!$C$69:$CH$69)),"não chega")
A34: Capital necessário (pior caixa acumulado) | B34: =-MIN(0,MIN('Modelo A'!$C$74:$CH$74)) | C34: =-MIN(0,MIN('Modelo B'!$C$68:$CH$68))
A35: Margem bruta no ano 5 | B35: =SUMIF('Modelo A'!$C$3:$CH$3,5,'Modelo A'!$C$57:$CH$57)/SUMIF('Modelo A'!$C$3:$CH$3,5,'Modelo A'!$C$50:$CH$50) | C35: =SUMIF('Modelo B'!$C$3:$CH$3,5,'Modelo B'!$C$51:$CH$51)/SUMIF('Modelo B'!$C$3:$CH$3,5,'Modelo B'!$C$44:$CH$44) | D35: =Premissas!$F$97 | E35: =IF(B35>=Premissas!$F$97,"Sim","Não") | F35: =IF(C35>=Premissas!$F$97,"Sim","Não")
A36: LTV/CAC do plano principal (Consultório / Agenda Cheia), mídia paga | B36: =Unidade!H7 | C36: =Unidade!H14 | D36: =Premissas!$F$98 | E36: =IF(B36>=Premissas!$F$98,"Sim","Não") | F36: =IF(C36>=Premissas!$F$98,"Sim","Não")
A37: Recuperação do CAC do plano principal (meses) | B37: =Unidade!I7 | C37: =Unidade!I14 | D37: =Premissas!$F$99 | E37: =IF(B37<=Premissas!$F$99,"Sim","Não") | F37: =IF(C37<=Premissas!$F$99,"Sim","Não")
A38: Mês em que a receita anualizada chega a R$ 50 mi | B38: =IFERROR(1/(1/MIN('Modelo A'!$C$76:$CH$76)),"não chega") | C38: =IFERROR(1/(1/MIN('Modelo B'!$C$70:$CH$70)),"não chega")
A39: Participação no mercado nesse mês | B39: =IF(ISNUMBER(B38),INDEX('Modelo A'!$C$41:$CH$41,1,B38),"") | C39: =IF(ISNUMBER(C38),INDEX('Modelo B'!$C$35:$CH$35,1,C38),"") | D39: =Premissas!$F$101 | E39: =IF(ISNUMBER(B39),IF(B39<=Premissas!$F$101,"Sim","Não"),"Não chega a R$ 50 mi") | F39: =IF(ISNUMBER(C39),IF(C39<=Premissas!$F$101,"Sim","Não"),"Não chega a R$ 50 mi")
A40: Receita por pessoa no ano 5 | B40: =SUMIF('Modelo A'!$C$3:$CH$3,5,'Modelo A'!$C$45:$CH$45)/INDEX('Modelo A'!$C$77:$CH$77,1,60) | C40: =SUMIF('Modelo B'!$C$3:$CH$3,5,'Modelo B'!$C$39:$CH$39)/INDEX('Modelo B'!$C$71:$CH$71,1,60)
A41: Clientes ativos no ano 5 | B41: =INDEX('Modelo A'!$C$39:$CH$39,1,60) | C41: =INDEX('Modelo B'!$C$33:$CH$33,1,60)
A42: LTV/CAC ponderado pelo mix de novos clientes (mídia paga) | B42: =(Premissas!$F$47*Unidade!F6+Premissas!$F$52*Unidade!F7+Premissas!$F$57*Unidade!F8+Premissas!$F$63*Unidade!F9)/Premissas!$F$42 | C42: =(Premissas!$F$76*Unidade!F13+Premissas!$F$82*Unidade!F14+Premissas!$F$89*Unidade!F15)/Premissas!$F$70 | D42: =Premissas!$F$98 | E42: =IF(B42>=Premissas!$F$98,"Sim","Não") | F42: =IF(C42>=Premissas!$F$98,"Sim","Não")
A44: Como ler: H6 exige as três linhas com 'Sim' (margem, LTV/CAC e recuperação do CAC). H7 exige chegar a R$ 50 mi de receita anualizada em até 7 anos com no máximo 3% do mercado endereçável.
...

Sheet Leia-me
A1: Jalecon v2 · Como usar este modelo
A2: Compara dois desenhos de negócio com as mesmas condições de mercado:
A3: Modelo A, software por assinatura: o médico usa a plataforma e faz o trabalho com ajuda da IA (planos de R$ 297 a R$ 3.900, como no v0).
A4: Modelo B, agência operada por agentes: uma equipe de agentes de IA executa marca, site, Google, conteúdo, anúncios e atendimento no WhatsApp; um especialista humano supervisiona dezenas de contas; parte do preço é cobrada por consulta agendada.
A6: Abas: Resumo (comparação e critérios de corte), Leia-me, Unidade (economia por cliente), Premissas (tudo o que pode ser mudado), Modelo A e Modelo B (mês a mês, 84 meses), Cenarios e Sensibilidade (geradas por script).
A7: Premissas em azul. Troque o cenário em Premissas!C3. Cada premissa tem a fonte na coluna G; as referências vêm do relatório 03 (mercado e concorrência).
A8: O caixa é calculado sem captação: o pior caixa acumulado é o capital necessário até o equilíbrio (sem reserva). A captação recomendada soma 6 meses de reserva a esse valor.
A9: Versão 2.1 (20/10/2026): incorpora a contraprova. Impostos de lucro presumido desde o início; churn, CAC e capacidade dos especialistas do Modelo B pela regra pré-registrada; cobrança por consulta desligada (art. 59 do Código de Ética Médica); custos de implantação e de indicação; mídia proporcional à expansão; Agenda Cheia a partir do mês 9.
A10: Limitações: churn e CAC ainda são referências de mercado, não medição própria; não há sazonalidade; as consultas atribuídas no Modelo B são suposição a validar em piloto.

Sheet Premissas
A1: Jalecon v2 · Premissas
A2: Texto azul = premissa editável. A coluna F (Usado) segue o cenário escolhido em C3. A coluna G diz de onde veio cada número.
A3: Cenário (1 = Conservador, 2 = Base, 3 = Otimista) | C3: 2 | D3: =CHOOSE(C3,"Conservador","Base","Otimista")
A6: 1. Gerais
A7: Premissa | B7: Unidade | C7: Conservador | D7: Base | E7: Otimista | F7: Usado | G7: Fonte ou justificativa
A8: Mês de lançamento comercial (antes: produto e piloto) | B8: mês | C8: 5 | D8: 4 | E8: 4 | F8: =CHOOSE($C$3,C8,D8,E8) | G8: Plano v0: 3 meses de piloto antes da venda
A9: Impostos sobre a receita até R$ 4,8 mi nos últimos 12 meses | B9: % | C9: 0.163 | D9: 0.163 | E9: 0.163 | F9: =CHOOSE($C$3,C9,D9,E9) | G9: v2.1: lucro presumido desde o início. O Simples não admite sócio pessoa jurídica, o que impede investidor institucional (contraprova)
A10: Impostos sobre a receita acima de R$ 4,8 mi nos últimos 12 meses | B10: % | C10: 0.163 | D10: 0.163 | E10: 0.163 | F10: =CHOOSE($C$3,C10,D10,E10) | G10: Lucro presumido para serviços: PIS, COFINS, ISS, IRPJ e CSLL (aprox.)
A11: Meios de pagamento | B11: % da receita | C11: 0.03 | D11: 0.03 | E11: 0.03 | F11: =CHOOSE($C$3,C11,D11,E11) | G11: Cartão e boleto recorrentes
A12: Mercado endereçável: médicos que dependem de atrair pacientes particulares | B12: médicos | C12: 115000 | D12: 150000 | E12: 230000 | F12: =CHOOSE($C$3,C12,D12,E12) | G12: Relatório 03, seção 1: 635,7 mil médicos × 48% em consultório × 50% dependem de pacientes particulares
A13: Expansão para dentistas: mês de início | B13: mês | C13: 37 | D13: 25 | E13: 25 | F13: =CHOOSE($C$3,C13,D13,E13) | G13: Decisão; exige base de regras do CFO 196/2019 e produto adaptado
A14: Expansão: aquisição adicional sobre a de médicos | B14: % | C14: 0.4 | D14: 0.7 | E14: 1 | F14: =CHOOSE($C$3,C14,D14,E14) | G14: Dentistas: mais de 450 mil e quase só atendimento particular (CFO, fonte secundária). Concorrência já presente (Sorriai)
A15: Mercado endereçável: dentistas | B15: dentistas | C15: 120000 | D15: 180000 | E15: 225000 | F15: =CHOOSE($C$3,C15,D15,E15) | G15: 450 mil × 40% a 50% com consultório próprio e dependentes de pacientes particulares (suposição)
A16: Custo único da expansão (regras, produto, jurídico) | B16: R$ | C16: 400000 | D16: 300000 | E16: 200000 | F16: =CHOOSE($C$3,C16,D16,E16) | G16: Estimativa
A17: Indicação: novos clientes por mês, como % da base ativa | B17: % | C17: 0.005 | D17: 0.01 | E17: 0.015 | F17: =CHOOSE($C$3,C17,D17,E17) | G17: Programa de indicação; v0 usava 1%
A18: Parcerias: multiplicador sobre o plano de parcerias | B18: x | C18: 0.6 | D18: 1 | E18: 1.3 | F18: =CHOOSE($C$3,C18,D18,E18) | G18: Residências, sociedades, contadores, coworkings, clube de benefícios da iClinic
A20: 2. Decisões por ano (iguais nos dois modelos e nos três cenários)
C21: Ano 1 | D21: Ano 2 | E21: Ano 3 | F21: Ano 4 | G21: Ano 5 | H21: Ano 6 | I21: Ano 7 | J21: Fonte
A22: Orçamento de mídia paga por mês | B22: R$ | C22: 20000 | D22: 50000 | E22: 100000 | F22: 160000 | G22: 220000 | H22: 280000 | I22: 340000 | J22: Decisão de investimento
A23: Novos clientes por parcerias por mês (antes do multiplicador) | B23: clientes | C23: 4 | D23: 10 | E23: 18 | F23: 26 | G23: 34 | H23: 42 | I23: 50 | J23: Plano v0, ampliado
A24: Produto, engenharia e IA (pessoas) | B24: pessoas | C24: 4 | D24: 7 | E24: 10 | F24: 13 | G24: 16 | H24: 18 | I24: 20 | J24: Plano de contratação
A25: Administrativo, jurídico e conformidade (pessoas) | B25: pessoas | C25: 1 | D25: 2 | E25: 4 | F25: 6 | G25: 8 | H25: 9 | I25: 10 | J25: Plano de contratação
A26: Pró-labore por fundador por mês | B26: R$ | C26: 5000 | D26: 10000 | E26: 15000 | F26: 15000 | G26: 18000 | H26: 18000 | I26: 20000 | J26: Plano v0 (6 fundadores)
A27: Modelo A: vendas e marketing (pessoas) | B27: pessoas | C27: 2 | D27: 4 | E27: 7 | F27: 10 | G27: 13 | H27: 15 | I27: 17 | J27: Venda por autosserviço e inside sales
A28: Modelo B: vendas e marketing (pessoas) | B28: pessoas | C28: 3 | D28: 6 | E28: 10 | F28: 15 | G28: 20 | H28: 24 | I28: 28 | J28: Venda consultiva: ticket maior pede mais gente
A30: 3. Custos de pessoas e despesas gerais
A31: Premissa | B31: Unidade | C31: Conservador | D31: Base | E31: Otimista | F31: Usado | G31: Fonte ou justificativa
A32: Custo mensal por pessoa de produto e engenharia (com encargos) | B32: R$ | C32: 20000 | D32: 18000 | E32: 16000 | F32: =CHOOSE($C$3,C32,D32,E32) | G32: Mercado de São Paulo, pleno e sênior
A33: Custo mensal por pessoa de vendas e marketing | B33: R$ | C33: 11000 | D33: 10000 | E33: 9000 | F33: =CHOOSE($C$3,C33,D33,E33) | G33: Mercado de São Paulo, com comissão média
A34: Custo mensal por pessoa administrativa e jurídica | B34: R$ | C34: 13000 | D34: 12000 | E34: 11000 | F34: =CHOOSE($C$3,C34,D34,E34) | G34: Mercado de São Paulo
A35: Número de fundadores | B35: pessoas | C35: 6 | D35: 6 | E35: 6 | F35: =CHOOSE($C$3,C35,D35,E35) | G35: Grupo 1
A36: Outras despesas fixas por mês (ferramentas, jurídico, contabilidade) | B36: R$ | C36: 20000 | D36: 15000 | E36: 12000 | F36: =CHOOSE($C$3,C36,D36,E36) | G36: Estimativa
A37: Outras despesas variáveis | B37: % da receita | C37: 0.04 | D37: 0.03 | E37: 0.025 | F37: =CHOOSE($C$3,C37,D37,E37) | G37: Estimativa
A38: Marca, eventos e conteúdo próprio | B38: % da mídia | C38: 0.08 | D38: 0.05 | E38: 0.05 | F38: =CHOOSE($C$3,C38,D38,E38) | G38: Congressos e conteúdo sobre regras do CFM
A40: 4. Modelo A: software por assinatura
A41: Premissa | B41: Unidade | C41: Conservador | D41: Base | E41: Otimista | F41: Usado | G41: Fonte ou justificativa
A42: CAC na mídia paga | B42: R$ | C42: 6000 | D42: 4500 | E42: 3000 | F42: =CHOOSE($C$3,C42,D42,E42) | G42: Relatório 03, seção 4: recuperação do CAC em 8 a 11 meses equivale a R$ 4.500 a R$ 6.100; v0 usava R$ 1.800
A43: Custo por cliente vindo de parceria (comissão) | B43: R$ | C43: 1800 | D43: 1500 | E43: 1200 | F43: =CHOOSE($C$3,C43,D43,E43) | G43: Comissão de cerca de 2 mensalidades
A44: Custo mensal do gestor de conta (com encargos) | B44: R$ | C44: 9500 | D44: 9000 | E44: 8500 | F44: =CHOOSE($C$3,C44,D44,E44) | G44: Mercado
A45: Essencial: preço mensal | B45: R$ | C45: 297 | D45: 297 | E45: 297 | F45: =CHOOSE($C$3,C45,D45,E45) | G45: Plano v0
...

Sheet Unidade
A1: Economia por cliente, por plano (cenário selecionado)
A2: Contribuição = mensalidade e consultas, menos impostos (alíquota cheia), meios de pagamento, custo direto e parte do especialista humano. LTV = contribuição / churn + taxa de implantação - custo de implantação.
A4: Modelo A: software por assinatura
A5: Plano | B5: Receita mensal | C5: Contribuição mensal | D5: Margem de contribuição | E5: Churn mensal | F5: LTV | G5: CAC mídia paga | H5: LTV/CAC | I5: Recuperação do CAC (meses)
A6: Essencial | B6: =Premissas!$F$45 | C6: =B6*(1-Premissas!$F$10-Premissas!$F$11)-Premissas!$F$49 | D6: =C6/B6 | E6: =Premissas!$F$48 | F6: =C6/E6+Premissas!$F$46-Premissas!$F$105 | G6: =Premissas!$F$42 | H6: =F6/G6 | I6: =G6/C6
A7: Consultório | B7: =Premissas!$F$50 | C7: =B7*(1-Premissas!$F$10-Premissas!$F$11)-Premissas!$F$54 | D7: =C7/B7 | E7: =Premissas!$F$53 | F7: =C7/E7+Premissas!$F$51-Premissas!$F$105 | G7: =Premissas!$F$42 | H7: =F7/G7 | I7: =G7/C7
A8: Autoridade | B8: =Premissas!$F$55 | C8: =B8*(1-Premissas!$F$10-Premissas!$F$11)-Premissas!$F$59-Premissas!$F$44/Premissas!$F$60 | D8: =C8/B8 | E8: =Premissas!$F$58 | F8: =C8/E8+Premissas!$F$56-Premissas!$F$105 | G8: =Premissas!$F$42 | H8: =F8/G8 | I8: =G8/C8
A9: Clínica | B9: =Premissas!$F$61 | C9: =B9*(1-Premissas!$F$10-Premissas!$F$11)-Premissas!$F$65-Premissas!$F$44/Premissas!$F$66 | D9: =C9/B9 | E9: =Premissas!$F$64 | F9: =C9/E9+Premissas!$F$62-Premissas!$F$105 | G9: =Premissas!$F$42 | H9: =F9/G9 | I9: =G9/C9
A11: Modelo B: agência operada por agentes
A12: Plano | B12: Receita mensal | C12: Contribuição mensal | D12: Margem de contribuição | E12: Churn mensal | F12: LTV | G12: CAC mídia paga | H12: LTV/CAC | I12: Recuperação do CAC (meses)
A13: Presença | B13: =Premissas!$F$74 | C13: =B13*(1-Premissas!$F$10-Premissas!$F$11)-Premissas!$F$78-Premissas!$F$72/Premissas!$F$79 | D13: =C13/B13 | E13: =Premissas!$F$77 | F13: =C13/E13+Premissas!$F$75-Premissas!$F$106 | G13: =Premissas!$F$70 | H13: =F13/G13 | I13: =G13/C13
A14: Agenda Cheia | B14: =Premissas!$F$80+Premissas!$F$86*Premissas!$F$73 | C14: =B14*(1-Premissas!$F$10-Premissas!$F$11)-Premissas!$F$84-Premissas!$F$72/Premissas!$F$85 | D14: =C14/B14 | E14: =Premissas!$F$83 | F14: =C14/E14+Premissas!$F$81-Premissas!$F$106 | G14: =Premissas!$F$70 | H14: =F14/G14 | I14: =G14/C14
A15: Clínica | B15: =Premissas!$F$87+Premissas!$F$93*Premissas!$F$73 | C15: =B15*(1-Premissas!$F$10-Premissas!$F$11)-Premissas!$F$91-Premissas!$F$72/Premissas!$F$92 | D15: =C15/B15 | E15: =Premissas!$F$90 | F15: =C15/E15+Premissas!$F$88-Premissas!$F$106 | G15: =Premissas!$F$70 | H15: =F15/G15 | I15: =G15/C15

Sheet Modelo A
A1: Modelo A: software por assinatura · mês a mês
A2: Mês | C2: 1 | D2: 2 | E2: 3 | F2: 4 | G2: 5 | H2: 6 | I2: 7 | J2: 8 | K2: 9 | L2: 10 | M2: 11 | N2: 12 | O2: 13 | P2: 14 | Q2: 15 | R2: 16 | S2: 17 | T2: 18 | U2: 19 | V2: 20 | W2: 21 | X2: 22 | Y2: 23 | Z2: 24 | AA2: 25 | AB2: 26 | AC2: 27 | AD2: 28 | AE2: 29 | AF2: 30 | AG2: 31 | AH2: 32 | AI2: 33 | AJ2: 34 | AK2: 35 | AL2: 36 | AM2: 37 | AN2: 38 | AO2: 39 | AP2: 40 | AQ2: 41 | AR2: 42 | AS2: 43 | AT2: 44 | AU2: 45 | AV2: 46 | AW2: 47 | AX2: 48 | AY2: 49 | AZ2: 50 | BA2: 51 | BB2: 52 | BC2: 53 | BD2: 54 | BE2: 55 | BF2: 56 | BG2: 57 | BH2: 58 | BI2: 59 | BJ2: 60 | BK2: 61 | BL2: 62 | BM2: 63 | BN2: 64 | BO2: 65 | BP2: 66 | BQ2: 67 | BR2: 68 | BS2: 69 | BT2: 70 | BU2: 71 | BV2: 72 | BW2: 73 | BX2: 74 | BY2: 75 | BZ2: 76 | CA2: 77 | CB2: 78 | CC2: 79 | CD2: 80 | CE2: 81 | CF2: 82 | CG2: 83 | CH2: 84
A3: Ano | C3: =ROUNDUP(C2/12,0) | D3: =ROUNDUP(D2/12,0) | E3: =ROUNDUP(E2/12,0) | F3: =ROUNDUP(F2/12,0) | G3: =ROUNDUP(G2/12,0) | H3: =ROUNDUP(H2/12,0) | I3: =ROUNDUP(I2/12,0) | J3: =ROUNDUP(J2/12,0) | ... CH3: =ROUNDUP(CH2/12,0)
A4: Venda ativa (1 a partir do lançamento) | C4: =IF(C2>=Premissas!$F$8,1,0) | D4: =IF(D2>=Premissas!$F$8,1,0) | E4: =IF(E2>=Premissas!$F$8,1,0) | F4: =IF(F2>=Premissas!$F$8,1,0) | G4: =IF(G2>=Premissas!$F$8,1,0) | H4: =IF(H2>=Premissas!$F$8,1,0) | I4: =IF(I2>=Premissas!$F$8,1,0) | J4: =IF(J2>=Premissas!$F$8,1,0) | ... CH4: =IF(CH2>=Premissas!$F$8,1,0)
A5: Fator de expansão para dentistas | C5: =IF(C2>=Premissas!$F$13,1+Premissas!$F$14,1) | D5: =IF(D2>=Premissas!$F$13,1+Premissas!$F$14,1) | E5: =IF(E2>=Premissas!$F$13,1+Premissas!$F$14,1) | F5: =IF(F2>=Premissas!$F$13,1+Premissas!$F$14,1) | G5: =IF(G2>=Premissas!$F$13,1+Premissas!$F$14,1) | H5: =IF(H2>=Premissas!$F$13,1+Premissas!$F$14,1) | I5: =IF(I2>=Premissas!$F$13,1+Premissas!$F$14,1) | J5: =IF(J2>=Premissas!$F$13,1+Premissas!$F$14,1) | ... CH5: =IF(CH2>=Premissas!$F$13,1+Premissas!$F$14,1)
A7: Aquisição
A8: Mídia paga no mês | C8: =INDEX(Premissas!$C$22:$I$22,1,C3)*C4*C5 | D8: =INDEX(Premissas!$C$22:$I$22,1,D3)*D4*D5 | E8: =INDEX(Premissas!$C$22:$I$22,1,E3)*E4*E5 | F8: =INDEX(Premissas!$C$22:$I$22,1,F3)*F4*F5 | G8: =INDEX(Premissas!$C$22:$I$22,1,G3)*G4*G5 | H8: =INDEX(Premissas!$C$22:$I$22,1,H3)*H4*H5 | I8: =INDEX(Premissas!$C$22:$I$22,1,I3)*I4*I5 | J8: =INDEX(Premissas!$C$22:$I$22,1,J3)*J4*J5 | ... CH8: =INDEX(Premissas!$C$22:$I$22,1,CH3)*CH4*CH5
A9: Novos clientes por mídia paga | C9: =C8/Premissas!$F$42 | D9: =D8/Premissas!$F$42 | E9: =E8/Premissas!$F$42 | F9: =F8/Premissas!$F$42 | G9: =G8/Premissas!$F$42 | H9: =H8/Premissas!$F$42 | I9: =I8/Premissas!$F$42 | J9: =J8/Premissas!$F$42 | ... CH9: =CH8/Premissas!$F$42
A10: Novos clientes por parcerias | C10: =INDEX(Premissas!$C$23:$I$23,1,C3)*Premissas!$F$18*C4*C5 | D10: =INDEX(Premissas!$C$23:$I$23,1,D3)*Premissas!$F$18*D4*D5 | E10: =INDEX(Premissas!$C$23:$I$23,1,E3)*Premissas!$F$18*E4*E5 | F10: =INDEX(Premissas!$C$23:$I$23,1,F3)*Premissas!$F$18*F4*F5 | G10: =INDEX(Premissas!$C$23:$I$23,1,G3)*Premissas!$F$18*G4*G5 | H10: =INDEX(Premissas!$C$23:$I$23,1,H3)*Premissas!$F$18*H4*H5 | I10: =INDEX(Premissas!$C$23:$I$23,1,I3)*Premissas!$F$18*I4*I5 | J10: =INDEX(Premissas!$C$23:$I$23,1,J3)*Premissas!$F$18*J4*J5 | ... CH10: =INDEX(Premissas!$C$23:$I$23,1,CH3)*Premissas!$F$18*CH4*CH5
A11: Novos clientes por indicação | C11: =0 | D11: =C39*Premissas!$F$17*D4 | E11: =D39*Premissas!$F$17*E4 | F11: =E39*Premissas!$F$17*F4 | G11: =F39*Premissas!$F$17*G4 | H11: =G39*Premissas!$F$17*H4 | I11: =H39*Premissas!$F$17*I4 | J11: =I39*Premissas!$F$17*J4 | K11: =J39*Premissas!$F$17*K4 | ... CH11: =CG39*Premissas!$F$17*CH4
A12: Novos clientes no mês | C12: =C9+C10+C11 | D12: =D9+D10+D11 | E12: =E9+E10+E11 | F12: =F9+F10+F11 | G12: =G9+G10+G11 | H12: =H9+H10+H11 | I12: =I9+I10+I11 | J12: =J9+J10+J11 | ... CH12: =CH9+CH10+CH11
A14: Plano Essencial
A15: Participação nos novos | C15: =Premissas!$F$47 | D15: =Premissas!$F$47 | E15: =Premissas!$F$47 | F15: =Premissas!$F$47 | G15: =Premissas!$F$47 | H15: =Premissas!$F$47 | I15: =Premissas!$F$47 | J15: =Premissas!$F$47 | ... CH15: =Premissas!$F$47
A16: Novos | C16: =C12*C15 | D16: =D12*D15 | E16: =E12*E15 | F16: =F12*F15 | G16: =G12*G15 | H16: =H12*H15 | I16: =I12*I15 | J16: =J12*J15 | ... CH16: =CH12*CH15
A17: Cancelados | C17: =0*Premissas!$F$48 | D17: =C18*Premissas!$F$48 | E17: =D18*Premissas!$F$48 | F17: =E18*Premissas!$F$48 | G17: =F18*Premissas!$F$48 | H17: =G18*Premissas!$F$48 | I17: =H18*Premissas!$F$48 | J17: =I18*Premissas!$F$48 | K17: =J18*Premissas!$F$48 | ... CH17: =CG18*Premissas!$F$48
A18: Ativos no fim do mês | C18: =0+C16-C17 | D18: =C18+D16-D17 | E18: =D18+E16-E17 | F18: =E18+F16-F17 | G18: =F18+G16-G17 | H18: =G18+H16-H17 | I18: =H18+I16-I17 | J18: =I18+J16-J17 | K18: =J18+K16-K17 | ... CH18: =CG18+CH16-CH17
A20: Plano Consultório
A21: Participação nos novos | C21: =Premissas!$F$52+IF(C2<13,Premissas!$F$63,0) | D21: =Premissas!$F$52+IF(D2<13,Premissas!$F$63,0) | E21: =Premissas!$F$52+IF(E2<13,Premissas!$F$63,0) | F21: =Premissas!$F$52+IF(F2<13,Premissas!$F$63,0) | G21: =Premissas!$F$52+IF(G2<13,Premissas!$F$63,0) | H21: =Premissas!$F$52+IF(H2<13,Premissas!$F$63,0) | I21: =Premissas!$F$52+IF(I2<13,Premissas!$F$63,0) | J21: =Premissas!$F$52+IF(J2<13,Premissas!$F$63,0) | ... CH21: =Premissas!$F$52+IF(CH2<13,Premissas!$F$63,0)
A22: Novos | C22: =C12*C21 | D22: =D12*D21 | E22: =E12*E21 | F22: =F12*F21 | G22: =G12*G21 | H22: =H12*H21 | I22: =I12*I21 | J22: =J12*J21 | ... CH22: =CH12*CH21
A23: Cancelados | C23: =0*Premissas!$F$53 | D23: =C24*Premissas!$F$53 | E23: =D24*Premissas!$F$53 | F23: =E24*Premissas!$F$53 | G23: =F24*Premissas!$F$53 | H23: =G24*Premissas!$F$53 | I23: =H24*Premissas!$F$53 | J23: =I24*Premissas!$F$53 | K23: =J24*Premissas!$F$53 | ... CH23: =CG24*Premissas!$F$53
A24: Ativos no fim do mês | C24: =0+C22-C23 | D24: =C24+D22-D23 | E24: =D24+E22-E23 | F24: =E24+F22-F23 | G24: =F24+G22-G23 | H24: =G24+H22-H23 | I24: =H24+I22-I23 | J24: =I24+J22-J23 | K24: =J24+K22-K23 | ... CH24: =CG24+CH22-CH23
A26: Plano Autoridade
A27: Participação nos novos | C27: =Premissas!$F$57 | D27: =Premissas!$F$57 | E27: =Premissas!$F$57 | F27: =Premissas!$F$57 | G27: =Premissas!$F$57 | H27: =Premissas!$F$57 | I27: =Premissas!$F$57 | J27: =Premissas!$F$57 | ... CH27: =Premissas!$F$57
A28: Novos | C28: =C12*C27 | D28: =D12*D27 | E28: =E12*E27 | F28: =F12*F27 | G28: =G12*G27 | H28: =H12*H27 | I28: =I12*I27 | J28: =J12*J27 | ... CH28: =CH12*CH27
A29: Cancelados | C29: =0*Premissas!$F$58 | D29: =C30*Premissas!$F$58 | E29: =D30*Premissas!$F$58 | F29: =E30*Premissas!$F$58 | G29: =F30*Premissas!$F$58 | H29: =G30*Premissas!$F$58 | I29: =H30*Premissas!$F$58 | J29: =I30*Premissas!$F$58 | K29: =J30*Premissas!$F$58 | ... CH29: =CG30*Premissas!$F$58
A30: Ativos no fim do mês | C30: =0+C28-C29 | D30: =C30+D28-D29 | E30: =D30+E28-E29 | F30: =E30+F28-F29 | G30: =F30+G28-G29 | H30: =G30+H28-H29 | I30: =H30+I28-I29 | J30: =I30+J28-J29 | K30: =J30+K28-K29 | ... CH30: =CG30+CH28-CH29
A32: Plano Clínica
A33: Participação nos novos | C33: =IF(C2>=13,Premissas!$F$63,0) | D33: =IF(D2>=13,Premissas!$F$63,0) | E33: =IF(E2>=13,Premissas!$F$63,0) | F33: =IF(F2>=13,Premissas!$F$63,0) | G33: =IF(G2>=13,Premissas!$F$63,0) | H33: =IF(H2>=13,Premissas!$F$63,0) | I33: =IF(I2>=13,Premissas!$F$63,0) | J33: =IF(J2>=13,Premissas!$F$63,0) | ... CH33: =IF(CH2>=13,Premissas!$F$63,0)
A34: Novos | C34: =C12*C33 | D34: =D12*D33 | E34: =E12*E33 | F34: =F12*F33 | G34: =G12*G33 | H34: =H12*H33 | I34: =I12*I33 | J34: =J12*J33 | ... CH34: =CH12*CH33
A35: Cancelados | C35: =0*Premissas!$F$64 | D35: =C36*Premissas!$F$64 | E35: =D36*Premissas!$F$64 | F35: =E36*Premissas!$F$64 | G35: =F36*Premissas!$F$64 | H35: =G36*Premissas!$F$64 | I35: =H36*Premissas!$F$64 | J35: =I36*Premissas!$F$64 | K35: =J36*Premissas!$F$64 | ... CH35: =CG36*Premissas!$F$64
A36: Ativos no fim do mês | C36: =0+C34-C35 | D36: =C36+D34-D35 | E36: =D36+E34-E35 | F36: =E36+F34-F35 | G36: =F36+G34-G35 | H36: =G36+H34-H35 | I36: =H36+I34-I35 | J36: =I36+J34-J35 | K36: =J36+K34-K35 | ... CH36: =CG36+CH34-CH35
A38: Clientes e receita
A39: Clientes ativos | C39: =C18+C24+C30+C36 | D39: =D18+D24+D30+D36 | E39: =E18+E24+E30+E36 | F39: =F18+F24+F30+F36 | G39: =G18+G24+G30+G36 | H39: =H18+H24+H30+H36 | I39: =I18+I24+I30+I36 | J39: =J18+J24+J30+J36 | ... CH39: =CH18+CH24+CH30+CH36
A40: Mercado endereçável no mês | C40: =Premissas!$F$12+IF(C2>=Premissas!$F$13,Premissas!$F$15,0) | D40: =Premissas!$F$12+IF(D2>=Premissas!$F$13,Premissas!$F$15,0) | E40: =Premissas!$F$12+IF(E2>=Premissas!$F$13,Premissas!$F$15,0) | F40: =Premissas!$F$12+IF(F2>=Premissas!$F$13,Premissas!$F$15,0) | G40: =Premissas!$F$12+IF(G2>=Premissas!$F$13,Premissas!$F$15,0) | H40: =Premissas!$F$12+IF(H2>=Premissas!$F$13,Premissas!$F$15,0) | I40: =Premissas!$F$12+IF(I2>=Premissas!$F$13,Premissas!$F$15,0) | J40: =Premissas!$F$12+IF(J2>=Premissas!$F$13,Premissas!$F$15,0) | ... CH40: =Premissas!$F$12+IF(CH2>=Premissas!$F$13,Premissas!$F$15,0)
A41: Participação no mercado endereçável | C41: =C39/C40 | D41: =D39/D40 | E41: =E39/E40 | F41: =F39/F40 | G41: =G39/G40 | H41: =H39/H40 | I41: =I39/I40 | J41: =J39/J40 | ... CH41: =CH39/CH40
A42: Receita de mensalidades | C42: =C18*Premissas!$F$45+C24*Premissas!$F$50+C30*Premissas!$F$55+C36*Premissas!$F$61 | D42: =D18*Premissas!$F$45+D24*Premissas!$F$50+D30*Premissas!$F$55+D36*Premissas!$F$61 | E42: =E18*Premissas!$F$45+E24*Premissas!$F$50+E30*Premissas!$F$55+E36*Premissas!$F$61 | F42: =F18*Premissas!$F$45+F24*Premissas!$F$50+F30*Premissas!$F$55+F36*Premissas!$F$61 | G42: =G18*Premissas!$F$45+G24*Premissas!$F$50+G30*Premissas!$F$55+G36*Premissas!$F$61 | H42: =H18*Premissas!$F$45+H24*Premissas!$F$50+H30*Premissas!$F$55+H36*Premissas!$F$61 | I42: =I18*Premissas!$F$45+I24*Premissas!$F$50+I30*Premissas!$F$55+I36*Premissas!$F$61 | J42: =J18*Premissas!$F$45+J24*Premissas!$F$50+J30*Premissas!$F$55+J36*Premissas!$F$61 | ... CH42: =CH18*Premissas!$F$45+CH24*Premissas!$F$50+CH30*Premissas!$F$55+CH36*Premissas!$F$61
A43: Receita de implantação | C43: =C16*Premissas!$F$46+C22*Premissas!$F$51+C28*Premissas!$F$56+C34*Premissas!$F$62 | D43: =D16*Premissas!$F$46+D22*Premissas!$F$51+D28*Premissas!$F$56+D34*Premissas!$F$62 | E43: =E16*Premissas!$F$46+E22*Premissas!$F$51+E28*Premissas!$F$56+E34*Premissas!$F$62 | F43: =F16*Premissas!$F$46+F22*Premissas!$F$51+F28*Premissas!$F$56+F34*Premissas!$F$62 | G43: =G16*Premissas!$F$46+G22*Premissas!$F$51+G28*Premissas!$F$56+G34*Premissas!$F$62 | H43: =H16*Premissas!$F$46+H22*Premissas!$F$51+H28*Premissas!$F$56+H34*Premissas!$F$62 | I43: =I16*Premissas!$F$46+I22*Premissas!$F$51+I28*Premissas!$F$56+I34*Premissas!$F$62 | J43: =J16*Premissas!$F$46+J22*Premissas!$F$51+J28*Premissas!$F$56+J34*Premissas!$F$62 | ... CH43: =CH16*Premissas!$F$46+CH22*Premissas!$F$51+CH28*Premissas!$F$56+CH34*Premissas!$F$62
A44: Receita por consulta agendada | C44: =0 | D44: =0 | E44: =0 | F44: =0 | G44: =0 | H44: =0 | I44: =0 | J44: =0 | ... CH44: =0
A45: Receita bruta | C45: =C42+C43+C44 | D45: =D42+D43+D44 | E45: =E42+E43+E44 | F45: =F42+F43+F44 | G45: =G42+G43+G44 | H45: =H42+H43+H44 | I45: =I42+I43+I44 | J45: =J42+J43+J44 | ... CH45: =CH42+CH43+CH44
A46: Receita recorrente mensal (mensalidades + consultas) | C46: =C42+C44 | D46: =D42+D44 | E46: =E42+E44 | F46: =F42+F44 | G46: =G42+G44 | H46: =H42+H44 | I46: =I42+I44 | J46: =J42+J44 | ... CH46: =CH42+CH44
...

Sheet Modelo B
A1: Modelo B: agência operada por agentes · mês a mês
A2: Mês | C2: 1 | D2: 2 | E2: 3 | F2: 4 | G2: 5 | H2: 6 | I2: 7 | J2: 8 | K2: 9 | L2: 10 | M2: 11 | N2: 12 | O2: 13 | P2: 14 | Q2: 15 | R2: 16 | S2: 17 | T2: 18 | U2: 19 | V2: 20 | W2: 21 | X2: 22 | Y2: 23 | Z2: 24 | AA2: 25 | AB2: 26 | AC2: 27 | AD2: 28 | AE2: 29 | AF2: 30 | AG2: 31 | AH2: 32 | AI2: 33 | AJ2: 34 | AK2: 35 | AL2: 36 | AM2: 37 | AN2: 38 | AO2: 39 | AP2: 40 | AQ2: 41 | AR2: 42 | AS2: 43 | AT2: 44 | AU2: 45 | AV2: 46 | AW2: 47 | AX2: 48 | AY2: 49 | AZ2: 50 | BA2: 51 | BB2: 52 | BC2: 53 | BD2: 54 | BE2: 55 | BF2: 56 | BG2: 57 | BH2: 58 | BI2: 59 | BJ2: 60 | BK2: 61 | BL2: 62 | BM2: 63 | BN2: 64 | BO2: 65 | BP2: 66 | BQ2: 67 | BR2: 68 | BS2: 69 | BT2: 70 | BU2: 71 | BV2: 72 | BW2: 73 | BX2: 74 | BY2: 75 | BZ2: 76 | CA2: 77 | CB2: 78 | CC2: 79 | CD2: 80 | CE2: 81 | CF2: 82 | CG2: 83 | CH2: 84
A3: Ano | C3: =ROUNDUP(C2/12,0) | D3: =ROUNDUP(D2/12,0) | E3: =ROUNDUP(E2/12,0) | F3: =ROUNDUP(F2/12,0) | G3: =ROUNDUP(G2/12,0) | H3: =ROUNDUP(H2/12,0) | I3: =ROUNDUP(I2/12,0) | J3: =ROUNDUP(J2/12,0) | ... CH3: =ROUNDUP(CH2/12,0)
A4: Venda ativa (1 a partir do lançamento) | C4: =IF(C2>=Premissas!$F$8,1,0) | D4: =IF(D2>=Premissas!$F$8,1,0) | E4: =IF(E2>=Premissas!$F$8,1,0) | F4: =IF(F2>=Premissas!$F$8,1,0) | G4: =IF(G2>=Premissas!$F$8,1,0) | H4: =IF(H2>=Premissas!$F$8,1,0) | I4: =IF(I2>=Premissas!$F$8,1,0) | J4: =IF(J2>=Premissas!$F$8,1,0) | ... CH4: =IF(CH2>=Premissas!$F$8,1,0)
A5: Fator de expansão para dentistas | C5: =IF(C2>=Premissas!$F$13,1+Premissas!$F$14,1) | D5: =IF(D2>=Premissas!$F$13,1+Premissas!$F$14,1) | E5: =IF(E2>=Premissas!$F$13,1+Premissas!$F$14,1) | F5: =IF(F2>=Premissas!$F$13,1+Premissas!$F$14,1) | G5: =IF(G2>=Premissas!$F$13,1+Premissas!$F$14,1) | H5: =IF(H2>=Premissas!$F$13,1+Premissas!$F$14,1) | I5: =IF(I2>=Premissas!$F$13,1+Premissas!$F$14,1) | J5: =IF(J2>=Premissas!$F$13,1+Premissas!$F$14,1) | ... CH5: =IF(CH2>=Premissas!$F$13,1+Premissas!$F$14,1)
A7: Aquisição
A8: Mídia paga no mês | C8: =INDEX(Premissas!$C$22:$I$22,1,C3)*C4*C5 | D8: =INDEX(Premissas!$C$22:$I$22,1,D3)*D4*D5 | E8: =INDEX(Premissas!$C$22:$I$22,1,E3)*E4*E5 | F8: =INDEX(Premissas!$C$22:$I$22,1,F3)*F4*F5 | G8: =INDEX(Premissas!$C$22:$I$22,1,G3)*G4*G5 | H8: =INDEX(Premissas!$C$22:$I$22,1,H3)*H4*H5 | I8: =INDEX(Premissas!$C$22:$I$22,1,I3)*I4*I5 | J8: =INDEX(Premissas!$C$22:$I$22,1,J3)*J4*J5 | ... CH8: =INDEX(Premissas!$C$22:$I$22,1,CH3)*CH4*CH5
A9: Novos clientes por mídia paga | C9: =C8/Premissas!$F$70 | D9: =D8/Premissas!$F$70 | E9: =E8/Premissas!$F$70 | F9: =F8/Premissas!$F$70 | G9: =G8/Premissas!$F$70 | H9: =H8/Premissas!$F$70 | I9: =I8/Premissas!$F$70 | J9: =J8/Premissas!$F$70 | ... CH9: =CH8/Premissas!$F$70
A10: Novos clientes por parcerias | C10: =INDEX(Premissas!$C$23:$I$23,1,C3)*Premissas!$F$18*C4*C5 | D10: =INDEX(Premissas!$C$23:$I$23,1,D3)*Premissas!$F$18*D4*D5 | E10: =INDEX(Premissas!$C$23:$I$23,1,E3)*Premissas!$F$18*E4*E5 | F10: =INDEX(Premissas!$C$23:$I$23,1,F3)*Premissas!$F$18*F4*F5 | G10: =INDEX(Premissas!$C$23:$I$23,1,G3)*Premissas!$F$18*G4*G5 | H10: =INDEX(Premissas!$C$23:$I$23,1,H3)*Premissas!$F$18*H4*H5 | I10: =INDEX(Premissas!$C$23:$I$23,1,I3)*Premissas!$F$18*I4*I5 | J10: =INDEX(Premissas!$C$23:$I$23,1,J3)*Premissas!$F$18*J4*J5 | ... CH10: =INDEX(Premissas!$C$23:$I$23,1,CH3)*Premissas!$F$18*CH4*CH5
A11: Novos clientes por indicação | C11: =0 | D11: =C33*Premissas!$F$17*D4 | E11: =D33*Premissas!$F$17*E4 | F11: =E33*Premissas!$F$17*F4 | G11: =F33*Premissas!$F$17*G4 | H11: =G33*Premissas!$F$17*H4 | I11: =H33*Premissas!$F$17*I4 | J11: =I33*Premissas!$F$17*J4 | K11: =J33*Premissas!$F$17*K4 | ... CH11: =CG33*Premissas!$F$17*CH4
A12: Novos clientes no mês | C12: =C9+C10+C11 | D12: =D9+D10+D11 | E12: =E9+E10+E11 | F12: =F9+F10+F11 | G12: =G9+G10+G11 | H12: =H9+H10+H11 | I12: =I9+I10+I11 | J12: =J9+J10+J11 | ... CH12: =CH9+CH10+CH11
A14: Plano Presença
A15: Participação nos novos | C15: =Premissas!$F$76+IF(C2<9,Premissas!$F$82+IF(C2<13,Premissas!$F$89,0),0) | D15: =Premissas!$F$76+IF(D2<9,Premissas!$F$82+IF(D2<13,Premissas!$F$89,0),0) | E15: =Premissas!$F$76+IF(E2<9,Premissas!$F$82+IF(E2<13,Premissas!$F$89,0),0) | F15: =Premissas!$F$76+IF(F2<9,Premissas!$F$82+IF(F2<13,Premissas!$F$89,0),0) | G15: =Premissas!$F$76+IF(G2<9,Premissas!$F$82+IF(G2<13,Premissas!$F$89,0),0) | H15: =Premissas!$F$76+IF(H2<9,Premissas!$F$82+IF(H2<13,Premissas!$F$89,0),0) | I15: =Premissas!$F$76+IF(I2<9,Premissas!$F$82+IF(I2<13,Premissas!$F$89,0),0) | J15: =Premissas!$F$76+IF(J2<9,Premissas!$F$82+IF(J2<13,Premissas!$F$89,0),0) | ... CH15: =Premissas!$F$76+IF(CH2<9,Premissas!$F$82+IF(CH2<13,Premissas!$F$89,0),0)
A16: Novos | C16: =C12*C15 | D16: =D12*D15 | E16: =E12*E15 | F16: =F12*F15 | G16: =G12*G15 | H16: =H12*H15 | I16: =I12*I15 | J16: =J12*J15 | ... CH16: =CH12*CH15
A17: Cancelados | C17: =0*Premissas!$F$77 | D17: =C18*Premissas!$F$77 | E17: =D18*Premissas!$F$77 | F17: =E18*Premissas!$F$77 | G17: =F18*Premissas!$F$77 | H17: =G18*Premissas!$F$77 | I17: =H18*Premissas!$F$77 | J17: =I18*Premissas!$F$77 | K17: =J18*Premissas!$F$77 | ... CH17: =CG18*Premissas!$F$77
A18: Ativos no fim do mês | C18: =0+C16-C17 | D18: =C18+D16-D17 | E18: =D18+E16-E17 | F18: =E18+F16-F17 | G18: =F18+G16-G17 | H18: =G18+H16-H17 | I18: =H18+I16-I17 | J18: =I18+J16-J17 | K18: =J18+K16-K17 | ... CH18: =CG18+CH16-CH17
A20: Plano Agenda Cheia
A21: Participação nos novos | C21: =IF(C2>=9,Premissas!$F$82+IF(C2<13,Premissas!$F$89,0),0) | D21: =IF(D2>=9,Premissas!$F$82+IF(D2<13,Premissas!$F$89,0),0) | E21: =IF(E2>=9,Premissas!$F$82+IF(E2<13,Premissas!$F$89,0),0) | F21: =IF(F2>=9,Premissas!$F$82+IF(F2<13,Premissas!$F$89,0),0) | G21: =IF(G2>=9,Premissas!$F$82+IF(G2<13,Premissas!$F$89,0),0) | H21: =IF(H2>=9,Premissas!$F$82+IF(H2<13,Premissas!$F$89,0),0) | I21: =IF(I2>=9,Premissas!$F$82+IF(I2<13,Premissas!$F$89,0),0) | J21: =IF(J2>=9,Premissas!$F$82+IF(J2<13,Premissas!$F$89,0),0) | ... CH21: =IF(CH2>=9,Premissas!$F$82+IF(CH2<13,Premissas!$F$89,0),0)
A22: Novos | C22: =C12*C21 | D22: =D12*D21 | E22: =E12*E21 | F22: =F12*F21 | G22: =G12*G21 | H22: =H12*H21 | I22: =I12*I21 | J22: =J12*J21 | ... CH22: =CH12*CH21
A23: Cancelados | C23: =0*Premissas!$F$83 | D23: =C24*Premissas!$F$83 | E23: =D24*Premissas!$F$83 | F23: =E24*Premissas!$F$83 | G23: =F24*Premissas!$F$83 | H23: =G24*Premissas!$F$83 | I23: =H24*Premissas!$F$83 | J23: =I24*Premissas!$F$83 | K23: =J24*Premissas!$F$83 | ... CH23: =CG24*Premissas!$F$83
A24: Ativos no fim do mês | C24: =0+C22-C23 | D24: =C24+D22-D23 | E24: =D24+E22-E23 | F24: =E24+F22-F23 | G24: =F24+G22-G23 | H24: =G24+H22-H23 | I24: =H24+I22-I23 | J24: =I24+J22-J23 | K24: =J24+K22-K23 | ... CH24: =CG24+CH22-CH23
A26: Plano Clínica
A27: Participação nos novos | C27: =IF(C2>=13,Premissas!$F$89,0) | D27: =IF(D2>=13,Premissas!$F$89,0) | E27: =IF(E2>=13,Premissas!$F$89,0) | F27: =IF(F2>=13,Premissas!$F$89,0) | G27: =IF(G2>=13,Premissas!$F$89,0) | H27: =IF(H2>=13,Premissas!$F$89,0) | I27: =IF(I2>=13,Premissas!$F$89,0) | J27: =IF(J2>=13,Premissas!$F$89,0) | ... CH27: =IF(CH2>=13,Premissas!$F$89,0)
A28: Novos | C28: =C12*C27 | D28: =D12*D27 | E28: =E12*E27 | F28: =F12*F27 | G28: =G12*G27 | H28: =H12*H27 | I28: =I12*I27 | J28: =J12*J27 | ... CH28: =CH12*CH27
A29: Cancelados | C29: =0*Premissas!$F$90 | D29: =C30*Premissas!$F$90 | E29: =D30*Premissas!$F$90 | F29: =E30*Premissas!$F$90 | G29: =F30*Premissas!$F$90 | H29: =G30*Premissas!$F$90 | I29: =H30*Premissas!$F$90 | J29: =I30*Premissas!$F$90 | K29: =J30*Premissas!$F$90 | ... CH29: =CG30*Premissas!$F$90
A30: Ativos no fim do mês | C30: =0+C28-C29 | D30: =C30+D28-D29 | E30: =D30+E28-E29 | F30: =E30+F28-F29 | G30: =F30+G28-G29 | H30: =G30+H28-H29 | I30: =H30+I28-I29 | J30: =I30+J28-J29 | K30: =J30+K28-K29 | ... CH30: =CG30+CH28-CH29
A32: Clientes e receita
A33: Clientes ativos | C33: =C18+C24+C30 | D33: =D18+D24+D30 | E33: =E18+E24+E30 | F33: =F18+F24+F30 | G33: =G18+G24+G30 | H33: =H18+H24+H30 | I33: =I18+I24+I30 | J33: =J18+J24+J30 | ... CH33: =CH18+CH24+CH30
A34: Mercado endereçável no mês | C34: =Premissas!$F$12+IF(C2>=Premissas!$F$13,Premissas!$F$15,0) | D34: =Premissas!$F$12+IF(D2>=Premissas!$F$13,Premissas!$F$15,0) | E34: =Premissas!$F$12+IF(E2>=Premissas!$F$13,Premissas!$F$15,0) | F34: =Premissas!$F$12+IF(F2>=Premissas!$F$13,Premissas!$F$15,0) | G34: =Premissas!$F$12+IF(G2>=Premissas!$F$13,Premissas!$F$15,0) | H34: =Premissas!$F$12+IF(H2>=Premissas!$F$13,Premissas!$F$15,0) | I34: =Premissas!$F$12+IF(I2>=Premissas!$F$13,Premissas!$F$15,0) | J34: =Premissas!$F$12+IF(J2>=Premissas!$F$13,Premissas!$F$15,0) | ... CH34: =Premissas!$F$12+IF(CH2>=Premissas!$F$13,Premissas!$F$15,0)
A35: Participação no mercado endereçável | C35: =C33/C34 | D35: =D33/D34 | E35: =E33/E34 | F35: =F33/F34 | G35: =G33/G34 | H35: =H33/H34 | I35: =I33/I34 | J35: =J33/J34 | ... CH35: =CH33/CH34
A36: Receita de mensalidades | C36: =C18*Premissas!$F$74+C24*Premissas!$F$80+C30*Premissas!$F$87 | D36: =D18*Premissas!$F$74+D24*Premissas!$F$80+D30*Premissas!$F$87 | E36: =E18*Premissas!$F$74+E24*Premissas!$F$80+E30*Premissas!$F$87 | F36: =F18*Premissas!$F$74+F24*Premissas!$F$80+F30*Premissas!$F$87 | G36: =G18*Premissas!$F$74+G24*Premissas!$F$80+G30*Premissas!$F$87 | H36: =H18*Premissas!$F$74+H24*Premissas!$F$80+H30*Premissas!$F$87 | I36: =I18*Premissas!$F$74+I24*Premissas!$F$80+I30*Premissas!$F$87 | J36: =J18*Premissas!$F$74+J24*Premissas!$F$80+J30*Premissas!$F$87 | ... CH36: =CH18*Premissas!$F$74+CH24*Premissas!$F$80+CH30*Premissas!$F$87
A37: Receita de implantação | C37: =C16*Premissas!$F$75+C22*Premissas!$F$81+C28*Premissas!$F$88 | D37: =D16*Premissas!$F$75+D22*Premissas!$F$81+D28*Premissas!$F$88 | E37: =E16*Premissas!$F$75+E22*Premissas!$F$81+E28*Premissas!$F$88 | F37: =F16*Premissas!$F$75+F22*Premissas!$F$81+F28*Premissas!$F$88 | G37: =G16*Premissas!$F$75+G22*Premissas!$F$81+G28*Premissas!$F$88 | H37: =H16*Premissas!$F$75+H22*Premissas!$F$81+H28*Premissas!$F$88 | I37: =I16*Premissas!$F$75+I22*Premissas!$F$81+I28*Premissas!$F$88 | J37: =J16*Premissas!$F$75+J22*Premissas!$F$81+J28*Premissas!$F$88 | ... CH37: =CH16*Premissas!$F$75+CH22*Premissas!$F$81+CH28*Premissas!$F$88
A38: Receita por consulta agendada | C38: =(C24*Premissas!$F$86+C30*Premissas!$F$93)*Premissas!$F$73 | D38: =(D24*Premissas!$F$86+D30*Premissas!$F$93)*Premissas!$F$73 | E38: =(E24*Premissas!$F$86+E30*Premissas!$F$93)*Premissas!$F$73 | F38: =(F24*Premissas!$F$86+F30*Premissas!$F$93)*Premissas!$F$73 | G38: =(G24*Premissas!$F$86+G30*Premissas!$F$93)*Premissas!$F$73 | H38: =(H24*Premissas!$F$86+H30*Premissas!$F$93)*Premissas!$F$73 | I38: =(I24*Premissas!$F$86+I30*Premissas!$F$93)*Premissas!$F$73 | J38: =(J24*Premissas!$F$86+J30*Premissas!$F$93)*Premissas!$F$73 | ... CH38: =(CH24*Premissas!$F$86+CH30*Premissas!$F$93)*Premissas!$F$73
A39: Receita bruta | C39: =C36+C37+C38 | D39: =D36+D37+D38 | E39: =E36+E37+E38 | F39: =F36+F37+F38 | G39: =G36+G37+G38 | H39: =H36+H37+H38 | I39: =I36+I37+I38 | J39: =J36+J37+J38 | ... CH39: =CH36+CH37+CH38
A40: Receita recorrente mensal (mensalidades + consultas) | C40: =C36+C38 | D40: =D36+D38 | E40: =E36+E38 | F40: =F36+F38 | G40: =G36+G38 | H40: =H36+H38 | I40: =I36+I38 | J40: =J36+J38 | ... CH40: =CH36+CH38
A41: Receita recorrente anualizada (MRR × 12) | C41: =C40*12 | D41: =D40*12 | E41: =E40*12 | F41: =F40*12 | G41: =G40*12 | H41: =H40*12 | I41: =I40*12 | J41: =J40*12 | ... CH41: =CH40*12
A42: Impostos sobre a receita | C42: =C39*IF(SUMIFS($C$39:$CH$39,$C$2:$CH$2,">="&(C2-12),$C$2:$CH$2,"<"&C2)>4800000,Premissas!$F$10,Premissas!$F$9) | D42: =D39*IF(SUMIFS($C$39:$CH$39,$C$2:$CH$2,">="&(D2-12),$C$2:$CH$2,"<"&D2)>4800000,Premissas!$F$10,Premissas!$F$9) | E42: =E39*IF(SUMIFS($C$39:$CH$39,$C$2:$CH$2,">="&(E2-12),$C$2:$CH$2,"<"&E2)>4800000,Premissas!$F$10,Premissas!$F$9) | F42: =F39*IF(SUMIFS($C$39:$CH$39,$C$2:$CH$2,">="&(F2-12),$C$2:$CH$2,"<"&F2)>4800000,Premissas!$F$10,Premissas!$F$9) | G42: =G39*IF(SUMIFS($C$39:$CH$39,$C$2:$CH$2,">="&(G2-12),$C$2:$CH$2,"<"&G2)>4800000,Premissas!$F$10,Premissas!$F$9) | H42: =H39*IF(SUMIFS($C$39:$CH$39,$C$2:$CH$2,">="&(H2-12),$C$2:$CH$2,"<"&H2)>4800000,Premissas!$F$10,Premissas!$F$9) | I42: =I39*IF(SUMIFS($C$39:$CH$39,$C$2:$CH$2,">="&(I2-12),$C$2:$CH$2,"<"&I2)>4800000,Premissas!$F$10,Premissas!$F$9) | J42: =J39*IF(SUMIFS($C$39:$CH$39,$C$2:$CH$2,">="&(J2-12),$C$2:$CH$2,"<"&J2)>4800000,Premissas!$F$10,Premissas!$F$9) | ... CH42: =CH39*IF(SUMIFS($C$39:$CH$39,$C$2:$CH$2,">="&(CH2-12),$C$2:$CH$2,"<"&CH2)>4800000,Premissas!$F$10,Premissas!$F$9)
A43: Meios de pagamento | C43: =C39*Premissas!$F$11 | D43: =D39*Premissas!$F$11 | E43: =E39*Premissas!$F$11 | F43: =F39*Premissas!$F$11 | G43: =G39*Premissas!$F$11 | H43: =H39*Premissas!$F$11 | I43: =I39*Premissas!$F$11 | J43: =J39*Premissas!$F$11 | ... CH43: =CH39*Premissas!$F$11
A44: Receita líquida | C44: =C39-C42-C43 | D44: =D39-D42-D43 | E44: =E39-E42-E43 | F44: =F39-F42-F43 | G44: =G39-G42-G43 | H44: =H39-H42-H43 | I44: =I39-I42-I43 | J44: =J39-J42-J43 | ... CH44: =CH39-CH42-CH43
A46: Custo do serviço
...

Sheet Cenarios
A1: Cenários e testes de estresse (valores gerados por sensibilidade_v2.py)
A3: Modelo A: software por assinatura
A4: Indicador | B4: Conservador | C4: Base | D4: Otimista
A5: Receita recorrente anualizada no ano 5 | B5: 9425293.1 | C5: 20911682 | D5: 50946261
A6: Receita recorrente anualizada no ano 7 | B6: 16259058 | C6: 37026396 | D6: 97798177
A7: Mês de equilíbrio (EBITDA positivo daí em diante) | B7: não chega | C7: 65 | D7: 31
A8: Capital necessário (pior caixa acumulado) | B8: 44020986 | C8: 14551737 | D8: 4842978.2
A9: Margem bruta no ano 5 | B9: 0.75429414 | C9: 0.82050529 | D9: 0.85712085
A10: LTV/CAC do plano principal (Consultório / Agenda Cheia), mídia paga | B10: 1.2328071 | C10: 2.1461778 | D10: 4.4839917
A11: LTV/CAC ponderado pelo mix de novos clientes (mídia paga) | B11: 1.3756812 | C11: 2.5912237 | D11: 6.65219
A12: Recuperação do CAC do plano principal (meses) | B12: 12.060811 | C12: 8.7808476 | D12: 5.7418576
A13: Mês em que a receita anualizada chega a R$ 50 mi | B13: não chega | C13: não chega | D13: 60
A14: Participação no mercado nesse mês | D14: 0.010031052
A15: Receita por pessoa no ano 5 | B15: 167417.66 | C15: 334474.96 | D15: 618215.34
A16: Clientes ativos no ano 5 | B16: 948.55358 | C16: 2126.4989 | D16: 4564.1287
A18: Modelo B: agência operada por agentes
A19: Indicador | B19: Conservador | C19: Base | D19: Otimista
A20: Receita recorrente anualizada no ano 5 | B20: 14804181 | C20: 34605229 | D20: 77481260
A21: Receita recorrente anualizada no ano 7 | B21: 25174222 | C21: 60631763 | D21: 1.5022428e+08
A22: Mês de equilíbrio (EBITDA positivo daí em diante) | B22: não chega | C22: 56 | D22: 29
A23: Capital necessário (pior caixa acumulado) | B23: 55143316 | C23: 12489561 | D23: 4327759.4
A24: Margem bruta no ano 5 | B24: 0.40297964 | C24: 0.60280085 | D24: 0.71874857
A25: LTV/CAC do plano principal (Consultório / Agenda Cheia), mídia paga | B25: 1.1074872 | C25: 2.8790667 | D25: 7.1815333
A26: LTV/CAC ponderado pelo mix de novos clientes (mídia paga) | B26: 1.0079462 | C26: 2.6539549 | D26: 6.6889438
A27: Recuperação do CAC do plano principal (meses) | B27: 14.765475 | C27: 7.2935641 | D27: 4.7868419
A28: Mês em que a receita anualizada chega a R$ 50 mi | B28: não chega | C28: 75 | D28: 49
A29: Participação no mercado nesse mês | C29: 0.0082530084 | D29: 0.0056289594
A30: Receita por pessoa no ano 5 | B30: 162593.26 | C30: 301399.11 | D30: 478291.89
A31: Clientes ativos no ano 5 | B31: 792.82873 | C31: 1855.9642 | D31: 3914.079
A33: Testes de estresse do Modelo B (cenário base, uma aposta por vez)
A34: Teste | B34: Receita recorrente anualizada no ano 5 | C34: Receita recorrente anualizada no ano 7 | D34: Mês de equilíbrio (EBITDA positivo daí em diante) | E34: Capital necessário (pior caixa acumulado) | F34: Margem bruta no ano 5 | G34: LTV/CAC do plano principal (Consultório / Agenda Cheia), mídia paga | H34: LTV/CAC ponderado pelo mix de novos clientes (mídia paga) | I34: Recuperação do CAC do plano principal (meses) | J34: Mês em que a receita anualizada chega a R$ 50 mi | K34: Participação no mercado nesse mês | L34: Receita por pessoa no ano 5 | M34: Clientes ativos no ano 5
A35: B se as apostas se confirmarem (churn de agência, 40 a 70 contas por especialista, CAC R$ 5.500) | B35: 47196517 | C35: 88530927 | D35: 41 | E35: 7937541.8 | F35: 0.66108754 | G35: 6.0680606 | H35: 5.0463871 | I35: 5.6437462 | J35: 62 | K35: 0.008451415 | L35: 394735.13 | M35: 2590.3452
A36: B com cobrança de R$ 30 por consulta (só com parecer jurídico favorável) | B36: 38907850 | C36: 68322314 | D36: 51 | E36: 9358328.5 | F36: 0.64387192 | G36: 3.6239897 | H36: 3.2126472 | I36: 5.7354797 | J36: 69 | K36: 0.0072195857 | L36: 336158.47 | M36: 1855.9642
A37: B com as apostas confirmadas e cobrança por consulta (o base da v2) | B37: 52884368 | C37: 99344534 | D37: 39 | E37: 6532844.1 | F37: 0.69556431 | G37: 7.5353333 | H37: 5.9834409 | I37: 4.5206842 | J37: 59 | K37: 0.007637957 | L37: 439438.14 | M37: 2590.3452
A38: B com o dobro de contas por especialista, sem mudar o resto | B38: 34605229 | C38: 60631763 | D38: 51 | E38: 9248513.8 | F38: 0.71353444 | G38: 3.3918872 | H38: 3.1411344 | I38: 6.144461 | J38: 75 | K38: 0.0082530084 | L38: 408563.86 | M38: 1855.9642
A39: B com churn de agência com contrato, sem mudar o resto | B39: 43360493 | C39: 81127016 | D39: 51 | E39: 9925656.4 | F39: 0.60395094 | G39: 4.7071624 | H39: 3.9026571 | I39: 7.2935641 | J39: 65 | K39: 0.0085417363 | L39: 323042.43 | M39: 2379.723
A40: Sem expansão para dentistas | B40: 20736220 | C40: 35830707 | D40: 81 | E40: 19276295 | F40: 0.60309218 | G40: 2.8790667 | H40: 2.6539549 | I40: 7.2935641 | J40: não chega | L40: 230177.78 | M40: 1110.3203

Sheet Sensibilidade
A1: Sensibilidade no cenário base: quanto cada premissa mexe no resultado (valores gerados por script)
A3: Modelo A
A4: Premissa (ordenada pelo impacto no capital e na receita) | B4: Valor baixo | C4: Valor alto | D4: ARR ano 7 (baixo) | E4: ARR ano 7 (alto) | F4: Diferença no ARR | G4: Capital necessário (baixo) | H4: Capital necessário (alto) | I4: LTV/CAC (baixo / alto)
A5: CAC na mídia paga | B5: 6000 | C5: 3000 | D5: 31516385 | E5: 48046418 | F5: 16530033 | G5: 19630810 | H5: 9444707.4 | I5: 1.6x / 3.2x
A6: Preço do Consultório | B6: 497 | C6: 897 | D6: 33047651 | E6: 41005141 | F6: 7957489.3 | G6: 19124212 | H6: 11626535 | I6: 1.5x / 2.8x
A7: Parcerias (multiplicador) | B7: 0.6 | C7: 1.3 | D7: 31031855 | E7: 41522302 | F7: 10490446 | G7: 19021797 | H7: 12358774 | I7: 2.1x / 2.1x
A8: Churn do Consultório | B8: 0.07 | C8: 0.04 | D8: 34413704 | E8: 40791717 | F8: 6378013.5 | G8: 16213739 | H8: 12967525 | I8: 1.7x / 2.9x
A9: Indicação (% da base por mês) | B9: 0.005 | C9: 0.015 | D9: 34559955 | E9: 39821819 | F9: 5261864.1 | G9: 15737540 | H9: 13450833 | I9: 2.1x / 2.1x
A10: Churn do Essencial | B10: 0.09 | C10: 0.055 | D10: 35924257 | E10: 38211599 | F10: 2287342.1 | G10: 15226253 | H10: 13933188 | I10: 2.1x / 2.1x
A11: Custo direto do Consultório | B11: 80 | C11: 30 | D11: 37026396 | E11: 37026396 | F11: 0 | G11: 15303496 | H11: 14066164 | I11: 2.0x / 2.2x
A12: Base: ARR ano 7 = R$ 37.026.396; capital necessário = R$ 14.551.737
A14: Modelo B
A15: Premissa (ordenada pelo impacto no capital e na receita) | B15: Valor baixo | C15: Valor alto | D15: ARR ano 7 (baixo) | E15: ARR ano 7 (alto) | F15: Diferença no ARR | G15: Capital necessário (baixo) | H15: Capital necessário (alto) | I15: LTV/CAC (baixo / alto)
A16: Preço da Agenda Cheia | B16: 1290 | C16: 2290 | D16: 52851815 | E16: 68411710 | F16: 15559896 | G16: 19693977 | H16: 9143550.1 | I16: 1.6x / 4.1x
A17: CAC na mídia paga | B17: 9000 | C17: 5000 | D17: 52131039 | E17: 69812544 | F17: 17681505 | G17: 16346275 | H17: 9864383 | I17: 2.1x / 3.7x
A18: Churn da Agenda Cheia | B18: 0.065 | C18: 0.03 | D18: 55298076 | E18: 71845204 | F18: 16547128 | G18: 13765013 | H18: 10810516 | I18: 2.2x / 4.7x
A19: Preço por consulta atribuída | B19: 0 | C19: 30 | D19: 60631763 | E19: 68322314 | F19: 7690551.2 | G19: 12489561 | H19: 9358328.5 | I19: 2.9x / 3.6x
A20: Contas por especialista (Agenda Cheia) | B20: 20 | C20: 50 | D20: 60631763 | E20: 60631763 | F20: 0 | G20: 14820731 | H20: 11044277 | I20: 2.4x / 3.3x
A21: Churn da Presença | B21: 0.07 | C21: 0.035 | D21: 56686722 | E21: 68817425 | F21: 12130703 | G21: 13400854 | H21: 11131736 | I21: 2.9x / 2.9x
A22: Custo dos agentes por conta (Agenda Cheia) | B22: 400 | C22: 150 | D22: 60631763 | E22: 60631763 | F22: 0 | G22: 15069945 | H22: 11708227 | I22: 2.3x / 3.1x
A23: Contas por especialista (Presença) | B23: 35 | C23: 90 | D23: 60631763 | E23: 60631763 | F23: 0 | G23: 13935983 | H23: 11155129 | I23: 2.9x / 2.9x
A24: Indicação (% da base por mês) | B24: 0.005 | C24: 0.015 | D24: 56314643 | E24: 65561171 | F24: 9246527.5 | G24: 13286448 | H24: 11731195 | I24: 2.9x / 2.9x
A25: Base: ARR ano 7 = R$ 60.631.763; capital necessário = R$ 12.489.561
