Workbook

Sheet Premissas
A1: Jalecon: premissas do modelo financeiro
A2: Legenda: texto azul = premissa editável · preto = fórmula · verde = vínculo com outra aba · fundo amarelo = premissa-chave a validar. Valores em R$ nominais, mês 1 = jan/2027.
A4: Geral
A5: Câmbio (R$ por US$) | B5: 5.4 | I5: Premissa do grupo; ajustar à cotação do dia da banca.
A6: Carga tributária no Simples Nacional (% da receita) | B6: 0.11 | I6: Alíquota efetiva média estimada para SaaS no Anexo III/V; confirmar com contador.
A7: Carga tributária após sair do Simples (% da receita) | B7: 0.1633 | I7: Aproximação de Lucro Presumido (PIS/COFINS 3,65% + ISS ~2,9% + IRPJ/CSLL presumidos ~9,8%); confirmar com contador.
A8: Limite anual do Simples Nacional (R$) | B8: 4800000 | I8: Lei Complementar 123/2006.
A9: Taxa de meio de pagamento (% da receita) | B9: 0.035 | I9: Média de gateways de cartão/Pix recorrente.
A10: Encargos e benefícios CLT (% do salário) | B10: 0.7 | I10: Média de mercado para CLT no Brasil.
A11: Encargos sobre pró-labore (% do pró-labore) | B11: 0.2 | I11: INSS patronal no pró-labore (fora do Simples Anexo III).
A12: % de clientes no plano anual | B12: 0.3 | I12: Premissa; validar na pré-venda.
A13: Desconto do plano anual | B13: 0.15 | I13: Premissa de política comercial.
A14: Aporte pré-seed no mês 1 (R$) | B14: 3300000 | I14: Valor a decidir após o modelo; ver aba Resumo (necessidade de caixa).
A16: Planos
A17: Item | B17: Essencial | C17: Consultório | D17: Autoridade | E17: Clínica | I17: Nota
A18: Preço mensal (R$) | B18: 297 | C18: 697 | D18: 1497 | E18: 3900 | I18: Ancorado entre geradores de post (R$ 50 a 600) e agências (R$ 1,5 mil a 12 mil). Validar com Van Westendorp.
A19: Taxa de implantação média por novo cliente (R$) | B19: 0 | C19: 490 | D19: 990 | E19: 2900 | I19: Marca + site + diagnóstico completo; isenta no plano anual (já refletido na média).
A20: Churn mensal no ano 1 (cenário base) | B20: 0.05 | C20: 0.03 | D20: 0.025 | E20: 0.02 | I20: SaaS para pequenos negócios tem mediana perto de 3,5%/mês; planos maiores retêm mais.
A21: Custo de IA por conta/mês (US$) | B21: 4 | C21: 9 | D21: 18 | E21: 45 | I21: Estimativa: ~0,6 a 1,5 milhão de tokens/mês por conta com Claude Sonnet 5.5 (US$ 2/10 por milhão) e cache; inclui imagens.
A22: Infra, APIs e hospedagem por conta/mês (R$) | B22: 8 | C22: 12 | D22: 18 | E22: 40 | I22: Hospedagem de site, banco de dados, APIs de publicação e WhatsApp.
A23: Contas por gestor de conta humano | B23: 0 | C23: 0 | D23: 40 | E23: 20 | I23: Só planos com revisão humana dedicada. 0 = sem gestor.
A24: Salário mensal do gestor de conta (R$) | B24: 7000
A25: Melhoria anual do churn (redução relativa por ano) | B25: 0.08 | I25: Produto e sucesso do cliente amadurecem; aplicado a partir do ano 2.
A27: Mix de novos clientes por plano
A28: Ano | B28: Essencial | C28: Consultório | D28: Autoridade | E28: Clínica | F28: Soma
A29: Ano 1 | B29: 0.4 | C29: 0.5 | D29: 0.1 | E29: 0 | F29: =SUM(B29:E29) -> 1
A30: Ano 2 | B30: 0.35 | C30: 0.5 | D30: 0.13 | E30: 0.02 | F30: =SUM(B30:E30) -> 1
A31: Ano 3 | B31: 0.3 | C31: 0.5 | D31: 0.15 | E31: 0.05 | F31: =SUM(B31:E31) -> 1
A32: Ano 4 | B32: 0.28 | C32: 0.5 | D32: 0.16 | E32: 0.06 | F32: =SUM(B32:E32) -> 1
A33: Ano 5 | B33: 0.25 | C33: 0.5 | D33: 0.18 | E33: 0.07 | F33: =SUM(B33:E33) -> 1
A35: Aquisição e receitas adicionais (cenário base)
A36: Item | B36: Ano 1 | C36: Ano 2 | D36: Ano 3 | E36: Ano 4 | F36: Ano 5 | H36: Nota
A37: Mídia paga e inbound: orçamento mensal (R$) | B37: 25000 | C37: 70000 | D37: 150000 | E37: 240000 | F37: 320000 | H37: Meta, Google, conteúdo, ferramentas de captação.
A38: Parcerias: novos clientes por mês | B38: 4 | C38: 12 | D38: 25 | E38: 40 | F38: 55 | H38: Residências, sociedades de especialidade, contadores médicos, coworkings de consultório.
A39: Serviços adicionais (% da receita recorrente) | B39: 0.05 | C39: 0.08 | D39: 0.11 | E39: 0.13 | F39: 0.15 | H39: Check-up de conformidade avulso, gestão de tráfego, ensaio de fotos (comissão), domínio.
A40: CAC de mídia paga no ano 1 (R$ por cliente) | B40: 1800 | H40: Premissa-chave: SaaS para pequenos negócios com venda assistida. Validar com testes de campanha.
A41: Queda anual do CAC (marca, indicação, conteúdo) | B41: 0.07
A42: CAC de mídia paga por ano (R$) | B42: =$B$40 -> 1800 | C42: =B42*(1-$B$41) -> 1674 | D42: =C42*(1-$B$41) -> 1556.82 | E42: =D42*(1-$B$41) -> 1447.8426 | F42: =E42*(1-$B$41) -> 1346.4936
A43: Indicação: novos clientes por mês (% da base ativa) | B43: 0.01
A45: Cenários
...

Sheet Resumo
A1: Jalecon: resumo anual e comparação de cenários
A2: Todos os valores vêm das abas Modelo_*. Para mudar premissas, edite a aba Premissas.
A4: DRE anual: cenário base (R$)
A5: Linha | B5: Ano 1 (2027) | C5: Ano 2 (2028) | D5: Ano 3 (2029) | E5: Ano 4 (2030) | F5: Ano 5 (2031)
A6: Clientes ativos no fim do ano | B6: =INDEX(Modelo_Base!$C$26:$BJ$26,1*12) -> 185.33502 | C6: =INDEX(Modelo_Base!$C$26:$BJ$26,2*12) -> 709.49457 | D6: =INDEX(Modelo_Base!$C$26:$BJ$26,3*12) -> 1870.4941 | E6: =INDEX(Modelo_Base!$C$26:$BJ$26,4*12) -> 3790.9775 | F6: =INDEX(Modelo_Base!$C$26:$BJ$26,5*12) -> 6465.1074
A7: ARR no fim do ano | B7: =INDEX(Modelo_Base!$C$62:$BJ$62,1*12) -> 1343066.9 | C7: =INDEX(Modelo_Base!$C$62:$BJ$62,2*12) -> 5944061.6 | D7: =INDEX(Modelo_Base!$C$62:$BJ$62,3*12) -> 18263945 | E7: =INDEX(Modelo_Base!$C$62:$BJ$62,4*12) -> 39883663 | F7: =INDEX(Modelo_Base!$C$62:$BJ$62,5*12) -> 72438951
A8: Receita recorrente | B8: =SUMIFS(Modelo_Base!$C$32:$BJ$32,Modelo_Base!$C$4:$BJ$4,1) -> 757819.82 | C8: =SUMIFS(Modelo_Base!$C$32:$BJ$32,Modelo_Base!$C$4:$BJ$4,2) -> 3917805.1 | D8: =SUMIFS(Modelo_Base!$C$32:$BJ$32,Modelo_Base!$C$4:$BJ$4,3) -> 12791921 | E8: =SUMIFS(Modelo_Base!$C$32:$BJ$32,Modelo_Base!$C$4:$BJ$4,4) -> 30231632 | F8: =SUMIFS(Modelo_Base!$C$32:$BJ$32,Modelo_Base!$C$4:$BJ$4,5) -> 57837829
A9: Taxas de implantação | B9: =SUMIFS(Modelo_Base!$C$33:$BJ$33,Modelo_Base!$C$4:$BJ$4,1) -> 77559.353 | C9: =SUMIFS(Modelo_Base!$C$33:$BJ$33,Modelo_Base!$C$4:$BJ$4,2) -> 301445.74 | D9: =SUMIFS(Modelo_Base!$C$33:$BJ$33,Modelo_Base!$C$4:$BJ$4,3) -> 865784.91 | E9: =SUMIFS(Modelo_Base!$C$33:$BJ$33,Modelo_Base!$C$4:$BJ$4,4) -> 1618375.9 | F9: =SUMIFS(Modelo_Base!$C$33:$BJ$33,Modelo_Base!$C$4:$BJ$4,5) -> 2578676
A10: Serviços adicionais | B10: =SUMIFS(Modelo_Base!$C$34:$BJ$34,Modelo_Base!$C$4:$BJ$4,1) -> 37890.991 | C10: =SUMIFS(Modelo_Base!$C$34:$BJ$34,Modelo_Base!$C$4:$BJ$4,2) -> 313424.41 | D10: =SUMIFS(Modelo_Base!$C$34:$BJ$34,Modelo_Base!$C$4:$BJ$4,3) -> 1407111.3 | E10: =SUMIFS(Modelo_Base!$C$34:$BJ$34,Modelo_Base!$C$4:$BJ$4,4) -> 3930112.2 | F10: =SUMIFS(Modelo_Base!$C$34:$BJ$34,Modelo_Base!$C$4:$BJ$4,5) -> 8675674.3
A11: Receita bruta | B11: =SUMIFS(Modelo_Base!$C$35:$BJ$35,Modelo_Base!$C$4:$BJ$4,1) -> 873270.17 | C11: =SUMIFS(Modelo_Base!$C$35:$BJ$35,Modelo_Base!$C$4:$BJ$4,2) -> 4532675.3 | D11: =SUMIFS(Modelo_Base!$C$35:$BJ$35,Modelo_Base!$C$4:$BJ$4,3) -> 15064817 | E11: =SUMIFS(Modelo_Base!$C$35:$BJ$35,Modelo_Base!$C$4:$BJ$4,4) -> 35780120 | F11: =SUMIFS(Modelo_Base!$C$35:$BJ$35,Modelo_Base!$C$4:$BJ$4,5) -> 69092179
A12: (-) Impostos | B12: =SUMIFS(Modelo_Base!$C$36:$BJ$36,Modelo_Base!$C$4:$BJ$4,1) -> -96059.718 | C12: =SUMIFS(Modelo_Base!$C$36:$BJ$36,Modelo_Base!$C$4:$BJ$4,2) -> -498594.28 | D12: =SUMIFS(Modelo_Base!$C$36:$BJ$36,Modelo_Base!$C$4:$BJ$4,3) -> -1657129.9 | E12: =SUMIFS(Modelo_Base!$C$36:$BJ$36,Modelo_Base!$C$4:$BJ$4,4) -> -5842893.6 | F12: =SUMIFS(Modelo_Base!$C$36:$BJ$36,Modelo_Base!$C$4:$BJ$4,5) -> -11282753
A13: Receita líquida | B13: =SUMIFS(Modelo_Base!$C$37:$BJ$37,Modelo_Base!$C$4:$BJ$4,1) -> 777210.45 | C13: =SUMIFS(Modelo_Base!$C$37:$BJ$37,Modelo_Base!$C$4:$BJ$4,2) -> 4034081 | D13: =SUMIFS(Modelo_Base!$C$37:$BJ$37,Modelo_Base!$C$4:$BJ$4,3) -> 13407687 | E13: =SUMIFS(Modelo_Base!$C$37:$BJ$37,Modelo_Base!$C$4:$BJ$4,4) -> 29937227 | F13: =SUMIFS(Modelo_Base!$C$37:$BJ$37,Modelo_Base!$C$4:$BJ$4,5) -> 57809426
A14: (-) Custo do serviço | B14: =SUMIFS(Modelo_Base!$C$43:$BJ$43,Modelo_Base!$C$4:$BJ$4,1) -> -138682.83 | C14: =SUMIFS(Modelo_Base!$C$43:$BJ$43,Modelo_Base!$C$4:$BJ$4,2) -> -776997.86 | D14: =SUMIFS(Modelo_Base!$C$43:$BJ$43,Modelo_Base!$C$4:$BJ$4,3) -> -2731580.3 | E14: =SUMIFS(Modelo_Base!$C$43:$BJ$43,Modelo_Base!$C$4:$BJ$4,4) -> -6702146.5 | F14: =SUMIFS(Modelo_Base!$C$43:$BJ$43,Modelo_Base!$C$4:$BJ$4,5) -> -13180217
A15: Lucro bruto | B15: =SUMIFS(Modelo_Base!$C$44:$BJ$44,Modelo_Base!$C$4:$BJ$4,1) -> 638527.62 | C15: =SUMIFS(Modelo_Base!$C$44:$BJ$44,Modelo_Base!$C$4:$BJ$4,2) -> 3257083.1 | D15: =SUMIFS(Modelo_Base!$C$44:$BJ$44,Modelo_Base!$C$4:$BJ$4,3) -> 10676107 | E15: =SUMIFS(Modelo_Base!$C$44:$BJ$44,Modelo_Base!$C$4:$BJ$4,4) -> 23235080 | F15: =SUMIFS(Modelo_Base!$C$44:$BJ$44,Modelo_Base!$C$4:$BJ$4,5) -> 44629209
A16: Margem bruta | B16: =IFERROR(B15/B13,0) -> 0.82156334 | C16: =IFERROR(C15/C13,0) -> 0.80739161 | D16: =IFERROR(D15/D13,0) -> 0.7962676 | E16: =IFERROR(E15/E13,0) -> 0.77612667 | F16: =IFERROR(F15/F13,0) -> 0.77200574
A17: (-) Pessoal | B17: =SUMIFS(Modelo_Base!$C$47:$BJ$47,Modelo_Base!$C$4:$BJ$4,1) -> -1926600 | C17: =SUMIFS(Modelo_Base!$C$47:$BJ$47,Modelo_Base!$C$4:$BJ$4,2) -> -4459200 | D17: =SUMIFS(Modelo_Base!$C$47:$BJ$47,Modelo_Base!$C$4:$BJ$4,3) -> -7456800 | E17: =SUMIFS(Modelo_Base!$C$47:$BJ$47,Modelo_Base!$C$4:$BJ$4,4) -> -10791000 | F17: =SUMIFS(Modelo_Base!$C$47:$BJ$47,Modelo_Base!$C$4:$BJ$4,5) -> -13705200
A18: (-) Mídia, comissões e marca | B18: =SUMIFS(Modelo_Base!$C$48:$BJ$48,Modelo_Base!$C$4:$BJ$4,1)+SUMIFS(Modelo_Base!$C$49:$BJ$49,Modelo_Base!$C$4:$BJ$4,1)+SUMIFS(Modelo_Base!$C$51:$BJ$51,Modelo_Base!$C$4:$BJ$4,1) -> -337911.08 | C18: =SUMIFS(Modelo_Base!$C$48:$BJ$48,Modelo_Base!$C$4:$BJ$4,2)+SUMIFS(Modelo_Base!$C$49:$BJ$49,Modelo_Base!$C$4:$BJ$4,2)+SUMIFS(Modelo_Base!$C$51:$BJ$51,Modelo_Base!$C$4:$BJ$4,2) -> -986629.2 | D18: =SUMIFS(Modelo_Base!$C$48:$BJ$48,Modelo_Base!$C$4:$BJ$4,3)+SUMIFS(Modelo_Base!$C$49:$BJ$49,Modelo_Base!$C$4:$BJ$4,3)+SUMIFS(Modelo_Base!$C$51:$BJ$51,Modelo_Base!$C$4:$BJ$4,3) -> -2117810.1 | E18: =SUMIFS(Modelo_Base!$C$48:$BJ$48,Modelo_Base!$C$4:$BJ$4,4)+SUMIFS(Modelo_Base!$C$49:$BJ$49,Modelo_Base!$C$4:$BJ$4,4)+SUMIFS(Modelo_Base!$C$51:$BJ$51,Modelo_Base!$C$4:$BJ$4,4) -> -3433710 | F18: =SUMIFS(Modelo_Base!$C$48:$BJ$48,Modelo_Base!$C$4:$BJ$4,5)+SUMIFS(Modelo_Base!$C$49:$BJ$49,Modelo_Base!$C$4:$BJ$4,5)+SUMIFS(Modelo_Base!$C$51:$BJ$51,Modelo_Base!$C$4:$BJ$4,5) -> -4657471.1
A19: (-) Demais despesas | B19: =SUMIFS(Modelo_Base!$C$50:$BJ$50,Modelo_Base!$C$4:$BJ$4,1)+SUMIFS(Modelo_Base!$C$52:$BJ$52,Modelo_Base!$C$4:$BJ$4,1)+SUMIFS(Modelo_Base!$C$53:$BJ$53,Modelo_Base!$C$4:$BJ$4,1)+SUMIFS(Modelo_Base!$C$54:$BJ$54,Modelo_Base!$C$4:$BJ$4,1) -> -156000 | C19: =SUMIFS(Modelo_Base!$C$50:$BJ$50,Modelo_Base!$C$4:$BJ$4,2)+SUMIFS(Modelo_Base!$C$52:$BJ$52,Modelo_Base!$C$4:$BJ$4,2)+SUMIFS(Modelo_Base!$C$53:$BJ$53,Modelo_Base!$C$4:$BJ$4,2)+SUMIFS(Modelo_Base!$C$54:$BJ$54,Modelo_Base!$C$4:$BJ$4,2) -> -324000 | D19: =SUMIFS(Modelo_Base!$C$50:$BJ$50,Modelo_Base!$C$4:$BJ$4,3)+SUMIFS(Modelo_Base!$C$52:$BJ$52,Modelo_Base!$C$4:$BJ$4,3)+SUMIFS(Modelo_Base!$C$53:$BJ$53,Modelo_Base!$C$4:$BJ$4,3)+SUMIFS(Modelo_Base!$C$54:$BJ$54,Modelo_Base!$C$4:$BJ$4,3) -> -612000 | E19: =SUMIFS(Modelo_Base!$C$50:$BJ$50,Modelo_Base!$C$4:$BJ$4,4)+SUMIFS(Modelo_Base!$C$52:$BJ$52,Modelo_Base!$C$4:$BJ$4,4)+SUMIFS(Modelo_Base!$C$53:$BJ$53,Modelo_Base!$C$4:$BJ$4,4)+SUMIFS(Modelo_Base!$C$54:$BJ$54,Modelo_Base!$C$4:$BJ$4,4) -> -984000 | F19: =SUMIFS(Modelo_Base!$C$50:$BJ$50,Modelo_Base!$C$4:$BJ$4,5)+SUMIFS(Modelo_Base!$C$52:$BJ$52,Modelo_Base!$C$4:$BJ$4,5)+SUMIFS(Modelo_Base!$C$53:$BJ$53,Modelo_Base!$C$4:$BJ$4,5)+SUMIFS(Modelo_Base!$C$54:$BJ$54,Modelo_Base!$C$4:$BJ$4,5) -> -1380000
A20: EBITDA | B20: =SUMIFS(Modelo_Base!$C$56:$BJ$56,Modelo_Base!$C$4:$BJ$4,1) -> -1781983.5 | C20: =SUMIFS(Modelo_Base!$C$56:$BJ$56,Modelo_Base!$C$4:$BJ$4,2) -> -2512746.1 | D20: =SUMIFS(Modelo_Base!$C$56:$BJ$56,Modelo_Base!$C$4:$BJ$4,3) -> 489496.87 | E20: =SUMIFS(Modelo_Base!$C$56:$BJ$56,Modelo_Base!$C$4:$BJ$4,4) -> 8026370.2 | F20: =SUMIFS(Modelo_Base!$C$56:$BJ$56,Modelo_Base!$C$4:$BJ$4,5) -> 24886538
A21: Margem EBITDA | B21: =IFERROR(B20/B13,0) -> -2.292794 | C21: =IFERROR(C20/C13,0) -> -0.62287943 | D21: =IFERROR(D20/D13,0) -> 0.036508673 | E21: =IFERROR(E20/E13,0) -> 0.26810667 | F21: =IFERROR(F20/F13,0) -> 0.43049273
A22: Caixa no fim do ano | B22: =INDEX(Modelo_Base!$C$60:$BJ$60,1*12) -> 1518016.5 | C22: =INDEX(Modelo_Base!$C$60:$BJ$60,2*12) -> 7005270.5 | D22: =INDEX(Modelo_Base!$C$60:$BJ$60,3*12) -> 7494767.3 | E22: =INDEX(Modelo_Base!$C$60:$BJ$60,4*12) -> 15521138 | F22: =INDEX(Modelo_Base!$C$60:$BJ$60,5*12) -> 40407675
A23: Quadro de pessoas (sem gestores de conta) | B23: =INDEX(Premissas!$D$68:$H$68,1) -> 12 | C23: =INDEX(Premissas!$D$68:$H$68,2) -> 22 | D23: =INDEX(Premissas!$D$68:$H$68,3) -> 35 | E23: =INDEX(Premissas!$D$68:$H$68,4) -> 50 | F23: =INDEX(Premissas!$D$68:$H$68,5) -> 64
A25: Comparação de cenários
A26: Indicador | B26: Conservador | C26: Base | D26: Otimista
A27: Clientes ativos no fim do ano 3 | B27: =INDEX(Modelo_Conservador!$C$26:$BJ$26,3*12) -> 1058.8075 | C27: =INDEX(Modelo_Base!$C$26:$BJ$26,3*12) -> 1870.4941 | D27: =INDEX(Modelo_Otimista!$C$26:$BJ$26,3*12) -> 2882.8485
A28: Clientes ativos no fim do ano 5 | B28: =INDEX(Modelo_Conservador!$C$26:$BJ$26,5*12) -> 3529.566 | C28: =INDEX(Modelo_Base!$C$26:$BJ$26,5*12) -> 6465.1074 | D28: =INDEX(Modelo_Otimista!$C$26:$BJ$26,5*12) -> 10308.411
A29: ARR no fim do ano 3 (R$) | B29: =INDEX(Modelo_Conservador!$C$62:$BJ$62,3*12) -> 10493266 | C29: =INDEX(Modelo_Base!$C$62:$BJ$62,3*12) -> 18263945 | D29: =INDEX(Modelo_Otimista!$C$62:$BJ$62,3*12) -> 27851498
A30: ARR no fim do ano 5 (R$) | B30: =INDEX(Modelo_Conservador!$C$62:$BJ$62,5*12) -> 40211471 | C30: =INDEX(Modelo_Base!$C$62:$BJ$62,5*12) -> 72438951 | D30: =INDEX(Modelo_Otimista!$C$62:$BJ$62,5*12) -> 1.1409067e+08
A31: Receita bruta do ano 5 (R$) | B31: =SUMIFS(Modelo_Conservador!$C$35:$BJ$35,Modelo_Conservador!$C$4:$BJ$4,5) -> 37369921 | C31: =SUMIFS(Modelo_Base!$C$35:$BJ$35,Modelo_Base!$C$4:$BJ$4,5) -> 69092179 | D31: =SUMIFS(Modelo_Otimista!$C$35:$BJ$35,Modelo_Otimista!$C$4:$BJ$4,5) -> 1.1041608e+08
A32: EBITDA do ano 5 (R$) | B32: =SUMIFS(Modelo_Conservador!$C$56:$BJ$56,Modelo_Conservador!$C$4:$BJ$4,5) -> 5072790.7 | C32: =SUMIFS(Modelo_Base!$C$56:$BJ$56,Modelo_Base!$C$4:$BJ$4,5) -> 24886538 | D32: =SUMIFS(Modelo_Otimista!$C$56:$BJ$56,Modelo_Otimista!$C$4:$BJ$4,5) -> 51279553
A33: Mês do equilíbrio (EBITDA positivo daí em diante) | B33: =MIN(Modelo_Conservador!$C$65:$BJ$65) -> 50 | C33: =MIN(Modelo_Base!$C$65:$BJ$65) -> 30 | D33: =MIN(Modelo_Otimista!$C$65:$BJ$65) -> 27
A34: Menor saldo de caixa no período (R$) | B34: =MIN(Modelo_Conservador!$C$60:$BJ$60) -> -3219857.7 | C34: =MIN(Modelo_Base!$C$60:$BJ$60) -> 558638.49 | D34: =MIN(Modelo_Otimista!$C$60:$BJ$60) -> 1473064.4
A35: Total captado no período (R$) | B35: =SUM(Modelo_Conservador!$C$59:$BJ$59) -> 8300000 | C35: =SUM(Modelo_Base!$C$59:$BJ$59) -> 11300000 | D35: =SUM(Modelo_Otimista!$C$59:$BJ$59) -> 13300000
A36: Leitura: 999 em 'mês do equilíbrio' significa que o cenário não chega ao equilíbrio em 60 meses. Caixa negativo indica necessidade de captação adicional.
A38: Necessidade de caixa antes da rodada seed (cenário base)
A39: Queima acumulada até o mês anterior ao seed (R$) | B39: =-SUMIFS(Modelo_Base!$C$56:$BJ$56,Modelo_Base!$C$3:$BJ$3,"<"&INDEX(Premissas!$B$53:$D$53,2)) -> 2741361.5
A40: Reserva de segurança (meses de queima média) | B40: 3
A41: Pré-seed recomendado (R$) | B41: =ROUNDUP((B39+B39/(INDEX(Premissas!$B$53:$D$53,2)-1)*B40)/100000,0)*100000 -> 3300000 | C41: Cobre a queima até o seed mais a reserva, arredondado para R$ 100 mil.
A43: Clientes ativos no fim de cada ano por cenário (dados do gráfico)
A44: Ano | B44: Conservador | C44: Base | D44: Otimista
...

Sheet Unit_Economics
A1: Jalecon: economia por cliente (cenário base, ano 1)
A2: Margem de contribuição por conta e retorno do custo de aquisição.
A4: Item | B4: Essencial | C4: Consultório | D4: Autoridade | E4: Clínica
A5: Preço efetivo mensal (R$, após desconto anual) | B5: =Premissas!$B$18*(1-Premissas!$B$12*Premissas!$B$13) -> 283.635 | C5: =Premissas!$C$18*(1-Premissas!$B$12*Premissas!$B$13) -> 665.635 | D5: =Premissas!$D$18*(1-Premissas!$B$12*Premissas!$B$13) -> 1429.635 | E5: =Premissas!$E$18*(1-Premissas!$B$12*Premissas!$B$13) -> 3724.5
A6: (-) Impostos (Simples) | B6: =-B5*Premissas!$B$6 -> -31.19985 | C6: =-C5*Premissas!$B$6 -> -73.21985 | D6: =-D5*Premissas!$B$6 -> -157.25985 | E6: =-E5*Premissas!$B$6 -> -409.695
A7: (-) IA | B7: =-Premissas!$B$21*Premissas!$B$5 -> -21.6 | C7: =-Premissas!$C$21*Premissas!$B$5 -> -48.6 | D7: =-Premissas!$D$21*Premissas!$B$5 -> -97.2 | E7: =-Premissas!$E$21*Premissas!$B$5 -> -243
A8: (-) Infra e APIs | B8: =-Premissas!$B$22 -> -8 | C8: =-Premissas!$C$22 -> -12 | D8: =-Premissas!$D$22 -> -18 | E8: =-Premissas!$E$22 -> -40
A9: (-) Gestor de conta (rateio) | B9: =-IFERROR(Premissas!$B$24*(1+Premissas!$B$10)/Premissas!$B$23,0) -> 0 | C9: =-IFERROR(Premissas!$B$24*(1+Premissas!$B$10)/Premissas!$C$23,0) -> 0 | D9: =-IFERROR(Premissas!$B$24*(1+Premissas!$B$10)/Premissas!$D$23,0) -> -297.5 | E9: =-IFERROR(Premissas!$B$24*(1+Premissas!$B$10)/Premissas!$E$23,0) -> -595
A10: (-) Meio de pagamento | B10: =-B5*Premissas!$B$9 -> -9.927225 | C10: =-C5*Premissas!$B$9 -> -23.297225 | D10: =-D5*Premissas!$B$9 -> -50.037225 | E10: =-E5*Premissas!$B$9 -> -130.3575
A11: Margem de contribuição mensal (R$) | B11: =SUM(B5:B10) -> 212.90793 | C11: =SUM(C5:C10) -> 508.51792 | D11: =SUM(D5:D10) -> 809.63792 | E11: =SUM(E5:E10) -> 2306.4475
A12: Margem de contribuição (%) | B12: =IFERROR(B11/B5,0) -> 0.75064052 | C12: =IFERROR(C11/C5,0) -> 0.76395911 | D12: =IFERROR(D11/D5,0) -> 0.56632492 | E12: =IFERROR(E11/E5,0) -> 0.61926366
A13: Churn mensal (ano 1, base) | B13: =Premissas!$B$20 -> 0.05 | C13: =Premissas!$C$20 -> 0.03 | D13: =Premissas!$D$20 -> 0.025 | E13: =Premissas!$E$20 -> 0.02
A14: Vida média do cliente (meses) | B14: =IFERROR(1/B13,0) -> 20 | C14: =IFERROR(1/C13,0) -> 33.333333 | D14: =IFERROR(1/D13,0) -> 40 | E14: =IFERROR(1/E13,0) -> 50
A15: LTV: margem acumulada na vida do cliente (R$) | B15: =B11*B14 -> 4258.1585 | C15: =C11*C14 -> 16950.597 | D15: =D11*D14 -> 32385.517 | E15: =E11*E14 -> 115322.38
A16: CAC de mídia paga, ano 1 (R$) | B16: =Premissas!$B$42 -> 1800 | C16: =Premissas!$B$42 -> 1800 | D16: =Premissas!$B$42 -> 1800 | E16: =Premissas!$B$42 -> 1800
A17: LTV / CAC | B17: =IFERROR(B15/B16,0) -> 2.3656436 | C17: =IFERROR(C15/C16,0) -> 9.4169986 | D17: =IFERROR(D15/D16,0) -> 17.991954 | E17: =IFERROR(E15/E16,0) -> 64.067986
A18: Payback do CAC (meses) | B18: =IFERROR(B16/B11,0) -> 8.4543589 | C18: =IFERROR(C16/C11,0) -> 3.5396982 | D18: =IFERROR(D16/D11,0) -> 2.223216 | E18: =IFERROR(E16/E11,0) -> 0.78042097
A20: Referência de mercado: LTV/CAC acima de 3x e payback abaixo de 12 meses são considerados saudáveis para SaaS.

Sheet Mercado
A1: Jalecon: tamanho de mercado (TAM, SAM, SOM)
A3: Item | B3: Valor | C3: Fonte / nota
A4: Médicos em atividade no Brasil (projeção 2025) | B4: 635706 | C4: Demografia Médica no Brasil 2025 (FMUSP, AMB, Ministério da Saúde).
A5: % de médicos sem contrato formal (atuação autônoma/PJ) | B5: 0.48 | C5: Demografia Médica 2025: subiu de 30% (2015) para 48% (2025).
A6: % dos especialistas no Sudeste | B6: 0.554 | C6: Demografia Médica 2025.
A7: Receita anual média por conta (R$) | B7: =Unit_Economics!C5*12*(1+INDEX(Premissas!$B$39:$F$39,3)) -> 8866.2582 | C7: Plano Consultório + serviços adicionais do ano 3.
A8: TAM: todos os médicos × receita anual por conta (R$) | B8: =B4*B7 -> 5.6363335e+09 | C8: Mercado total se todo médico assinasse.
A9: SAM: médicos autônomos/PJ (quantidade) | B9: =B4*B5 -> 305138.88 | C9: Quem precisa gerar a própria demanda.
A10: SAM (R$ por ano) | B10: =B9*B7 -> 2.7054401e+09
A11: SOM ano 5: clientes do cenário base | B11: =INDEX(Modelo_Base!$C$26:$BJ$26,5*12) -> 6465.1074 | C11: Calculado pelo modelo.
A12: SOM como % do SAM | B12: =IFERROR(B11/B9,0) -> 0.021187426
A13: SOM (ARR do ano 5, cenário base, R$) | B13: =INDEX(Modelo_Base!$C$62:$BJ$62,5*12) -> 72438951
A14: Primeiro segmento: autônomos no Sudeste (quantidade, aproximação) | B14: =B9*B6 -> 169046.94 | C14: Aproximação usando a participação do Sudeste nos especialistas.
A16: Expansão: outras profissões de saúde (estimativas a confirmar nos conselhos)
A17: Cirurgiões-dentistas | B17: 400000 | C17: Estimativa; confirmar no painel do CFO.
A18: Psicólogos | B18: 500000 | C18: Estimativa; confirmar no CFP.
A19: Nutricionistas | B19: 150000 | C19: Estimativa; o CFN cita 'mais de 110 mil' em nota antiga.
A20: Fisioterapeutas | B20: 300000 | C20: Estimativa; confirmar no COFFITO.
A21: Profissionais na expansão (total) | B21: =SUM(B17:B20) -> 1350000
A22: TAM ampliado (médicos + expansão, R$ por ano) | B22: =(B4+B21)*B7 -> 1.7605782e+10

Sheet Modelo_Conservador
A1: Jalecon: projeção mensal, cenário conservador
A2: Cenário (1 = conservador, 2 = base, 3 = otimista) | B2: 1
A3: Mês | C3: 1 | D3: =C3+1 -> 2 | E3: =D3+1 -> 3 | F3: =E3+1 -> 4 | G3: =F3+1 -> 5 | H3: =G3+1 -> 6 | I3: =H3+1 -> 7 | J3: =I3+1 -> 8 | K3: =J3+1 -> 9 | ... BJ3: =BI3+1 -> 60
A4: Ano | C4: =ROUNDUP(C3/12,0) -> 1 | D4: =ROUNDUP(D3/12,0) -> 1 | E4: =ROUNDUP(E3/12,0) -> 1 | F4: =ROUNDUP(F3/12,0) -> 1 | G4: =ROUNDUP(G3/12,0) -> 1 | H4: =ROUNDUP(H3/12,0) -> 1 | I4: =ROUNDUP(I3/12,0) -> 1 | J4: =ROUNDUP(J3/12,0) -> 1 | ... BJ4: =ROUNDUP(BJ3/12,0) -> 5
A6: Aquisição
A7: Orçamento de mídia paga (R$) | C7: =INDEX(Premissas!$B$37:$F$37,C$4)*INDEX(Premissas!$B$51:$D$51,$B$2) -> 20000 | D7: =INDEX(Premissas!$B$37:$F$37,D$4)*INDEX(Premissas!$B$51:$D$51,$B$2) -> 20000 | E7: =INDEX(Premissas!$B$37:$F$37,E$4)*INDEX(Premissas!$B$51:$D$51,$B$2) -> 20000 | F7: =INDEX(Premissas!$B$37:$F$37,F$4)*INDEX(Premissas!$B$51:$D$51,$B$2) -> 20000 | G7: =INDEX(Premissas!$B$37:$F$37,G$4)*INDEX(Premissas!$B$51:$D$51,$B$2) -> 20000 | H7: =INDEX(Premissas!$B$37:$F$37,H$4)*INDEX(Premissas!$B$51:$D$51,$B$2) -> 20000 | I7: =INDEX(Premissas!$B$37:$F$37,I$4)*INDEX(Premissas!$B$51:$D$51,$B$2) -> 20000 | J7: =INDEX(Premissas!$B$37:$F$37,J$4)*INDEX(Premissas!$B$51:$D$51,$B$2) -> 20000 | ... BJ7: =INDEX(Premissas!$B$37:$F$37,BJ$4)*INDEX(Premissas!$B$51:$D$51,$B$2) -> 256000
A8: CAC de mídia paga (R$) | C8: =INDEX(Premissas!$B$42:$F$42,C$4)*INDEX(Premissas!$B$47:$D$47,$B$2) -> 2340 | D8: =INDEX(Premissas!$B$42:$F$42,D$4)*INDEX(Premissas!$B$47:$D$47,$B$2) -> 2340 | E8: =INDEX(Premissas!$B$42:$F$42,E$4)*INDEX(Premissas!$B$47:$D$47,$B$2) -> 2340 | F8: =INDEX(Premissas!$B$42:$F$42,F$4)*INDEX(Premissas!$B$47:$D$47,$B$2) -> 2340 | G8: =INDEX(Premissas!$B$42:$F$42,G$4)*INDEX(Premissas!$B$47:$D$47,$B$2) -> 2340 | H8: =INDEX(Premissas!$B$42:$F$42,H$4)*INDEX(Premissas!$B$47:$D$47,$B$2) -> 2340 | I8: =INDEX(Premissas!$B$42:$F$42,I$4)*INDEX(Premissas!$B$47:$D$47,$B$2) -> 2340 | J8: =INDEX(Premissas!$B$42:$F$42,J$4)*INDEX(Premissas!$B$47:$D$47,$B$2) -> 2340 | ... BJ8: =INDEX(Premissas!$B$42:$F$42,BJ$4)*INDEX(Premissas!$B$47:$D$47,$B$2) -> 1750.4417
A9: Novos clientes: mídia paga | C9: =IFERROR(C7/C8,0) -> 8.5470085 | D9: =IFERROR(D7/D8,0) -> 8.5470085 | E9: =IFERROR(E7/E8,0) -> 8.5470085 | F9: =IFERROR(F7/F8,0) -> 8.5470085 | G9: =IFERROR(G7/G8,0) -> 8.5470085 | H9: =IFERROR(H7/H8,0) -> 8.5470085 | I9: =IFERROR(I7/I8,0) -> 8.5470085 | J9: =IFERROR(J7/J8,0) -> 8.5470085 | ... BJ9: =IFERROR(BJ7/BJ8,0) -> 146.2488
A10: Novos clientes: parcerias | C10: =INDEX(Premissas!$B$38:$F$38,C$4)*INDEX(Premissas!$B$49:$D$49,$B$2) -> 2.8 | D10: =INDEX(Premissas!$B$38:$F$38,D$4)*INDEX(Premissas!$B$49:$D$49,$B$2) -> 2.8 | E10: =INDEX(Premissas!$B$38:$F$38,E$4)*INDEX(Premissas!$B$49:$D$49,$B$2) -> 2.8 | F10: =INDEX(Premissas!$B$38:$F$38,F$4)*INDEX(Premissas!$B$49:$D$49,$B$2) -> 2.8 | G10: =INDEX(Premissas!$B$38:$F$38,G$4)*INDEX(Premissas!$B$49:$D$49,$B$2) -> 2.8 | H10: =INDEX(Premissas!$B$38:$F$38,H$4)*INDEX(Premissas!$B$49:$D$49,$B$2) -> 2.8 | I10: =INDEX(Premissas!$B$38:$F$38,I$4)*INDEX(Premissas!$B$49:$D$49,$B$2) -> 2.8 | J10: =INDEX(Premissas!$B$38:$F$38,J$4)*INDEX(Premissas!$B$49:$D$49,$B$2) -> 2.8 | ... BJ10: =INDEX(Premissas!$B$38:$F$38,BJ$4)*INDEX(Premissas!$B$49:$D$49,$B$2) -> 38.5
A11: Novos clientes: indicação | C11: =0 -> 0 | D11: =C26*Premissas!$B$43*INDEX(Premissas!$B$49:$D$49,$B$2) -> 0.07942906 | E11: =D26*Premissas!$B$43*INDEX(Premissas!$B$49:$D$49,$B$2) -> 0.15554196 | F11: =E26*Premissas!$B$43*INDEX(Premissas!$B$49:$D$49,$B$2) -> 0.2284914 | G11: =F26*Premissas!$B$43*INDEX(Premissas!$B$49:$D$49,$B$2) -> 0.29842238 | H11: =G26*Premissas!$B$43*INDEX(Premissas!$B$49:$D$49,$B$2) -> 0.36547255 | I11: =H26*Premissas!$B$43*INDEX(Premissas!$B$49:$D$49,$B$2) -> 0.42977269 | J11: =I26*Premissas!$B$43*INDEX(Premissas!$B$49:$D$49,$B$2) -> 0.49144701 | K11: =J26*Premissas!$B$43*INDEX(Premissas!$B$49:$D$49,$B$2) -> 0.55061357 | ... BJ11: =BI26*Premissas!$B$43*INDEX(Premissas!$B$49:$D$49,$B$2) -> 23.976994
A12: Novos clientes: total | C12: =C9+C10+C11 -> 11.347009 | D12: =D9+D10+D11 -> 11.426438 | E12: =E9+E10+E11 -> 11.502551 | F12: =F9+F10+F11 -> 11.5755 | G12: =G9+G10+G11 -> 11.645431 | H12: =H9+H10+H11 -> 11.712481 | I12: =I9+I10+I11 -> 11.776781 | J12: =J9+J10+J11 -> 11.838456 | ... BJ12: =BJ9+BJ10+BJ11 -> 208.72579
A13: Clientes por plano
A14: Novos: Essencial | C14: =C12*INDEX(Premissas!$B$29:$B$33,C$4) -> 4.5388034 | D14: =D12*INDEX(Premissas!$B$29:$B$33,D$4) -> 4.570575 | E14: =E12*INDEX(Premissas!$B$29:$B$33,E$4) -> 4.6010202 | F14: =F12*INDEX(Premissas!$B$29:$B$33,F$4) -> 4.6302 | G14: =G12*INDEX(Premissas!$B$29:$B$33,G$4) -> 4.6581724 | H14: =H12*INDEX(Premissas!$B$29:$B$33,H$4) -> 4.6849924 | I14: =I12*INDEX(Premissas!$B$29:$B$33,I$4) -> 4.7107125 | J14: =J12*INDEX(Premissas!$B$29:$B$33,J$4) -> 4.7353822 | ... BJ14: =BJ12*INDEX(Premissas!$B$29:$B$33,BJ$4) -> 52.181449
A15: Novos: Consultório | C15: =C12*INDEX(Premissas!$C$29:$C$33,C$4) -> 5.6735043 | D15: =D12*INDEX(Premissas!$C$29:$C$33,D$4) -> 5.7132188 | E15: =E12*INDEX(Premissas!$C$29:$C$33,E$4) -> 5.7512753 | F15: =F12*INDEX(Premissas!$C$29:$C$33,F$4) -> 5.78775 | G15: =G12*INDEX(Premissas!$C$29:$C$33,G$4) -> 5.8227155 | H15: =H12*INDEX(Premissas!$C$29:$C$33,H$4) -> 5.8562405 | I15: =I12*INDEX(Premissas!$C$29:$C$33,I$4) -> 5.8883906 | J15: =J12*INDEX(Premissas!$C$29:$C$33,J$4) -> 5.9192278 | ... BJ15: =BJ12*INDEX(Premissas!$C$29:$C$33,BJ$4) -> 104.3629
A16: Novos: Autoridade | C16: =C12*INDEX(Premissas!$D$29:$D$33,C$4) -> 1.1347009 | D16: =D12*INDEX(Premissas!$D$29:$D$33,D$4) -> 1.1426438 | E16: =E12*INDEX(Premissas!$D$29:$D$33,E$4) -> 1.1502551 | F16: =F12*INDEX(Premissas!$D$29:$D$33,F$4) -> 1.15755 | G16: =G12*INDEX(Premissas!$D$29:$D$33,G$4) -> 1.1645431 | H16: =H12*INDEX(Premissas!$D$29:$D$33,H$4) -> 1.1712481 | I16: =I12*INDEX(Premissas!$D$29:$D$33,I$4) -> 1.1776781 | J16: =J12*INDEX(Premissas!$D$29:$D$33,J$4) -> 1.1838456 | ... BJ16: =BJ12*INDEX(Premissas!$D$29:$D$33,BJ$4) -> 37.570643
A17: Novos: Clínica | C17: =C12*INDEX(Premissas!$E$29:$E$33,C$4) -> 0 | D17: =D12*INDEX(Premissas!$E$29:$E$33,D$4) -> 0 | E17: =E12*INDEX(Premissas!$E$29:$E$33,E$4) -> 0 | F17: =F12*INDEX(Premissas!$E$29:$E$33,F$4) -> 0 | G17: =G12*INDEX(Premissas!$E$29:$E$33,G$4) -> 0 | H17: =H12*INDEX(Premissas!$E$29:$E$33,H$4) -> 0 | I17: =I12*INDEX(Premissas!$E$29:$E$33,I$4) -> 0 | J17: =J12*INDEX(Premissas!$E$29:$E$33,J$4) -> 0 | ... BJ17: =BJ12*INDEX(Premissas!$E$29:$E$33,BJ$4) -> 14.610806
A18: Cancelamentos: Essencial | C18: =0 -> 0 | D18: =C22*Premissas!$B$20*INDEX(Premissas!$B$48:$D$48,$B$2)*(1-Premissas!$B$25)^(D$4-1) -> 0.29502222 | E18: =D22*Premissas!$B$20*INDEX(Premissas!$B$48:$D$48,$B$2)*(1-Premissas!$B$25)^(E$4-1) -> 0.57293316 | F18: =E22*Premissas!$B$20*INDEX(Premissas!$B$48:$D$48,$B$2)*(1-Premissas!$B$25)^(F$4-1) -> 0.83475881 | G18: =F22*Premissas!$B$20*INDEX(Premissas!$B$48:$D$48,$B$2)*(1-Premissas!$B$25)^(G$4-1) -> 1.0814625 | H18: =G22*Premissas!$B$20*INDEX(Premissas!$B$48:$D$48,$B$2)*(1-Premissas!$B$25)^(H$4-1) -> 1.3139486 | I18: =H22*Premissas!$B$20*INDEX(Premissas!$B$48:$D$48,$B$2)*(1-Premissas!$B$25)^(I$4-1) -> 1.5330665 | J18: =I22*Premissas!$B$20*INDEX(Premissas!$B$48:$D$48,$B$2)*(1-Premissas!$B$25)^(J$4-1) -> 1.7396135 | K18: =J22*Premissas!$B$20*INDEX(Premissas!$B$48:$D$48,$B$2)*(1-Premissas!$B$25)^(K$4-1) -> 1.9343384 | ... BJ18: =BI22*Premissas!$B$20*INDEX(Premissas!$B$48:$D$48,$B$2)*(1-Premissas!$B$25)^(BJ$4-1) -> 35.073952
A19: Cancelamentos: Consultório | C19: =0 -> 0 | D19: =C23*Premissas!$C$20*INDEX(Premissas!$B$48:$D$48,$B$2)*(1-Premissas!$B$25)^(D$4-1) -> 0.22126667 | E19: =D23*Premissas!$C$20*INDEX(Premissas!$B$48:$D$48,$B$2)*(1-Premissas!$B$25)^(E$4-1) -> 0.4354528 | F19: =E23*Premissas!$C$20*INDEX(Premissas!$B$48:$D$48,$B$2)*(1-Premissas!$B$25)^(F$4-1) -> 0.64276988 | G19: =F23*Premissas!$C$20*INDEX(Premissas!$B$48:$D$48,$B$2)*(1-Premissas!$B$25)^(G$4-1) -> 0.8434241 | H19: =G23*Premissas!$C$20*INDEX(Premissas!$B$48:$D$48,$B$2)*(1-Premissas!$B$25)^(H$4-1) -> 1.0376165 | I19: =H23*Premissas!$C$20*INDEX(Premissas!$B$48:$D$48,$B$2)*(1-Premissas!$B$25)^(I$4-1) -> 1.2255428 | J19: =I23*Premissas!$C$20*INDEX(Premissas!$B$48:$D$48,$B$2)*(1-Premissas!$B$25)^(J$4-1) -> 1.4073939 | K19: =J23*Premissas!$C$20*INDEX(Premissas!$B$48:$D$48,$B$2)*(1-Premissas!$B$25)^(K$4-1) -> 1.5833554 | ... BJ19: =BI23*Premissas!$C$20*INDEX(Premissas!$B$48:$D$48,$B$2)*(1-Premissas!$B$25)^(BJ$4-1) -> 49.895365
A20: Cancelamentos: Autoridade | C20: =0 -> 0 | D20: =C24*Premissas!$D$20*INDEX(Premissas!$B$48:$D$48,$B$2)*(1-Premissas!$B$25)^(D$4-1) -> 0.036877778 | E20: =D24*Premissas!$D$20*INDEX(Premissas!$B$48:$D$48,$B$2)*(1-Premissas!$B$25)^(E$4-1) -> 0.072815172 | F20: =E24*Premissas!$D$20*INDEX(Premissas!$B$48:$D$48,$B$2)*(1-Premissas!$B$25)^(F$4-1) -> 0.10783197 | G20: =F24*Premissas!$D$20*INDEX(Premissas!$B$48:$D$48,$B$2)*(1-Premissas!$B$25)^(G$4-1) -> 0.1419478 | H20: =G24*Premissas!$D$20*INDEX(Premissas!$B$48:$D$48,$B$2)*(1-Premissas!$B$25)^(H$4-1) -> 0.17518215 | I20: =H24*Premissas!$D$20*INDEX(Premissas!$B$48:$D$48,$B$2)*(1-Premissas!$B$25)^(I$4-1) -> 0.20755429 | J20: =I24*Premissas!$D$20*INDEX(Premissas!$B$48:$D$48,$B$2)*(1-Premissas!$B$25)^(J$4-1) -> 0.23908332 | K20: =J24*Premissas!$D$20*INDEX(Premissas!$B$48:$D$48,$B$2)*(1-Premissas!$B$25)^(K$4-1) -> 0.26978809 | ... BJ20: =BI24*Premissas!$D$20*INDEX(Premissas!$B$48:$D$48,$B$2)*(1-Premissas!$B$25)^(BJ$4-1) -> 14.84196
A21: Cancelamentos: Clínica | C21: =0 -> 0 | D21: =C25*Premissas!$E$20*INDEX(Premissas!$B$48:$D$48,$B$2)*(1-Premissas!$B$25)^(D$4-1) -> 0 | E21: =D25*Premissas!$E$20*INDEX(Premissas!$B$48:$D$48,$B$2)*(1-Premissas!$B$25)^(E$4-1) -> 0 | F21: =E25*Premissas!$E$20*INDEX(Premissas!$B$48:$D$48,$B$2)*(1-Premissas!$B$25)^(F$4-1) -> 0 | G21: =F25*Premissas!$E$20*INDEX(Premissas!$B$48:$D$48,$B$2)*(1-Premissas!$B$25)^(G$4-1) -> 0 | H21: =G25*Premissas!$E$20*INDEX(Premissas!$B$48:$D$48,$B$2)*(1-Premissas!$B$25)^(H$4-1) -> 0 | I21: =H25*Premissas!$E$20*INDEX(Premissas!$B$48:$D$48,$B$2)*(1-Premissas!$B$25)^(I$4-1) -> 0 | J21: =I25*Premissas!$E$20*INDEX(Premissas!$B$48:$D$48,$B$2)*(1-Premissas!$B$25)^(J$4-1) -> 0 | K21: =J25*Premissas!$E$20*INDEX(Premissas!$B$48:$D$48,$B$2)*(1-Premissas!$B$25)^(K$4-1) -> 0 | ... BJ21: =BI25*Premissas!$E$20*INDEX(Premissas!$B$48:$D$48,$B$2)*(1-Premissas!$B$25)^(BJ$4-1) -> 4.6333726
A22: Ativos: Essencial | C22: =C14-C18 -> 4.5388034 | D22: =C22+D14-D18 -> 8.8143562 | E22: =D22+E14-E18 -> 12.842443 | F22: =E22+F14-F18 -> 16.637884 | G22: =F22+G14-G18 -> 20.214594 | H22: =G22+H14-H18 -> 23.585638 | I22: =H22+I14-I18 -> 26.763284 | J22: =I22+J14-J18 -> 29.759053 | K22: =J22+K14-K18 -> 32.583763 | ... BJ22: =BI22+BJ14-BJ18 -> 770.32436
A23: Ativos: Consultório | C23: =C15-C19 -> 5.6735043 | D23: =C23+D15-D19 -> 11.165456 | E23: =D23+E15-E19 -> 16.481279 | F23: =E23+F15-F19 -> 21.626259 | G23: =F23+G15-G19 -> 26.60555 | H23: =G23+H15-H19 -> 31.424174 | I23: =H23+I15-I19 -> 36.087022 | J23: =I23+J15-J19 -> 40.598856 | K23: =J23+K15-K19 -> 44.964312 | ... BJ23: =BI23+BJ15-BJ19 -> 1840.3147
A24: Ativos: Autoridade | C24: =C16-C20 -> 1.1347009 | D24: =C24+D16-D20 -> 2.2404668 | E24: =D24+E16-E20 -> 3.3179067 | F24: =E24+F16-F20 -> 4.3676247 | G24: =F24+G16-G20 -> 5.39022 | H24: =G24+H16-H20 -> 6.386286 | I24: =H24+I16-I20 -> 7.3564098 | J24: =I24+J16-J20 -> 8.3011721 | K24: =J24+K16-K20 -> 9.2211462 | ... BJ24: =BI24+BJ16-BJ20 -> 660.19406
A25: Ativos: Clínica | C25: =C17-C21 -> 0 | D25: =C25+D17-D21 -> 0 | E25: =D25+E17-E21 -> 0 | F25: =E25+F17-F21 -> 0 | G25: =F25+G17-G21 -> 0 | H25: =G25+H17-H21 -> 0 | I25: =H25+I17-I21 -> 0 | J25: =I25+J17-J21 -> 0 | K25: =J25+K17-K21 -> 0 | ... BJ25: =BI25+BJ17-BJ21 -> 258.73286
A26: Clientes ativos: total | C26: =SUM(C22:C25) -> 11.347009 | D26: =SUM(D22:D25) -> 22.220279 | E26: =SUM(E22:E25) -> 32.641629 | F26: =SUM(F22:F25) -> 42.631768 | G26: =SUM(G22:G25) -> 52.210365 | H26: =SUM(H22:H25) -> 61.396099 | I26: =SUM(I22:I25) -> 70.206716 | J26: =SUM(J22:J25) -> 78.659081 | ... BJ26: =SUM(BJ22:BJ25) -> 3529.566
A27: Receita (R$)
A28: Receita recorrente: Essencial | C28: =C22*Premissas!$B$18*(1-Premissas!$B$12*Premissas!$B$13) -> 1287.3635 | D28: =D22*Premissas!$B$18*(1-Premissas!$B$12*Premissas!$B$13) -> 2500.0599 | E28: =E22*Premissas!$B$18*(1-Premissas!$B$12*Premissas!$B$13) -> 3642.5664 | F28: =F22*Premissas!$B$18*(1-Premissas!$B$12*Premissas!$B$13) -> 4719.0864 | G28: =G22*Premissas!$B$18*(1-Premissas!$B$12*Premissas!$B$13) -> 5733.5665 | H28: =H22*Premissas!$B$18*(1-Premissas!$B$12*Premissas!$B$13) -> 6689.7125 | I28: =I22*Premissas!$B$18*(1-Premissas!$B$12*Premissas!$B$13) -> 7591.0041 | J28: =J22*Premissas!$B$18*(1-Premissas!$B$12*Premissas!$B$13) -> 8440.709 | ... BJ28: =BJ22*Premissas!$B$18*(1-Premissas!$B$12*Premissas!$B$13) -> 218490.95
A29: Receita recorrente: Consultório | C29: =C23*Premissas!$C$18*(1-Premissas!$B$12*Premissas!$B$13) -> 3776.483 | D29: =D23*Premissas!$C$18*(1-Premissas!$B$12*Premissas!$B$13) -> 7432.1186 | E29: =E23*Premissas!$C$18*(1-Premissas!$B$12*Premissas!$B$13) -> 10970.516 | F29: =F23*Premissas!$C$18*(1-Premissas!$B$12*Premissas!$B$13) -> 14395.195 | G29: =G23*Premissas!$C$18*(1-Premissas!$B$12*Premissas!$B$13) -> 17709.585 | H29: =H23*Premissas!$C$18*(1-Premissas!$B$12*Premissas!$B$13) -> 20917.03 | I29: =I23*Premissas!$C$18*(1-Premissas!$B$12*Premissas!$B$13) -> 24020.785 | J29: =J23*Premissas!$C$18*(1-Premissas!$B$12*Premissas!$B$13) -> 27024.02 | ... BJ29: =BJ23*Premissas!$C$18*(1-Premissas!$B$12*Premissas!$B$13) -> 1224977.9
A30: Receita recorrente: Autoridade | C30: =C24*Premissas!$D$18*(1-Premissas!$B$12*Premissas!$B$13) -> 1622.2081 | D30: =D24*Premissas!$D$18*(1-Premissas!$B$12*Premissas!$B$13) -> 3203.0498 | E30: =E24*Premissas!$D$18*(1-Premissas!$B$12*Premissas!$B$13) -> 4743.3956 | F30: =F24*Premissas!$D$18*(1-Premissas!$B$12*Premissas!$B$13) -> 6244.1092 | G30: =G24*Premissas!$D$18*(1-Premissas!$B$12*Premissas!$B$13) -> 7706.0472 | H30: =H24*Premissas!$D$18*(1-Premissas!$B$12*Premissas!$B$13) -> 9130.058 | I30: =I24*Premissas!$D$18*(1-Premissas!$B$12*Premissas!$B$13) -> 10516.981 | J30: =J24*Premissas!$D$18*(1-Premissas!$B$12*Premissas!$B$13) -> 11867.646 | ... BJ30: =BJ24*Premissas!$D$18*(1-Premissas!$B$12*Premissas!$B$13) -> 943836.53
A31: Receita recorrente: Clínica | C31: =C25*Premissas!$E$18*(1-Premissas!$B$12*Premissas!$B$13) -> 0 | D31: =D25*Premissas!$E$18*(1-Premissas!$B$12*Premissas!$B$13) -> 0 | E31: =E25*Premissas!$E$18*(1-Premissas!$B$12*Premissas!$B$13) -> 0 | F31: =F25*Premissas!$E$18*(1-Premissas!$B$12*Premissas!$B$13) -> 0 | G31: =G25*Premissas!$E$18*(1-Premissas!$B$12*Premissas!$B$13) -> 0 | H31: =H25*Premissas!$E$18*(1-Premissas!$B$12*Premissas!$B$13) -> 0 | I31: =I25*Premissas!$E$18*(1-Premissas!$B$12*Premissas!$B$13) -> 0 | J31: =J25*Premissas!$E$18*(1-Premissas!$B$12*Premissas!$B$13) -> 0 | ... BJ31: =BJ25*Premissas!$E$18*(1-Premissas!$B$12*Premissas!$B$13) -> 963650.54
A32: Receita recorrente mensal (MRR) | C32: =SUM(C28:C31) -> 6686.0546 | D32: =SUM(D28:D31) -> 13135.228 | E32: =SUM(E28:E31) -> 19356.478 | F32: =SUM(F28:F31) -> 25358.39 | G32: =SUM(G28:G31) -> 31149.199 | H32: =SUM(H28:H31) -> 36736.801 | I32: =SUM(I28:I31) -> 42128.77 | J32: =SUM(J28:J31) -> 47332.375 | ... BJ32: =SUM(BJ28:BJ31) -> 3350955.9
A33: Taxas de implantação | C33: =C14*Premissas!$B$19+C15*Premissas!$C$19+C16*Premissas!$D$19+C17*Premissas!$E$19 -> 3903.3709 | D33: =D14*Premissas!$B$19+D15*Premissas!$C$19+D16*Premissas!$D$19+D17*Premissas!$E$19 -> 3930.6945 | E33: =E14*Premissas!$B$19+E15*Premissas!$C$19+E16*Premissas!$D$19+E17*Premissas!$E$19 -> 3956.8774 | F33: =F14*Premissas!$B$19+F15*Premissas!$C$19+F16*Premissas!$D$19+F17*Premissas!$E$19 -> 3981.972 | G33: =G14*Premissas!$B$19+G15*Premissas!$C$19+G16*Premissas!$D$19+G17*Premissas!$E$19 -> 4006.0282 | H33: =H14*Premissas!$B$19+H15*Premissas!$C$19+H16*Premissas!$D$19+H17*Premissas!$E$19 -> 4029.0935 | I33: =I14*Premissas!$B$19+I15*Premissas!$C$19+I16*Premissas!$D$19+I17*Premissas!$E$19 -> 4051.2127 | J33: =J14*Premissas!$B$19+J15*Premissas!$C$19+J16*Premissas!$D$19+J17*Premissas!$E$19 -> 4072.4287 | ... BJ33: =BJ14*Premissas!$B$19+BJ15*Premissas!$C$19+BJ16*Premissas!$D$19+BJ17*Premissas!$E$19 -> 130704.09
A34: Serviços adicionais | C34: =C32*INDEX(Premissas!$B$39:$F$39,C$4)*INDEX(Premissas!$B$50:$D$50,$B$2) -> 234.01191 | D34: =D32*INDEX(Premissas!$B$39:$F$39,D$4)*INDEX(Premissas!$B$50:$D$50,$B$2) -> 459.73299 | E34: =E32*INDEX(Premissas!$B$39:$F$39,E$4)*INDEX(Premissas!$B$50:$D$50,$B$2) -> 677.47673 | F34: =F32*INDEX(Premissas!$B$39:$F$39,F$4)*INDEX(Premissas!$B$50:$D$50,$B$2) -> 887.54367 | G34: =G32*INDEX(Premissas!$B$39:$F$39,G$4)*INDEX(Premissas!$B$50:$D$50,$B$2) -> 1090.222 | H34: =H32*INDEX(Premissas!$B$39:$F$39,H$4)*INDEX(Premissas!$B$50:$D$50,$B$2) -> 1285.788 | I34: =I32*INDEX(Premissas!$B$39:$F$39,I$4)*INDEX(Premissas!$B$50:$D$50,$B$2) -> 1474.507 | J34: =J32*INDEX(Premissas!$B$39:$F$39,J$4)*INDEX(Premissas!$B$50:$D$50,$B$2) -> 1656.6331 | ... BJ34: =BJ32*INDEX(Premissas!$B$39:$F$39,BJ$4)*INDEX(Premissas!$B$50:$D$50,$B$2) -> 351850.37
A35: Receita bruta | C35: =C32+C33+C34 -> 10823.437 | D35: =D32+D33+D34 -> 17525.656 | E35: =E32+E33+E34 -> 23990.832 | F35: =F32+F33+F34 -> 30227.906 | G35: =G32+G33+G34 -> 36245.449 | H35: =H32+H33+H34 -> 42051.682 | I35: =I32+I33+I34 -> 47654.49 | J35: =J32+J33+J34 -> 53061.437 | ... BJ35: =BJ32+BJ33+BJ34 -> 3833510.3
A36: (-) Impostos sobre receita | C36: =-C35*IF(SUMIFS($C$35:$BJ$35,$C$4:$BJ$4,C$4-1)>Premissas!$B$8,Premissas!$B$7,Premissas!$B$6) -> -1190.5781 | D36: =-D35*IF(SUMIFS($C$35:$BJ$35,$C$4:$BJ$4,D$4-1)>Premissas!$B$8,Premissas!$B$7,Premissas!$B$6) -> -1927.8221 | E36: =-E35*IF(SUMIFS($C$35:$BJ$35,$C$4:$BJ$4,E$4-1)>Premissas!$B$8,Premissas!$B$7,Premissas!$B$6) -> -2638.9915 | F36: =-F35*IF(SUMIFS($C$35:$BJ$35,$C$4:$BJ$4,F$4-1)>Premissas!$B$8,Premissas!$B$7,Premissas!$B$6) -> -3325.0697 | G36: =-G35*IF(SUMIFS($C$35:$BJ$35,$C$4:$BJ$4,G$4-1)>Premissas!$B$8,Premissas!$B$7,Premissas!$B$6) -> -3986.9994 | H36: =-H35*IF(SUMIFS($C$35:$BJ$35,$C$4:$BJ$4,H$4-1)>Premissas!$B$8,Premissas!$B$7,Premissas!$B$6) -> -4625.6851 | I36: =-I35*IF(SUMIFS($C$35:$BJ$35,$C$4:$BJ$4,I$4-1)>Premissas!$B$8,Premissas!$B$7,Premissas!$B$6) -> -5241.9939 | J36: =-J35*IF(SUMIFS($C$35:$BJ$35,$C$4:$BJ$4,J$4-1)>Premissas!$B$8,Premissas!$B$7,Premissas!$B$6) -> -5836.758 | ... BJ36: =-BJ35*IF(SUMIFS($C$35:$BJ$35,$C$4:$BJ$4,BJ$4-1)>Premissas!$B$8,Premissas!$B$7,Premissas!$B$6) -> -626012.24
A37: Receita líquida | C37: =C35+C36 -> 9632.8593 | D37: =D35+D36 -> 15597.834 | E37: =E35+E36 -> 21351.841 | F37: =F35+F36 -> 26902.836 | G37: =G35+G36 -> 32258.45 | H37: =H35+H36 -> 37425.997 | I37: =I35+I36 -> 42412.496 | J37: =J35+J36 -> 47224.679 | ... BJ37: =BJ35+BJ36 -> 3207498.1
A38: Custo do serviço (R$)
A39: IA (modelos de linguagem e imagem) | C39: =-(C22*Premissas!$B$21+C23*Premissas!$C$21+C24*Premissas!$D$21+C25*Premissas!$E$21)*Premissas!$B$5 -> -484.06338 | D39: =-(D22*Premissas!$B$21+D23*Premissas!$C$21+D24*Premissas!$D$21+D25*Premissas!$E$21)*Premissas!$B$5 -> -950.80465 | E39: =-(E22*Premissas!$B$21+E23*Premissas!$C$21+E24*Premissas!$D$21+E25*Premissas!$E$21)*Premissas!$B$5 -> -1400.8875 | F39: =-(F22*Premissas!$B$21+F23*Premissas!$C$21+F24*Premissas!$D$21+F25*Premissas!$E$21)*Premissas!$B$5 -> -1834.9476 | G39: =-(G22*Premissas!$B$21+G23*Premissas!$C$21+G24*Premissas!$D$21+G25*Premissas!$E$21)*Premissas!$B$5 -> -2253.5944 | H39: =-(H22*Premissas!$B$21+H23*Premissas!$C$21+H24*Premissas!$D$21+H25*Premissas!$E$21)*Premissas!$B$5 -> -2657.4117 | I39: =-(I22*Premissas!$B$21+I23*Premissas!$C$21+I24*Premissas!$D$21+I25*Premissas!$E$21)*Premissas!$B$5 -> -3046.9593 | J39: =-(J22*Premissas!$B$21+J23*Premissas!$C$21+J24*Premissas!$D$21+J25*Premissas!$E$21)*Premissas!$B$5 -> -3422.7739 | ... BJ39: =-(BJ22*Premissas!$B$21+BJ23*Premissas!$C$21+BJ24*Premissas!$D$21+BJ25*Premissas!$E$21)*Premissas!$B$5 -> -233121.25
A40: Infraestrutura e APIs | C40: =-(C22*Premissas!$B$22+C23*Premissas!$C$22+C24*Premissas!$D$22+C25*Premissas!$E$22) -> -124.81709 | D40: =-(D22*Premissas!$B$22+D23*Premissas!$C$22+D24*Premissas!$D$22+D25*Premissas!$E$22) -> -244.82873 | E40: =-(E22*Premissas!$B$22+E23*Premissas!$C$22+E24*Premissas!$D$22+E25*Premissas!$E$22) -> -360.23721 | F40: =-(F22*Premissas!$B$22+F23*Premissas!$C$22+F24*Premissas!$D$22+F25*Premissas!$E$22) -> -471.23543 | G40: =-(G22*Premissas!$B$22+G23*Premissas!$C$22+G24*Premissas!$D$22+G25*Premissas!$E$22) -> -578.00732 | H40: =-(H22*Premissas!$B$22+H23*Premissas!$C$22+H24*Premissas!$D$22+H25*Premissas!$E$22) -> -680.72835 | I40: =-(I22*Premissas!$B$22+I23*Premissas!$C$22+I24*Premissas!$D$22+I25*Premissas!$E$22) -> -779.56592 | J40: =-(J22*Premissas!$B$22+J23*Premissas!$C$22+J24*Premissas!$D$22+J25*Premissas!$E$22) -> -874.67979 | ... BJ40: =-(BJ22*Premissas!$B$22+BJ23*Premissas!$C$22+BJ24*Premissas!$D$22+BJ25*Premissas!$E$22) -> -50479.179
A41: Gestores de conta (revisão humana) | C41: =-(IFERROR(C22/Premissas!$B$23,0)+IFERROR(C23/Premissas!$C$23,0)+IFERROR(C24/Premissas!$D$23,0)+IFERROR(C25/Premissas!$E$23,0))*Premissas!$B$24*(1+Premissas!$B$10) -> -337.5735 | D41: =-(IFERROR(D22/Premissas!$B$23,0)+IFERROR(D23/Premissas!$C$23,0)+IFERROR(D24/Premissas!$D$23,0)+IFERROR(D25/Premissas!$E$23,0))*Premissas!$B$24*(1+Premissas!$B$10) -> -666.53888 | E41: =-(IFERROR(E22/Premissas!$B$23,0)+IFERROR(E23/Premissas!$C$23,0)+IFERROR(E24/Premissas!$D$23,0)+IFERROR(E25/Premissas!$E$23,0))*Premissas!$B$24*(1+Premissas!$B$10) -> -987.07725 | F41: =-(IFERROR(F22/Premissas!$B$23,0)+IFERROR(F23/Premissas!$C$23,0)+IFERROR(F24/Premissas!$D$23,0)+IFERROR(F25/Premissas!$E$23,0))*Premissas!$B$24*(1+Premissas!$B$10) -> -1299.3684 | G41: =-(IFERROR(G22/Premissas!$B$23,0)+IFERROR(G23/Premissas!$C$23,0)+IFERROR(G24/Premissas!$D$23,0)+IFERROR(G25/Premissas!$E$23,0))*Premissas!$B$24*(1+Premissas!$B$10) -> -1603.5905 | H41: =-(IFERROR(H22/Premissas!$B$23,0)+IFERROR(H23/Premissas!$C$23,0)+IFERROR(H24/Premissas!$D$23,0)+IFERROR(H25/Premissas!$E$23,0))*Premissas!$B$24*(1+Premissas!$B$10) -> -1899.9201 | I41: =-(IFERROR(I22/Premissas!$B$23,0)+IFERROR(I23/Premissas!$C$23,0)+IFERROR(I24/Premissas!$D$23,0)+IFERROR(I25/Premissas!$E$23,0))*Premissas!$B$24*(1+Premissas!$B$10) -> -2188.5319 | J41: =-(IFERROR(J22/Premissas!$B$23,0)+IFERROR(J23/Premissas!$C$23,0)+IFERROR(J24/Premissas!$D$23,0)+IFERROR(J25/Premissas!$E$23,0))*Premissas!$B$24*(1+Premissas!$B$10) -> -2469.5987 | ... BJ41: =-(IFERROR(BJ22/Premissas!$B$23,0)+IFERROR(BJ23/Premissas!$C$23,0)+IFERROR(BJ24/Premissas!$D$23,0)+IFERROR(BJ25/Premissas!$E$23,0))*Premissas!$B$24*(1+Premissas!$B$10) -> -350353.78
...

Sheet Modelo_Base
A1: Jalecon: projeção mensal, cenário base
A2: Cenário (1 = conservador, 2 = base, 3 = otimista) | B2: 2
A3: Mês | C3: 1 | D3: =C3+1 -> 2 | E3: =D3+1 -> 3 | F3: =E3+1 -> 4 | G3: =F3+1 -> 5 | H3: =G3+1 -> 6 | I3: =H3+1 -> 7 | J3: =I3+1 -> 8 | K3: =J3+1 -> 9 | ... BJ3: =BI3+1 -> 60
A4: Ano | C4: =ROUNDUP(C3/12,0) -> 1 | D4: =ROUNDUP(D3/12,0) -> 1 | E4: =ROUNDUP(E3/12,0) -> 1 | F4: =ROUNDUP(F3/12,0) -> 1 | G4: =ROUNDUP(G3/12,0) -> 1 | H4: =ROUNDUP(H3/12,0) -> 1 | I4: =ROUNDUP(I3/12,0) -> 1 | J4: =ROUNDUP(J3/12,0) -> 1 | ... BJ4: =ROUNDUP(BJ3/12,0) -> 5
A6: Aquisição
A7: Orçamento de mídia paga (R$) | C7: =INDEX(Premissas!$B$37:$F$37,C$4)*INDEX(Premissas!$B$51:$D$51,$B$2) -> 25000 | D7: =INDEX(Premissas!$B$37:$F$37,D$4)*INDEX(Premissas!$B$51:$D$51,$B$2) -> 25000 | E7: =INDEX(Premissas!$B$37:$F$37,E$4)*INDEX(Premissas!$B$51:$D$51,$B$2) -> 25000 | F7: =INDEX(Premissas!$B$37:$F$37,F$4)*INDEX(Premissas!$B$51:$D$51,$B$2) -> 25000 | G7: =INDEX(Premissas!$B$37:$F$37,G$4)*INDEX(Premissas!$B$51:$D$51,$B$2) -> 25000 | H7: =INDEX(Premissas!$B$37:$F$37,H$4)*INDEX(Premissas!$B$51:$D$51,$B$2) -> 25000 | I7: =INDEX(Premissas!$B$37:$F$37,I$4)*INDEX(Premissas!$B$51:$D$51,$B$2) -> 25000 | J7: =INDEX(Premissas!$B$37:$F$37,J$4)*INDEX(Premissas!$B$51:$D$51,$B$2) -> 25000 | ... BJ7: =INDEX(Premissas!$B$37:$F$37,BJ$4)*INDEX(Premissas!$B$51:$D$51,$B$2) -> 320000
A8: CAC de mídia paga (R$) | C8: =INDEX(Premissas!$B$42:$F$42,C$4)*INDEX(Premissas!$B$47:$D$47,$B$2) -> 1800 | D8: =INDEX(Premissas!$B$42:$F$42,D$4)*INDEX(Premissas!$B$47:$D$47,$B$2) -> 1800 | E8: =INDEX(Premissas!$B$42:$F$42,E$4)*INDEX(Premissas!$B$47:$D$47,$B$2) -> 1800 | F8: =INDEX(Premissas!$B$42:$F$42,F$4)*INDEX(Premissas!$B$47:$D$47,$B$2) -> 1800 | G8: =INDEX(Premissas!$B$42:$F$42,G$4)*INDEX(Premissas!$B$47:$D$47,$B$2) -> 1800 | H8: =INDEX(Premissas!$B$42:$F$42,H$4)*INDEX(Premissas!$B$47:$D$47,$B$2) -> 1800 | I8: =INDEX(Premissas!$B$42:$F$42,I$4)*INDEX(Premissas!$B$47:$D$47,$B$2) -> 1800 | J8: =INDEX(Premissas!$B$42:$F$42,J$4)*INDEX(Premissas!$B$47:$D$47,$B$2) -> 1800 | ... BJ8: =INDEX(Premissas!$B$42:$F$42,BJ$4)*INDEX(Premissas!$B$47:$D$47,$B$2) -> 1346.4936
A9: Novos clientes: mídia paga | C9: =IFERROR(C7/C8,0) -> 13.888889 | D9: =IFERROR(D7/D8,0) -> 13.888889 | E9: =IFERROR(E7/E8,0) -> 13.888889 | F9: =IFERROR(F7/F8,0) -> 13.888889 | G9: =IFERROR(G7/G8,0) -> 13.888889 | H9: =IFERROR(H7/H8,0) -> 13.888889 | I9: =IFERROR(I7/I8,0) -> 13.888889 | J9: =IFERROR(J7/J8,0) -> 13.888889 | ... BJ9: =IFERROR(BJ7/BJ8,0) -> 237.6543
A10: Novos clientes: parcerias | C10: =INDEX(Premissas!$B$38:$F$38,C$4)*INDEX(Premissas!$B$49:$D$49,$B$2) -> 4 | D10: =INDEX(Premissas!$B$38:$F$38,D$4)*INDEX(Premissas!$B$49:$D$49,$B$2) -> 4 | E10: =INDEX(Premissas!$B$38:$F$38,E$4)*INDEX(Premissas!$B$49:$D$49,$B$2) -> 4 | F10: =INDEX(Premissas!$B$38:$F$38,F$4)*INDEX(Premissas!$B$49:$D$49,$B$2) -> 4 | G10: =INDEX(Premissas!$B$38:$F$38,G$4)*INDEX(Premissas!$B$49:$D$49,$B$2) -> 4 | H10: =INDEX(Premissas!$B$38:$F$38,H$4)*INDEX(Premissas!$B$49:$D$49,$B$2) -> 4 | I10: =INDEX(Premissas!$B$38:$F$38,I$4)*INDEX(Premissas!$B$49:$D$49,$B$2) -> 4 | J10: =INDEX(Premissas!$B$38:$F$38,J$4)*INDEX(Premissas!$B$49:$D$49,$B$2) -> 4 | ... BJ10: =INDEX(Premissas!$B$38:$F$38,BJ$4)*INDEX(Premissas!$B$49:$D$49,$B$2) -> 55
A11: Novos clientes: indicação | C11: =0 -> 0 | D11: =C26*Premissas!$B$43*INDEX(Premissas!$B$49:$D$49,$B$2) -> 0.17888889 | E11: =D26*Premissas!$B$43*INDEX(Premissas!$B$49:$D$49,$B$2) -> 0.35285833 | F11: =E26*Premissas!$B$43*INDEX(Premissas!$B$49:$D$49,$B$2) -> 0.52206263 | G11: =F26*Premissas!$B$43*INDEX(Premissas!$B$49:$D$49,$B$2) -> 0.68665051 | H11: =G26*Premissas!$B$43*INDEX(Premissas!$B$49:$D$49,$B$2) -> 0.84676541 | I11: =H26*Premissas!$B$43*INDEX(Premissas!$B$49:$D$49,$B$2) -> 1.0025456 | J11: =I26*Premissas!$B$43*INDEX(Premissas!$B$49:$D$49,$B$2) -> 1.1541246 | K11: =J26*Premissas!$B$43*INDEX(Premissas!$B$49:$D$49,$B$2) -> 1.301631 | ... BJ11: =BI26*Premissas!$B$43*INDEX(Premissas!$B$49:$D$49,$B$2) -> 62.577373
A12: Novos clientes: total | C12: =C9+C10+C11 -> 17.888889 | D12: =D9+D10+D11 -> 18.067778 | E12: =E9+E10+E11 -> 18.241747 | F12: =F9+F10+F11 -> 18.410952 | G12: =G9+G10+G11 -> 18.575539 | H12: =H9+H10+H11 -> 18.735654 | I12: =I9+I10+I11 -> 18.891435 | J12: =J9+J10+J11 -> 19.043013 | ... BJ12: =BJ9+BJ10+BJ11 -> 355.23167
A13: Clientes por plano
A14: Novos: Essencial | C14: =C12*INDEX(Premissas!$B$29:$B$33,C$4) -> 7.1555556 | D14: =D12*INDEX(Premissas!$B$29:$B$33,D$4) -> 7.2271111 | E14: =E12*INDEX(Premissas!$B$29:$B$33,E$4) -> 7.2966989 | F14: =F12*INDEX(Premissas!$B$29:$B$33,F$4) -> 7.3643806 | G14: =G12*INDEX(Premissas!$B$29:$B$33,G$4) -> 7.4302158 | H14: =H12*INDEX(Premissas!$B$29:$B$33,H$4) -> 7.4942617 | I14: =I12*INDEX(Premissas!$B$29:$B$33,I$4) -> 7.5565738 | J14: =J12*INDEX(Premissas!$B$29:$B$33,J$4) -> 7.6172054 | ... BJ14: =BJ12*INDEX(Premissas!$B$29:$B$33,BJ$4) -> 88.807919
A15: Novos: Consultório | C15: =C12*INDEX(Premissas!$C$29:$C$33,C$4) -> 8.9444444 | D15: =D12*INDEX(Premissas!$C$29:$C$33,D$4) -> 9.0338889 | E15: =E12*INDEX(Premissas!$C$29:$C$33,E$4) -> 9.1208736 | F15: =F12*INDEX(Premissas!$C$29:$C$33,F$4) -> 9.2054758 | G15: =G12*INDEX(Premissas!$C$29:$C$33,G$4) -> 9.2877697 | H15: =H12*INDEX(Premissas!$C$29:$C$33,H$4) -> 9.3678272 | I15: =I12*INDEX(Premissas!$C$29:$C$33,I$4) -> 9.4457173 | J15: =J12*INDEX(Premissas!$C$29:$C$33,J$4) -> 9.5215067 | ... BJ15: =BJ12*INDEX(Premissas!$C$29:$C$33,BJ$4) -> 177.61584
A16: Novos: Autoridade | C16: =C12*INDEX(Premissas!$D$29:$D$33,C$4) -> 1.7888889 | D16: =D12*INDEX(Premissas!$D$29:$D$33,D$4) -> 1.8067778 | E16: =E12*INDEX(Premissas!$D$29:$D$33,E$4) -> 1.8241747 | F16: =F12*INDEX(Premissas!$D$29:$D$33,F$4) -> 1.8410952 | G16: =G12*INDEX(Premissas!$D$29:$D$33,G$4) -> 1.8575539 | H16: =H12*INDEX(Premissas!$D$29:$D$33,H$4) -> 1.8735654 | I16: =I12*INDEX(Premissas!$D$29:$D$33,I$4) -> 1.8891435 | J16: =J12*INDEX(Premissas!$D$29:$D$33,J$4) -> 1.9043013 | ... BJ16: =BJ12*INDEX(Premissas!$D$29:$D$33,BJ$4) -> 63.941701
A17: Novos: Clínica | C17: =C12*INDEX(Premissas!$E$29:$E$33,C$4) -> 0 | D17: =D12*INDEX(Premissas!$E$29:$E$33,D$4) -> 0 | E17: =E12*INDEX(Premissas!$E$29:$E$33,E$4) -> 0 | F17: =F12*INDEX(Premissas!$E$29:$E$33,F$4) -> 0 | G17: =G12*INDEX(Premissas!$E$29:$E$33,G$4) -> 0 | H17: =H12*INDEX(Premissas!$E$29:$E$33,H$4) -> 0 | I17: =I12*INDEX(Premissas!$E$29:$E$33,I$4) -> 0 | J17: =J12*INDEX(Premissas!$E$29:$E$33,J$4) -> 0 | ... BJ17: =BJ12*INDEX(Premissas!$E$29:$E$33,BJ$4) -> 24.866217
A18: Cancelamentos: Essencial | C18: =0 -> 0 | D18: =C22*Premissas!$B$20*INDEX(Premissas!$B$48:$D$48,$B$2)*(1-Premissas!$B$25)^(D$4-1) -> 0.35777778 | E18: =D22*Premissas!$B$20*INDEX(Premissas!$B$48:$D$48,$B$2)*(1-Premissas!$B$25)^(E$4-1) -> 0.70124444 | F18: =E22*Premissas!$B$20*INDEX(Premissas!$B$48:$D$48,$B$2)*(1-Premissas!$B$25)^(F$4-1) -> 1.0310172 | G18: =F22*Premissas!$B$20*INDEX(Premissas!$B$48:$D$48,$B$2)*(1-Premissas!$B$25)^(G$4-1) -> 1.3476853 | H18: =G22*Premissas!$B$20*INDEX(Premissas!$B$48:$D$48,$B$2)*(1-Premissas!$B$25)^(H$4-1) -> 1.6518119 | I18: =H22*Premissas!$B$20*INDEX(Premissas!$B$48:$D$48,$B$2)*(1-Premissas!$B$25)^(I$4-1) -> 1.9439344 | J18: =I22*Premissas!$B$20*INDEX(Premissas!$B$48:$D$48,$B$2)*(1-Premissas!$B$25)^(J$4-1) -> 2.2245663 | K18: =J22*Premissas!$B$20*INDEX(Premissas!$B$48:$D$48,$B$2)*(1-Premissas!$B$25)^(K$4-1) -> 2.4941983 | ... BJ18: =BI22*Premissas!$B$20*INDEX(Premissas!$B$48:$D$48,$B$2)*(1-Premissas!$B$25)^(BJ$4-1) -> 51.4491
A19: Cancelamentos: Consultório | C19: =0 -> 0 | D19: =C23*Premissas!$C$20*INDEX(Premissas!$B$48:$D$48,$B$2)*(1-Premissas!$B$25)^(D$4-1) -> 0.26833333 | E19: =D23*Premissas!$C$20*INDEX(Premissas!$B$48:$D$48,$B$2)*(1-Premissas!$B$25)^(E$4-1) -> 0.5313 | F19: =E23*Premissas!$C$20*INDEX(Premissas!$B$48:$D$48,$B$2)*(1-Premissas!$B$25)^(F$4-1) -> 0.78898721 | G19: =F23*Premissas!$C$20*INDEX(Premissas!$B$48:$D$48,$B$2)*(1-Premissas!$B$25)^(G$4-1) -> 1.0414819 | H19: =G23*Premissas!$C$20*INDEX(Premissas!$B$48:$D$48,$B$2)*(1-Premissas!$B$25)^(H$4-1) -> 1.2888705 | I19: =H23*Premissas!$C$20*INDEX(Premissas!$B$48:$D$48,$B$2)*(1-Premissas!$B$25)^(I$4-1) -> 1.5312392 | J19: =I23*Premissas!$C$20*INDEX(Premissas!$B$48:$D$48,$B$2)*(1-Premissas!$B$25)^(J$4-1) -> 1.7686735 | K19: =J23*Premissas!$C$20*INDEX(Premissas!$B$48:$D$48,$B$2)*(1-Premissas!$B$25)^(K$4-1) -> 2.0012585 | ... BJ19: =BI23*Premissas!$C$20*INDEX(Premissas!$B$48:$D$48,$B$2)*(1-Premissas!$B$25)^(BJ$4-1) -> 69.757831
A20: Cancelamentos: Autoridade | C20: =0 -> 0 | D20: =C24*Premissas!$D$20*INDEX(Premissas!$B$48:$D$48,$B$2)*(1-Premissas!$B$25)^(D$4-1) -> 0.044722222 | E20: =D24*Premissas!$D$20*INDEX(Premissas!$B$48:$D$48,$B$2)*(1-Premissas!$B$25)^(E$4-1) -> 0.088773611 | F20: =E24*Premissas!$D$20*INDEX(Premissas!$B$48:$D$48,$B$2)*(1-Premissas!$B$25)^(F$4-1) -> 0.13215864 | G20: =F24*Premissas!$D$20*INDEX(Premissas!$B$48:$D$48,$B$2)*(1-Premissas!$B$25)^(G$4-1) -> 0.17488205 | H20: =G24*Premissas!$D$20*INDEX(Premissas!$B$48:$D$48,$B$2)*(1-Premissas!$B$25)^(H$4-1) -> 0.21694885 | I20: =H24*Premissas!$D$20*INDEX(Premissas!$B$48:$D$48,$B$2)*(1-Premissas!$B$25)^(I$4-1) -> 0.25836426 | J20: =I24*Premissas!$D$20*INDEX(Premissas!$B$48:$D$48,$B$2)*(1-Premissas!$B$25)^(J$4-1) -> 0.29913374 | K20: =J24*Premissas!$D$20*INDEX(Premissas!$B$48:$D$48,$B$2)*(1-Premissas!$B$25)^(K$4-1) -> 0.33926293 | ... BJ20: =BI24*Premissas!$D$20*INDEX(Premissas!$B$48:$D$48,$B$2)*(1-Premissas!$B$25)^(BJ$4-1) -> 20.397637
A21: Cancelamentos: Clínica | C21: =0 -> 0 | D21: =C25*Premissas!$E$20*INDEX(Premissas!$B$48:$D$48,$B$2)*(1-Premissas!$B$25)^(D$4-1) -> 0 | E21: =D25*Premissas!$E$20*INDEX(Premissas!$B$48:$D$48,$B$2)*(1-Premissas!$B$25)^(E$4-1) -> 0 | F21: =E25*Premissas!$E$20*INDEX(Premissas!$B$48:$D$48,$B$2)*(1-Premissas!$B$25)^(F$4-1) -> 0 | G21: =F25*Premissas!$E$20*INDEX(Premissas!$B$48:$D$48,$B$2)*(1-Premissas!$B$25)^(G$4-1) -> 0 | H21: =G25*Premissas!$E$20*INDEX(Premissas!$B$48:$D$48,$B$2)*(1-Premissas!$B$25)^(H$4-1) -> 0 | I21: =H25*Premissas!$E$20*INDEX(Premissas!$B$48:$D$48,$B$2)*(1-Premissas!$B$25)^(I$4-1) -> 0 | J21: =I25*Premissas!$E$20*INDEX(Premissas!$B$48:$D$48,$B$2)*(1-Premissas!$B$25)^(J$4-1) -> 0 | K21: =J25*Premissas!$E$20*INDEX(Premissas!$B$48:$D$48,$B$2)*(1-Premissas!$B$25)^(K$4-1) -> 0 | ... BJ21: =BI25*Premissas!$E$20*INDEX(Premissas!$B$48:$D$48,$B$2)*(1-Premissas!$B$25)^(BJ$4-1) -> 6.2570084
A22: Ativos: Essencial | C22: =C14-C18 -> 7.1555556 | D22: =C22+D14-D18 -> 14.024889 | E22: =D22+E14-E18 -> 20.620343 | F22: =E22+F14-F18 -> 26.953707 | G22: =F22+G14-G18 -> 33.036237 | H22: =G22+H14-H18 -> 38.878687 | I22: =H22+I14-I18 -> 44.491327 | J22: =I22+J14-J18 -> 49.883966 | K22: =J22+K14-K18 -> 55.065975 | ... BJ22: =BI22+BJ14-BJ18 -> 1473.6962
A23: Ativos: Consultório | C23: =C15-C19 -> 8.9444444 | D23: =C23+D15-D19 -> 17.71 | E23: =D23+E15-E19 -> 26.299574 | F23: =E23+F15-F19 -> 34.716062 | G23: =F23+G15-G19 -> 42.96235 | H23: =G23+H15-H19 -> 51.041307 | I23: =H23+I15-I19 -> 58.955785 | J23: =I23+J15-J19 -> 66.708618 | K23: =J23+K15-K19 -> 74.302619 | ... BJ23: =BI23+BJ15-BJ19 -> 3353.6479
A24: Ativos: Autoridade | C24: =C16-C20 -> 1.7888889 | D24: =C24+D16-D20 -> 3.5509444 | E24: =D24+E16-E20 -> 5.2863456 | F24: =E24+F16-F20 -> 6.9952821 | G24: =F24+G16-G20 -> 8.677954 | H24: =G24+H16-H20 -> 10.334571 | I24: =H24+I16-I20 -> 11.96535 | J24: =I24+J16-J20 -> 13.570517 | K24: =J24+K16-K20 -> 15.150306 | ... BJ24: =BI24+BJ16-BJ20 -> 1182.4518
A25: Ativos: Clínica | C25: =C17-C21 -> 0 | D25: =C25+D17-D21 -> 0 | E25: =D25+E17-E21 -> 0 | F25: =E25+F17-F21 -> 0 | G25: =F25+G17-G21 -> 0 | H25: =G25+H17-H21 -> 0 | I25: =H25+I17-I21 -> 0 | J25: =I25+J17-J21 -> 0 | K25: =J25+K17-K21 -> 0 | ... BJ25: =BI25+BJ17-BJ21 -> 455.31146
A26: Clientes ativos: total | C26: =SUM(C22:C25) -> 17.888889 | D26: =SUM(D22:D25) -> 35.285833 | E26: =SUM(E22:E25) -> 52.206263 | F26: =SUM(F22:F25) -> 68.665051 | G26: =SUM(G22:G25) -> 84.676541 | H26: =SUM(H22:H25) -> 100.25456 | I26: =SUM(I22:I25) -> 115.41246 | J26: =SUM(J22:J25) -> 130.1631 | ... BJ26: =SUM(BJ22:BJ25) -> 6465.1074
A27: Receita (R$)
A28: Receita recorrente: Essencial | C28: =C22*Premissas!$B$18*(1-Premissas!$B$12*Premissas!$B$13) -> 2029.566 | D28: =D22*Premissas!$B$18*(1-Premissas!$B$12*Premissas!$B$13) -> 3977.9494 | E28: =E22*Premissas!$B$18*(1-Premissas!$B$12*Premissas!$B$13) -> 5848.6511 | F28: =F22*Premissas!$B$18*(1-Premissas!$B$12*Premissas!$B$13) -> 7645.0146 | G28: =G22*Premissas!$B$18*(1-Premissas!$B$12*Premissas!$B$13) -> 9370.2331 | H28: =H22*Premissas!$B$18*(1-Premissas!$B$12*Premissas!$B$13) -> 11027.356 | I28: =I22*Premissas!$B$18*(1-Premissas!$B$12*Premissas!$B$13) -> 12619.297 | J28: =J22*Premissas!$B$18*(1-Premissas!$B$12*Premissas!$B$13) -> 14148.839 | ... BJ28: =BJ22*Premissas!$B$18*(1-Premissas!$B$12*Premissas!$B$13) -> 417991.82
A29: Receita recorrente: Consultório | C29: =C23*Premissas!$C$18*(1-Premissas!$B$12*Premissas!$B$13) -> 5953.7353 | D29: =D23*Premissas!$C$18*(1-Premissas!$B$12*Premissas!$B$13) -> 11788.396 | E29: =E23*Premissas!$C$18*(1-Premissas!$B$12*Premissas!$B$13) -> 17505.917 | F29: =F23*Premissas!$C$18*(1-Premissas!$B$12*Premissas!$B$13) -> 23108.226 | G29: =G23*Premissas!$C$18*(1-Premissas!$B$12*Premissas!$B$13) -> 28597.244 | H29: =H23*Premissas!$C$18*(1-Premissas!$B$12*Premissas!$B$13) -> 33974.88 | I29: =I23*Premissas!$C$18*(1-Premissas!$B$12*Premissas!$B$13) -> 39243.034 | J29: =J23*Premissas!$C$18*(1-Premissas!$B$12*Premissas!$B$13) -> 44403.591 | ... BJ29: =BJ23*Premissas!$C$18*(1-Premissas!$B$12*Premissas!$B$13) -> 2232305.4
A30: Receita recorrente: Autoridade | C30: =C24*Premissas!$D$18*(1-Premissas!$B$12*Premissas!$B$13) -> 2557.4582 | D30: =D24*Premissas!$D$18*(1-Premissas!$B$12*Premissas!$B$13) -> 5076.5545 | E30: =E24*Premissas!$D$18*(1-Premissas!$B$12*Premissas!$B$13) -> 7557.5446 | F30: =F24*Premissas!$D$18*(1-Premissas!$B$12*Premissas!$B$13) -> 10000.7 | G30: =G24*Premissas!$D$18*(1-Premissas!$B$12*Premissas!$B$13) -> 12406.307 | H30: =H24*Premissas!$D$18*(1-Premissas!$B$12*Premissas!$B$13) -> 14774.664 | I30: =I24*Premissas!$D$18*(1-Premissas!$B$12*Premissas!$B$13) -> 17106.083 | J30: =J24*Premissas!$D$18*(1-Premissas!$B$12*Premissas!$B$13) -> 19400.887 | ... BJ30: =BJ24*Premissas!$D$18*(1-Premissas!$B$12*Premissas!$B$13) -> 1690474.5
A31: Receita recorrente: Clínica | C31: =C25*Premissas!$E$18*(1-Premissas!$B$12*Premissas!$B$13) -> 0 | D31: =D25*Premissas!$E$18*(1-Premissas!$B$12*Premissas!$B$13) -> 0 | E31: =E25*Premissas!$E$18*(1-Premissas!$B$12*Premissas!$B$13) -> 0 | F31: =F25*Premissas!$E$18*(1-Premissas!$B$12*Premissas!$B$13) -> 0 | G31: =G25*Premissas!$E$18*(1-Premissas!$B$12*Premissas!$B$13) -> 0 | H31: =H25*Premissas!$E$18*(1-Premissas!$B$12*Premissas!$B$13) -> 0 | I31: =I25*Premissas!$E$18*(1-Premissas!$B$12*Premissas!$B$13) -> 0 | J31: =J25*Premissas!$E$18*(1-Premissas!$B$12*Premissas!$B$13) -> 0 | ... BJ31: =BJ25*Premissas!$E$18*(1-Premissas!$B$12*Premissas!$B$13) -> 1695807.5
A32: Receita recorrente mensal (MRR) | C32: =SUM(C28:C31) -> 10540.759 | D32: =SUM(D28:D31) -> 20842.9 | E32: =SUM(E28:E31) -> 30912.112 | F32: =SUM(F28:F31) -> 40753.941 | G32: =SUM(G28:G31) -> 50373.784 | H32: =SUM(H28:H31) -> 59776.9 | I32: =SUM(I28:I31) -> 68968.414 | J32: =SUM(J28:J31) -> 77953.316 | ... BJ32: =SUM(BJ28:BJ31) -> 6036579.3
A33: Taxas de implantação | C33: =C14*Premissas!$B$19+C15*Premissas!$C$19+C16*Premissas!$D$19+C17*Premissas!$E$19 -> 6153.7778 | D33: =D14*Premissas!$B$19+D15*Premissas!$C$19+D16*Premissas!$D$19+D17*Premissas!$E$19 -> 6215.3156 | E33: =E14*Premissas!$B$19+E15*Premissas!$C$19+E16*Premissas!$D$19+E17*Premissas!$E$19 -> 6275.161 | F33: =F14*Premissas!$B$19+F15*Premissas!$C$19+F16*Premissas!$D$19+F17*Premissas!$E$19 -> 6333.3673 | G33: =G14*Premissas!$B$19+G15*Premissas!$C$19+G16*Premissas!$D$19+G17*Premissas!$E$19 -> 6389.9856 | H33: =H14*Premissas!$B$19+H15*Premissas!$C$19+H16*Premissas!$D$19+H17*Premissas!$E$19 -> 6445.0651 | I33: =I14*Premissas!$B$19+I15*Premissas!$C$19+I16*Premissas!$D$19+I17*Premissas!$E$19 -> 6498.6535 | J33: =J14*Premissas!$B$19+J15*Premissas!$C$19+J16*Premissas!$D$19+J17*Premissas!$E$19 -> 6550.7966 | ... BJ33: =BJ14*Premissas!$B$19+BJ15*Premissas!$C$19+BJ16*Premissas!$D$19+BJ17*Premissas!$E$19 -> 222446.07
