Workbook

Sheet Resumo
A1: Jalecon Clínicas (Modelo C) · Resumo
A2: Cenário: | B2: =Premissas!$D$3
A3: Troque o cenário na aba Premissas, célula C3. Valores em reais nominais.
A5: Ano a ano
A6: Indicador | B6: Ano 1 | C6: Ano 2 | D6: Ano 3 | E6: Ano 4 | F6: Ano 5 | G6: Ano 6 | H6: Ano 7
A7: Clínicas ativas (fim do ano) | B7: =INDEX('Modelo C'!$C$36:$CH$36,1,12) | C7: =INDEX('Modelo C'!$C$36:$CH$36,1,24) | D7: =INDEX('Modelo C'!$C$36:$CH$36,1,36) | E7: =INDEX('Modelo C'!$C$36:$CH$36,1,48) | F7: =INDEX('Modelo C'!$C$36:$CH$36,1,60) | G7: =INDEX('Modelo C'!$C$36:$CH$36,1,72) | H7: =INDEX('Modelo C'!$C$36:$CH$36,1,84)
A8: Clínicas novas no ano | B8: =SUMIF('Modelo C'!$C$3:$CH$3,1,'Modelo C'!$C$15:$CH$15) | C8: =SUMIF('Modelo C'!$C$3:$CH$3,2,'Modelo C'!$C$15:$CH$15) | D8: =SUMIF('Modelo C'!$C$3:$CH$3,3,'Modelo C'!$C$15:$CH$15) | E8: =SUMIF('Modelo C'!$C$3:$CH$3,4,'Modelo C'!$C$15:$CH$15) | F8: =SUMIF('Modelo C'!$C$3:$CH$3,5,'Modelo C'!$C$15:$CH$15) | G8: =SUMIF('Modelo C'!$C$3:$CH$3,6,'Modelo C'!$C$15:$CH$15) | H8: =SUMIF('Modelo C'!$C$3:$CH$3,7,'Modelo C'!$C$15:$CH$15)
A9: Receita bruta | B9: =SUMIF('Modelo C'!$C$3:$CH$3,1,'Modelo C'!$C$43:$CH$43) | C9: =SUMIF('Modelo C'!$C$3:$CH$3,2,'Modelo C'!$C$43:$CH$43) | D9: =SUMIF('Modelo C'!$C$3:$CH$3,3,'Modelo C'!$C$43:$CH$43) | E9: =SUMIF('Modelo C'!$C$3:$CH$3,4,'Modelo C'!$C$43:$CH$43) | F9: =SUMIF('Modelo C'!$C$3:$CH$3,5,'Modelo C'!$C$43:$CH$43) | G9: =SUMIF('Modelo C'!$C$3:$CH$3,6,'Modelo C'!$C$43:$CH$43) | H9: =SUMIF('Modelo C'!$C$3:$CH$3,7,'Modelo C'!$C$43:$CH$43)
A10: Receita recorrente anualizada (fim do ano) | B10: =INDEX('Modelo C'!$C$45:$CH$45,1,12) | C10: =INDEX('Modelo C'!$C$45:$CH$45,1,24) | D10: =INDEX('Modelo C'!$C$45:$CH$45,1,36) | E10: =INDEX('Modelo C'!$C$45:$CH$45,1,48) | F10: =INDEX('Modelo C'!$C$45:$CH$45,1,60) | G10: =INDEX('Modelo C'!$C$45:$CH$45,1,72) | H10: =INDEX('Modelo C'!$C$45:$CH$45,1,84)
A11: Mensalidade média por clínica (fim do ano) | B11: =INDEX('Modelo C'!$C$46:$CH$46,1,12) | C11: =INDEX('Modelo C'!$C$46:$CH$46,1,24) | D11: =INDEX('Modelo C'!$C$46:$CH$46,1,36) | E11: =INDEX('Modelo C'!$C$46:$CH$46,1,48) | F11: =INDEX('Modelo C'!$C$46:$CH$46,1,60) | G11: =INDEX('Modelo C'!$C$46:$CH$46,1,72) | H11: =INDEX('Modelo C'!$C$46:$CH$46,1,84)
A12: Lucro bruto | B12: =SUMIF('Modelo C'!$C$3:$CH$3,1,'Modelo C'!$C$57:$CH$57) | C12: =SUMIF('Modelo C'!$C$3:$CH$3,2,'Modelo C'!$C$57:$CH$57) | D12: =SUMIF('Modelo C'!$C$3:$CH$3,3,'Modelo C'!$C$57:$CH$57) | E12: =SUMIF('Modelo C'!$C$3:$CH$3,4,'Modelo C'!$C$57:$CH$57) | F12: =SUMIF('Modelo C'!$C$3:$CH$3,5,'Modelo C'!$C$57:$CH$57) | G12: =SUMIF('Modelo C'!$C$3:$CH$3,6,'Modelo C'!$C$57:$CH$57) | H12: =SUMIF('Modelo C'!$C$3:$CH$3,7,'Modelo C'!$C$57:$CH$57)
A13: Margem bruta (sobre a receita líquida) | B13: =IFERROR(SUMIF('Modelo C'!$C$3:$CH$3,1,'Modelo C'!$C$57:$CH$57)/SUMIF('Modelo C'!$C$3:$CH$3,1,'Modelo C'!$C$49:$CH$49),0) | C13: =IFERROR(SUMIF('Modelo C'!$C$3:$CH$3,2,'Modelo C'!$C$57:$CH$57)/SUMIF('Modelo C'!$C$3:$CH$3,2,'Modelo C'!$C$49:$CH$49),0) | D13: =IFERROR(SUMIF('Modelo C'!$C$3:$CH$3,3,'Modelo C'!$C$57:$CH$57)/SUMIF('Modelo C'!$C$3:$CH$3,3,'Modelo C'!$C$49:$CH$49),0) | E13: =IFERROR(SUMIF('Modelo C'!$C$3:$CH$3,4,'Modelo C'!$C$57:$CH$57)/SUMIF('Modelo C'!$C$3:$CH$3,4,'Modelo C'!$C$49:$CH$49),0) | F13: =IFERROR(SUMIF('Modelo C'!$C$3:$CH$3,5,'Modelo C'!$C$57:$CH$57)/SUMIF('Modelo C'!$C$3:$CH$3,5,'Modelo C'!$C$49:$CH$49),0) | G13: =IFERROR(SUMIF('Modelo C'!$C$3:$CH$3,6,'Modelo C'!$C$57:$CH$57)/SUMIF('Modelo C'!$C$3:$CH$3,6,'Modelo C'!$C$49:$CH$49),0) | H13: =IFERROR(SUMIF('Modelo C'!$C$3:$CH$3,7,'Modelo C'!$C$57:$CH$57)/SUMIF('Modelo C'!$C$3:$CH$3,7,'Modelo C'!$C$49:$CH$49),0)
A14: EBITDA | B14: =SUMIF('Modelo C'!$C$3:$CH$3,1,'Modelo C'!$C$75:$CH$75) | C14: =SUMIF('Modelo C'!$C$3:$CH$3,2,'Modelo C'!$C$75:$CH$75) | D14: =SUMIF('Modelo C'!$C$3:$CH$3,3,'Modelo C'!$C$75:$CH$75) | E14: =SUMIF('Modelo C'!$C$3:$CH$3,4,'Modelo C'!$C$75:$CH$75) | F14: =SUMIF('Modelo C'!$C$3:$CH$3,5,'Modelo C'!$C$75:$CH$75) | G14: =SUMIF('Modelo C'!$C$3:$CH$3,6,'Modelo C'!$C$75:$CH$75) | H14: =SUMIF('Modelo C'!$C$3:$CH$3,7,'Modelo C'!$C$75:$CH$75)
A15: Caixa acumulado sem captação (fim do ano) | B15: =INDEX('Modelo C'!$C$76:$CH$76,1,12) | C15: =INDEX('Modelo C'!$C$76:$CH$76,1,24) | D15: =INDEX('Modelo C'!$C$76:$CH$76,1,36) | E15: =INDEX('Modelo C'!$C$76:$CH$76,1,48) | F15: =INDEX('Modelo C'!$C$76:$CH$76,1,60) | G15: =INDEX('Modelo C'!$C$76:$CH$76,1,72) | H15: =INDEX('Modelo C'!$C$76:$CH$76,1,84)
A16: Pessoas (fim do ano) | B16: =INDEX('Modelo C'!$C$79:$CH$79,1,12) | C16: =INDEX('Modelo C'!$C$79:$CH$79,1,24) | D16: =INDEX('Modelo C'!$C$79:$CH$79,1,36) | E16: =INDEX('Modelo C'!$C$79:$CH$79,1,48) | F16: =INDEX('Modelo C'!$C$79:$CH$79,1,60) | G16: =INDEX('Modelo C'!$C$79:$CH$79,1,72) | H16: =INDEX('Modelo C'!$C$79:$CH$79,1,84)
A17: Participação no mercado endereçável (fim do ano) | B17: =INDEX('Modelo C'!$C$39:$CH$39,1,12) | C17: =INDEX('Modelo C'!$C$39:$CH$39,1,24) | D17: =INDEX('Modelo C'!$C$39:$CH$39,1,36) | E17: =INDEX('Modelo C'!$C$39:$CH$39,1,48) | F17: =INDEX('Modelo C'!$C$39:$CH$39,1,60) | G17: =INDEX('Modelo C'!$C$39:$CH$39,1,72) | H17: =INDEX('Modelo C'!$C$39:$CH$39,1,84)
A19: Indicadores-chave e critérios de corte
A20: Indicador | B20: Modelo C | C20: Critério | D20: Passa?
A21: Receita recorrente anualizada no ano 5 | B21: =INDEX('Modelo C'!$C$45:$CH$45,1,60)
A22: Receita recorrente anualizada no ano 7 | B22: =INDEX('Modelo C'!$C$45:$CH$45,1,84)
A23: Mês de equilíbrio (EBITDA positivo daí em diante) | B23: =IFERROR(1/(1/MIN('Modelo C'!$C$77:$CH$77)),"não chega")
A24: Capital necessário (pior caixa acumulado) | B24: =-MIN(0,MIN('Modelo C'!$C$76:$CH$76))
A25: Margem bruta no ano 5 | B25: =SUMIF('Modelo C'!$C$3:$CH$3,5,'Modelo C'!$C$57:$CH$57)/SUMIF('Modelo C'!$C$3:$CH$3,5,'Modelo C'!$C$49:$CH$49) | C25: =Premissas!$F$75 | D25: =IF(B25>=Premissas!$F$75,"Sim","Não")
A26: LTV/CAC ponderado pelo mix, com CAC total do ano 5 | B26: =Unidade!H8 | C26: =Premissas!$F$76 | D26: =IF(B26>=Premissas!$F$76,"Sim","Não")
A27: Recuperação do CAC total, ponderada (meses) | B27: =Unidade!I8 | C27: =Premissas!$F$77 | D27: =IF(B27<=Premissas!$F$77,"Sim","Não")
A28: LTV/CAC ponderado com CAC só de mídia (comparável ao v2.1) | B28: =Unidade!G8/Unidade!B12
A29: CAC total no ano 5 | B29: =Unidade!B11
A30: Mês em que a receita anualizada chega a R$ 50 mi | B30: =IFERROR(1/(1/MIN('Modelo C'!$C$78:$CH$78)),"não chega")
A31: Participação no mercado nesse mês | B31: =IF(ISNUMBER(B30),INDEX('Modelo C'!$C$39:$CH$39,1,B30),"") | C31: =Premissas!$F$79 | D31: =IF(ISNUMBER(B31),IF(B31<=Premissas!$F$79,"Sim","Não"),"Não chega a R$ 50 mi")
A32: Receita de expansão no ano 5, como % das mensalidades | B32: =SUMIF('Modelo C'!$C$3:$CH$3,5,'Modelo C'!$C$41:$CH$41)/SUMIF('Modelo C'!$C$3:$CH$3,5,'Modelo C'!$C$40:$CH$40)
A33: Receita por pessoa no ano 5 | B33: =SUMIF('Modelo C'!$C$3:$CH$3,5,'Modelo C'!$C$43:$CH$43)/INDEX('Modelo C'!$C$79:$CH$79,1,60)
A34: Clínicas ativas no ano 5 | B34: =INDEX('Modelo C'!$C$36:$CH$36,1,60)
A35: Especialistas nas contas no ano 5 | B35: =INDEX('Modelo C'!$C$53:$CH$53,1,60)
A37: Como ler: H6 exige as três linhas com 'Sim' (margem, LTV/CAC e recuperação do CAC). H7 exige R$ 50 mi de receita anualizada em até 7 anos com no máximo 3% do mercado endereçável.
A38: As abas Cenarios e Sensibilidade são geradas pelo script sensibilidade_clinicas.py: são valores, não fórmulas.

Sheet Leia-me
A1: Jalecon Clínicas (Modelo C) · Como usar este modelo
A2: Pivô avaliado depois do memorando 08: a mesma agência operada por agentes de IA, vendida a clínicas privadas de 2 a 15 médicos (e redes), em vez de médicos individuais.
A3: O que muda em relação ao Modelo B do v2.1: planos por porte da clínica (R$ 2.900, R$ 4.900 e R$ 8.900), venda ativa com duplas de SDR e executivo, receita de expansão quando a clínica contrata médicos ou abre unidades, e mercado contado em clínicas.
A4: O que não muda: impostos, critérios de corte (H6 e H7), mecânica de caixa e cobrança por consulta desligada (art. 59 do Código de Ética Médica).
A5: Critério de LTV/CAC mais exigente que no v2.1: usa o CAC total (mídia, duplas, marketing, comissões e marca divididos pelas clínicas novas do ano 5), e não só o CAC de mídia. O LTV não inclui receita de expansão.
A6: Abas: Resumo, Leia-me, Unidade (economia por clínica), Premissas, Modelo C (84 meses), Cenarios e Sensibilidade (geradas por script).
A7: Limitações: tamanho do mercado, churn, produtividade de vendas e horas por clínica são referências de mercado, não medição própria. Não há sazonalidade nem reforma tributária.

Sheet Premissas
A1: Jalecon Clínicas (Modelo C) · Premissas
A2: Texto azul = premissa editável. A coluna F (Usado) segue o cenário escolhido em C3. A coluna G diz de onde veio cada número.
A3: Cenário (1 = Conservador, 2 = Base, 3 = Otimista) | C3: 2 | D3: =CHOOSE(C3,"Conservador","Base","Otimista")
A6: 1. Gerais
A7: Premissa | B7: Unidade | C7: Conservador | D7: Base | E7: Otimista | F7: Usado | G7: Fonte ou justificativa
A8: Mês de lançamento comercial (antes: piloto concierge) | B8: mês | C8: 5 | D8: 4 | E8: 4 | F8: =CHOOSE($C$3,C8,D8,E8) | G8: Como no v2.1
A9: Impostos sobre a receita até R$ 4,8 mi nos últimos 12 meses | B9: % | C9: 0.163 | D9: 0.163 | E9: 0.163 | F9: =CHOOSE($C$3,C9,D9,E9) | G9: Lucro presumido desde o início, como no v2.1
A10: Impostos sobre a receita acima de R$ 4,8 mi nos últimos 12 meses | B10: % | C10: 0.163 | D10: 0.163 | E10: 0.163 | F10: =CHOOSE($C$3,C10,D10,E10) | G10: Lucro presumido para serviços (aprox.)
A11: Meios de pagamento e inadimplência | B11: % da receita | C11: 0.04 | D11: 0.03 | E11: 0.025 | F11: =CHOOSE($C$3,C11,D11,E11) | G11: Boleto e Pix recorrentes; inclui inadimplência de PME
A12: Mercado endereçável: clínicas médicas privadas de 2 a 15 médicos que dependem de pacientes particulares | B12: clínicas | C12: 10000 | D12: 20000 | E12: 35000 | F12: =CHOOSE($C$3,C12,D12,E12) | G12: pesquisa/clinicas.md: 30 a 70 mil clínicas privadas de 2 a 15 médicos (extrapolação do CNES da Bahia), das quais 30% a 50% investem em captação e têm particular relevante. Estimativa, sem fonte direta
A13: Expansão para clínicas odontológicas: mês de início | B13: mês | C13: 37 | D13: 25 | E13: 25 | F13: =CHOOSE($C$3,C13,D13,E13) | G13: Exige base de regras do CFO 196/2019 e produto adaptado
A14: Expansão: aquisição adicional sobre a de clínicas médicas | B14: % | C14: 0.3 | D14: 0.5 | E14: 0.8 | F14: =CHOOSE($C$3,C14,D14,E14) | G14: Clinicorp e Simples Dental mostram mercado grande e já disputado
A15: Mercado endereçável: clínicas odontológicas com 2 ou mais dentistas | B15: clínicas | C15: 8000 | D15: 15000 | E15: 25000 | F15: =CHOOSE($C$3,C15,D15,E15) | G15: pesquisa/clinicas.md: 191,7 mil CNPJs odontológicos e Clinicorp com mais de 30 mil clínicas; endereçáveis ao ticket de R$ 2.900 ou mais. Estimativa
A16: Custo único da expansão (regras, produto, jurídico) | B16: R$ | C16: 400000 | D16: 300000 | E16: 200000 | F16: =CHOOSE($C$3,C16,D16,E16) | G16: Como no v2.1
A17: Indicação: novas clínicas por mês, como % da base ativa | B17: % | C17: 0.004 | D17: 0.008 | E17: 0.012 | F17: =CHOOSE($C$3,C17,D17,E17) | G17: Gestores de clínica conversam menos entre si do que médicos; abaixo do v2.1 (1%)
A18: Parcerias: multiplicador sobre o plano de parcerias | B18: x | C18: 0.6 | D18: 1 | E18: 1.3 | F18: =CHOOSE($C$3,C18,D18,E18) | G18: Softwares de gestão (Feegow, iClinic, Clinicorp), contadores e consultorias de clínicas
A20: 2. Decisões por ano (iguais nos três cenários)
C21: Ano 1 | D21: Ano 2 | E21: Ano 3 | F21: Ano 4 | G21: Ano 5 | H21: Ano 6 | I21: Ano 7 | J21: Fonte
A22: Orçamento de mídia paga por mês (gera reuniões com gestores) | B22: R$ | C22: 15000 | D22: 30000 | E22: 50000 | F22: 80000 | G22: 110000 | H22: 140000 | I22: 170000 | J22: Decisão; metade do Modelo B, porque a venda é ativa
A23: Duplas de venda ativa (SDR e executivo) | B23: duplas | C23: 1 | D23: 2 | E23: 4 | F23: 6 | G23: 8 | H23: 10 | I23: 12 | J23: Decisão; uma dupla nova produz 50% no ano em que entra
A24: Novas clínicas por parcerias por mês (antes do multiplicador) | B24: clínicas | C24: 0 | D24: 1 | E24: 2 | F24: 3 | G24: 4 | H24: 5 | I24: 6 | J24: Suposição sem evidência de canal; integração com softwares de gestão só a partir do ano 2
A25: Produto, engenharia e IA (pessoas) | B25: pessoas | C25: 4 | D25: 6 | E25: 8 | F25: 10 | G25: 12 | H25: 13 | I25: 14 | J25: Menos que no v2.1: um só tipo de cliente
A26: Marketing, pré-venda inbound e sucesso do cliente (pessoas) | B26: pessoas | C26: 1 | D26: 2 | E26: 3 | F26: 4 | G26: 5 | H26: 6 | I26: 7 | J26: Fecha os contatos que vêm da mídia
A27: Administrativo, jurídico e conformidade (pessoas) | B27: pessoas | C27: 1 | D27: 2 | E27: 3 | F27: 4 | G27: 6 | H27: 7 | I27: 8 | J27: Plano de contratação
A28: Pró-labore por fundador por mês | B28: R$ | C28: 5000 | D28: 10000 | E28: 15000 | F28: 15000 | G28: 18000 | H28: 18000 | I28: 20000 | J28: Como no v2.1 (6 fundadores)
A30: 3. Custos de pessoas e despesas gerais
A31: Premissa | B31: Unidade | C31: Conservador | D31: Base | E31: Otimista | F31: Usado | G31: Fonte ou justificativa
A32: Custo mensal por pessoa de produto e engenharia (com encargos) | B32: R$ | C32: 20000 | D32: 18000 | E32: 16000 | F32: =CHOOSE($C$3,C32,D32,E32) | G32: Como no v2.1
A33: Custo mensal de uma dupla de venda (SDR e executivo, com comissão) | B33: R$ | C33: 24000 | D33: 22000 | E33: 20000 | F33: =CHOOSE($C$3,C33,D33,E33) | G33: SDR de R$ 7 mil e executivo de R$ 13 mil com encargos, mais comissão
A34: Custo mensal por pessoa de marketing e sucesso do cliente | B34: R$ | C34: 11000 | D34: 10000 | E34: 9000 | F34: =CHOOSE($C$3,C34,D34,E34) | G34: Como vendas e marketing no v2.1
A35: Custo mensal por pessoa administrativa e jurídica | B35: R$ | C35: 13000 | D35: 12000 | E35: 11000 | F35: =CHOOSE($C$3,C35,D35,E35) | G35: Como no v2.1
A36: Número de fundadores | B36: pessoas | C36: 6 | D36: 6 | E36: 6 | F36: =CHOOSE($C$3,C36,D36,E36) | G36: Grupo 1
A37: Outras despesas fixas por mês (ferramentas, jurídico, contabilidade) | B37: R$ | C37: 20000 | D37: 15000 | E37: 12000 | F37: =CHOOSE($C$3,C37,D37,E37) | G37: Como no v2.1
A38: Outras despesas variáveis | B38: % da receita | C38: 0.04 | D38: 0.03 | E38: 0.025 | F38: =CHOOSE($C$3,C38,D38,E38) | G38: Como no v2.1
A39: Marca, eventos e conteúdo próprio | B39: % da mídia | C39: 0.1 | D39: 0.08 | E39: 0.06 | F39: =CHOOSE($C$3,C39,D39,E39) | G39: Feiras de gestão de clínicas e conteúdo para diretores técnicos
A41: 4. Aquisição
A42: Premissa | B42: Unidade | C42: Conservador | D42: Base | E42: Otimista | F42: Usado | G42: Fonte ou justificativa
A43: Custo de mídia por clínica fechada via inbound | B43: R$ | C43: 30000 | D43: 22000 | E43: 15000 | F43: =CHOOSE($C$3,C43,D43,E43) | G43: Calibrado para o CAC total do base ficar em cerca de 9,5 meses de contribuição (mesmo método da regra pré-registrada do v2.1); a confirmar no teste de aquisição
A44: Clínicas fechadas por dupla de venda ativa por mês (em ritmo pleno) | B44: clínicas | C44: 0.7 | D44: 1 | E44: 1.5 | F44: =CHOOSE($C$3,C44,D44,E44) | G44: Calibrado como o CAC de mídia: R$ 22 mil por fechamento no base. Equivale a cerca de R$ 640 mil de receita anual nova por executivo
A45: Custo por clínica vinda de parceria (comissão) | B45: R$ | C45: 11000 | D45: 9000 | E45: 7000 | F45: =CHOOSE($C$3,C45,D45,E45) | G45: Cerca de 20% da receita do primeiro ano, como em programas de revenda de software
...

Sheet Unidade
A1: Economia por clínica, por plano (cenário selecionado)
A2: Contribuição = mensalidade menos impostos (alíquota cheia), meios de pagamento, custo direto e parte do especialista. LTV = contribuição / churn + taxa de implantação - custo de implantação (sem receita de expansão).
A4: Plano | B4: Mensalidade | C4: Contribuição mensal | D4: Margem de contribuição | E4: Churn mensal | F4: Vida média (meses) | G4: LTV | H4: LTV/CAC (CAC total do ano 5) | I4: Recuperação do CAC (meses) | J4: Margem bruta do plano
A5: Clínica Essencial | B5: =Premissas!$F$54 | C5: =B5*(1-Premissas!$F$10-Premissas!$F$11)-Premissas!$F$58-Premissas!$F$50/Premissas!$F$59 | D5: =C5/B5 | E5: =Premissas!$F$57 | F5: =1/E5 | G5: =C5/E5+Premissas!$F$55-Premissas!$F$51 | H5: =G5/$B$11 | I5: =$B$11/C5 | J5: =C5/(B5*(1-Premissas!$F$10-Premissas!$F$11))
A6: Clínica Pro | B6: =Premissas!$F$60 | C6: =B6*(1-Premissas!$F$10-Premissas!$F$11)-Premissas!$F$64-Premissas!$F$50/Premissas!$F$65 | D6: =C6/B6 | E6: =Premissas!$F$63 | F6: =1/E6 | G6: =C6/E6+Premissas!$F$61-Premissas!$F$51 | H6: =G6/$B$11 | I6: =$B$11/C6 | J6: =C6/(B6*(1-Premissas!$F$10-Premissas!$F$11))
A7: Rede | B7: =Premissas!$F$66 | C7: =B7*(1-Premissas!$F$10-Premissas!$F$11)-Premissas!$F$70-Premissas!$F$50/Premissas!$F$71 | D7: =C7/B7 | E7: =Premissas!$F$69 | F7: =1/E7 | G7: =C7/E7+Premissas!$F$67-Premissas!$F$51 | H7: =G7/$B$11 | I7: =$B$11/C7 | J7: =C7/(B7*(1-Premissas!$F$10-Premissas!$F$11))
A8: Ponderado pelo mix de clínicas novas | B8: =Premissas!$F$56*B5+Premissas!$F$62*B6+Premissas!$F$68*B7 | C8: =Premissas!$F$56*C5+Premissas!$F$62*C6+Premissas!$F$68*C7 | G8: =Premissas!$F$56*G5+Premissas!$F$62*G6+Premissas!$F$68*G7 | H8: =G8/$B$11 | I8: =$B$11/C8
A11: CAC total no ano 5 (gasto de aquisição / clínicas novas) | B11: =SUMIF('Modelo C'!$C$3:$CH$3,5,'Modelo C'!$C$72:$CH$72)/SUMIF('Modelo C'!$C$3:$CH$3,5,'Modelo C'!$C$15:$CH$15)
A12: CAC só de mídia (comparável ao v2.1) | B12: =Premissas!$F$43
A13: CAC total no ano 2 | B13: =SUMIF('Modelo C'!$C$3:$CH$3,2,'Modelo C'!$C$72:$CH$72)/SUMIF('Modelo C'!$C$3:$CH$3,2,'Modelo C'!$C$15:$CH$15)

Sheet Modelo C
A1: Modelo C: agência operada por agentes para clínicas · mês a mês
A2: Mês | C2: 1 | D2: 2 | E2: 3 | F2: 4 | G2: 5 | H2: 6 | I2: 7 | J2: 8 | K2: 9 | L2: 10 | M2: 11 | N2: 12 | O2: 13 | P2: 14 | Q2: 15 | R2: 16 | S2: 17 | T2: 18 | U2: 19 | V2: 20 | W2: 21 | X2: 22 | Y2: 23 | Z2: 24 | AA2: 25 | AB2: 26 | AC2: 27 | AD2: 28 | AE2: 29 | AF2: 30 | AG2: 31 | AH2: 32 | AI2: 33 | AJ2: 34 | AK2: 35 | AL2: 36 | AM2: 37 | AN2: 38 | AO2: 39 | AP2: 40 | AQ2: 41 | AR2: 42 | AS2: 43 | AT2: 44 | AU2: 45 | AV2: 46 | AW2: 47 | AX2: 48 | AY2: 49 | AZ2: 50 | BA2: 51 | BB2: 52 | BC2: 53 | BD2: 54 | BE2: 55 | BF2: 56 | BG2: 57 | BH2: 58 | BI2: 59 | BJ2: 60 | BK2: 61 | BL2: 62 | BM2: 63 | BN2: 64 | BO2: 65 | BP2: 66 | BQ2: 67 | BR2: 68 | BS2: 69 | BT2: 70 | BU2: 71 | BV2: 72 | BW2: 73 | BX2: 74 | BY2: 75 | BZ2: 76 | CA2: 77 | CB2: 78 | CC2: 79 | CD2: 80 | CE2: 81 | CF2: 82 | CG2: 83 | CH2: 84
A3: Ano | C3: =ROUNDUP(C2/12,0) | D3: =ROUNDUP(D2/12,0) | E3: =ROUNDUP(E2/12,0) | F3: =ROUNDUP(F2/12,0) | G3: =ROUNDUP(G2/12,0) | H3: =ROUNDUP(H2/12,0) | I3: =ROUNDUP(I2/12,0) | J3: =ROUNDUP(J2/12,0) | ... CH3: =ROUNDUP(CH2/12,0)
A4: Venda ativa (1 a partir do lançamento) | C4: =IF(C2>=Premissas!$F$8,1,0) | D4: =IF(D2>=Premissas!$F$8,1,0) | E4: =IF(E2>=Premissas!$F$8,1,0) | F4: =IF(F2>=Premissas!$F$8,1,0) | G4: =IF(G2>=Premissas!$F$8,1,0) | H4: =IF(H2>=Premissas!$F$8,1,0) | I4: =IF(I2>=Premissas!$F$8,1,0) | J4: =IF(J2>=Premissas!$F$8,1,0) | ... CH4: =IF(CH2>=Premissas!$F$8,1,0)
A5: Fator de expansão para clínicas odontológicas | C5: =IF(C2>=Premissas!$F$13,1+Premissas!$F$14,1) | D5: =IF(D2>=Premissas!$F$13,1+Premissas!$F$14,1) | E5: =IF(E2>=Premissas!$F$13,1+Premissas!$F$14,1) | F5: =IF(F2>=Premissas!$F$13,1+Premissas!$F$14,1) | G5: =IF(G2>=Premissas!$F$13,1+Premissas!$F$14,1) | H5: =IF(H2>=Premissas!$F$13,1+Premissas!$F$14,1) | I5: =IF(I2>=Premissas!$F$13,1+Premissas!$F$14,1) | J5: =IF(J2>=Premissas!$F$13,1+Premissas!$F$14,1) | ... CH5: =IF(CH2>=Premissas!$F$13,1+Premissas!$F$14,1)
A7: Aquisição
A8: Mídia paga no mês | C8: =INDEX(Premissas!$C$22:$I$22,1,C3)*C4*C5 | D8: =INDEX(Premissas!$C$22:$I$22,1,D3)*D4*D5 | E8: =INDEX(Premissas!$C$22:$I$22,1,E3)*E4*E5 | F8: =INDEX(Premissas!$C$22:$I$22,1,F3)*F4*F5 | G8: =INDEX(Premissas!$C$22:$I$22,1,G3)*G4*G5 | H8: =INDEX(Premissas!$C$22:$I$22,1,H3)*H4*H5 | I8: =INDEX(Premissas!$C$22:$I$22,1,I3)*I4*I5 | J8: =INDEX(Premissas!$C$22:$I$22,1,J3)*J4*J5 | ... CH8: =INDEX(Premissas!$C$22:$I$22,1,CH3)*CH4*CH5
A9: Clínicas novas por mídia (inbound) | C9: =C8/Premissas!$F$43 | D9: =D8/Premissas!$F$43 | E9: =E8/Premissas!$F$43 | F9: =F8/Premissas!$F$43 | G9: =G8/Premissas!$F$43 | H9: =H8/Premissas!$F$43 | I9: =I8/Premissas!$F$43 | J9: =J8/Premissas!$F$43 | ... CH9: =CH8/Premissas!$F$43
A10: Duplas de venda contratadas | C10: =INDEX(Premissas!$C$23:$I$23,1,C3)*C5 | D10: =INDEX(Premissas!$C$23:$I$23,1,D3)*D5 | E10: =INDEX(Premissas!$C$23:$I$23,1,E3)*E5 | F10: =INDEX(Premissas!$C$23:$I$23,1,F3)*F5 | G10: =INDEX(Premissas!$C$23:$I$23,1,G3)*G5 | H10: =INDEX(Premissas!$C$23:$I$23,1,H3)*H5 | I10: =INDEX(Premissas!$C$23:$I$23,1,I3)*I5 | J10: =INDEX(Premissas!$C$23:$I$23,1,J3)*J5 | ... CH10: =INDEX(Premissas!$C$23:$I$23,1,CH3)*CH5
A11: Duplas em ritmo pleno (as novas do ano produzem 50%) | C11: =(INDEX(Premissas!$C$23:$I$23,1,C3)+IF(C3>1,INDEX(Premissas!$C$23:$I$23,1,C3-1),0))/2*C5 | D11: =(INDEX(Premissas!$C$23:$I$23,1,D3)+IF(D3>1,INDEX(Premissas!$C$23:$I$23,1,D3-1),0))/2*D5 | E11: =(INDEX(Premissas!$C$23:$I$23,1,E3)+IF(E3>1,INDEX(Premissas!$C$23:$I$23,1,E3-1),0))/2*E5 | F11: =(INDEX(Premissas!$C$23:$I$23,1,F3)+IF(F3>1,INDEX(Premissas!$C$23:$I$23,1,F3-1),0))/2*F5 | G11: =(INDEX(Premissas!$C$23:$I$23,1,G3)+IF(G3>1,INDEX(Premissas!$C$23:$I$23,1,G3-1),0))/2*G5 | H11: =(INDEX(Premissas!$C$23:$I$23,1,H3)+IF(H3>1,INDEX(Premissas!$C$23:$I$23,1,H3-1),0))/2*H5 | I11: =(INDEX(Premissas!$C$23:$I$23,1,I3)+IF(I3>1,INDEX(Premissas!$C$23:$I$23,1,I3-1),0))/2*I5 | J11: =(INDEX(Premissas!$C$23:$I$23,1,J3)+IF(J3>1,INDEX(Premissas!$C$23:$I$23,1,J3-1),0))/2*J5 | ... CH11: =(INDEX(Premissas!$C$23:$I$23,1,CH3)+IF(CH3>1,INDEX(Premissas!$C$23:$I$23,1,CH3-1),0))/2*CH5
A12: Clínicas novas por venda ativa | C12: =C11*Premissas!$F$44*C4 | D12: =D11*Premissas!$F$44*D4 | E12: =E11*Premissas!$F$44*E4 | F12: =F11*Premissas!$F$44*F4 | G12: =G11*Premissas!$F$44*G4 | H12: =H11*Premissas!$F$44*H4 | I12: =I11*Premissas!$F$44*I4 | J12: =J11*Premissas!$F$44*J4 | ... CH12: =CH11*Premissas!$F$44*CH4
A13: Clínicas novas por parcerias | C13: =INDEX(Premissas!$C$24:$I$24,1,C3)*Premissas!$F$18*C4*C5 | D13: =INDEX(Premissas!$C$24:$I$24,1,D3)*Premissas!$F$18*D4*D5 | E13: =INDEX(Premissas!$C$24:$I$24,1,E3)*Premissas!$F$18*E4*E5 | F13: =INDEX(Premissas!$C$24:$I$24,1,F3)*Premissas!$F$18*F4*F5 | G13: =INDEX(Premissas!$C$24:$I$24,1,G3)*Premissas!$F$18*G4*G5 | H13: =INDEX(Premissas!$C$24:$I$24,1,H3)*Premissas!$F$18*H4*H5 | I13: =INDEX(Premissas!$C$24:$I$24,1,I3)*Premissas!$F$18*I4*I5 | J13: =INDEX(Premissas!$C$24:$I$24,1,J3)*Premissas!$F$18*J4*J5 | ... CH13: =INDEX(Premissas!$C$24:$I$24,1,CH3)*Premissas!$F$18*CH4*CH5
A14: Clínicas novas por indicação | C14: =0 | D14: =C36*Premissas!$F$17*D4 | E14: =D36*Premissas!$F$17*E4 | F14: =E36*Premissas!$F$17*F4 | G14: =F36*Premissas!$F$17*G4 | H14: =G36*Premissas!$F$17*H4 | I14: =H36*Premissas!$F$17*I4 | J14: =I36*Premissas!$F$17*J4 | K14: =J36*Premissas!$F$17*K4 | ... CH14: =CG36*Premissas!$F$17*CH4
A15: Clínicas novas no mês | C15: =C9+C12+C13+C14 | D15: =D9+D12+D13+D14 | E15: =E9+E12+E13+E14 | F15: =F9+F12+F13+F14 | G15: =G9+G12+G13+G14 | H15: =H9+H12+H13+H14 | I15: =I9+I12+I13+I14 | J15: =J9+J12+J13+J14 | ... CH15: =CH9+CH12+CH13+CH14
A17: Plano Clínica Essencial
A18: Participação nas novas | C18: =Premissas!$F$56 | D18: =Premissas!$F$56 | E18: =Premissas!$F$56 | F18: =Premissas!$F$56 | G18: =Premissas!$F$56 | H18: =Premissas!$F$56 | I18: =Premissas!$F$56 | J18: =Premissas!$F$56 | ... CH18: =Premissas!$F$56
A19: Novas | C19: =C15*C18 | D19: =D15*D18 | E19: =E15*E18 | F19: =F15*F18 | G19: =G15*G18 | H19: =H15*H18 | I19: =I15*I18 | J19: =J15*J18 | ... CH19: =CH15*CH18
A20: Canceladas | C20: =0*Premissas!$F$57 | D20: =C21*Premissas!$F$57 | E20: =D21*Premissas!$F$57 | F20: =E21*Premissas!$F$57 | G20: =F21*Premissas!$F$57 | H20: =G21*Premissas!$F$57 | I20: =H21*Premissas!$F$57 | J20: =I21*Premissas!$F$57 | K20: =J21*Premissas!$F$57 | ... CH20: =CG21*Premissas!$F$57
A21: Ativas no fim do mês | C21: =0+C19-C20 | D21: =C21+D19-D20 | E21: =D21+E19-E20 | F21: =E21+F19-F20 | G21: =F21+G19-G20 | H21: =G21+H19-H20 | I21: =H21+I19-I20 | J21: =I21+J19-J20 | K21: =J21+K19-K20 | ... CH21: =CG21+CH19-CH20
A23: Plano Clínica Pro
A24: Participação nas novas | C24: =Premissas!$F$62+IF(C2<13,Premissas!$F$68,0) | D24: =Premissas!$F$62+IF(D2<13,Premissas!$F$68,0) | E24: =Premissas!$F$62+IF(E2<13,Premissas!$F$68,0) | F24: =Premissas!$F$62+IF(F2<13,Premissas!$F$68,0) | G24: =Premissas!$F$62+IF(G2<13,Premissas!$F$68,0) | H24: =Premissas!$F$62+IF(H2<13,Premissas!$F$68,0) | I24: =Premissas!$F$62+IF(I2<13,Premissas!$F$68,0) | J24: =Premissas!$F$62+IF(J2<13,Premissas!$F$68,0) | ... CH24: =Premissas!$F$62+IF(CH2<13,Premissas!$F$68,0)
A25: Novas | C25: =C15*C24 | D25: =D15*D24 | E25: =E15*E24 | F25: =F15*F24 | G25: =G15*G24 | H25: =H15*H24 | I25: =I15*I24 | J25: =J15*J24 | ... CH25: =CH15*CH24
A26: Canceladas | C26: =0*Premissas!$F$63 | D26: =C27*Premissas!$F$63 | E26: =D27*Premissas!$F$63 | F26: =E27*Premissas!$F$63 | G26: =F27*Premissas!$F$63 | H26: =G27*Premissas!$F$63 | I26: =H27*Premissas!$F$63 | J26: =I27*Premissas!$F$63 | K26: =J27*Premissas!$F$63 | ... CH26: =CG27*Premissas!$F$63
A27: Ativas no fim do mês | C27: =0+C25-C26 | D27: =C27+D25-D26 | E27: =D27+E25-E26 | F27: =E27+F25-F26 | G27: =F27+G25-G26 | H27: =G27+H25-H26 | I27: =H27+I25-I26 | J27: =I27+J25-J26 | K27: =J27+K25-K26 | ... CH27: =CG27+CH25-CH26
A29: Plano Rede
A30: Participação nas novas | C30: =IF(C2>=13,Premissas!$F$68,0) | D30: =IF(D2>=13,Premissas!$F$68,0) | E30: =IF(E2>=13,Premissas!$F$68,0) | F30: =IF(F2>=13,Premissas!$F$68,0) | G30: =IF(G2>=13,Premissas!$F$68,0) | H30: =IF(H2>=13,Premissas!$F$68,0) | I30: =IF(I2>=13,Premissas!$F$68,0) | J30: =IF(J2>=13,Premissas!$F$68,0) | ... CH30: =IF(CH2>=13,Premissas!$F$68,0)
A31: Novas | C31: =C15*C30 | D31: =D15*D30 | E31: =E15*E30 | F31: =F15*F30 | G31: =G15*G30 | H31: =H15*H30 | I31: =I15*I30 | J31: =J15*J30 | ... CH31: =CH15*CH30
A32: Canceladas | C32: =0*Premissas!$F$69 | D32: =C33*Premissas!$F$69 | E32: =D33*Premissas!$F$69 | F32: =E33*Premissas!$F$69 | G32: =F33*Premissas!$F$69 | H32: =G33*Premissas!$F$69 | I32: =H33*Premissas!$F$69 | J32: =I33*Premissas!$F$69 | K32: =J33*Premissas!$F$69 | ... CH32: =CG33*Premissas!$F$69
A33: Ativas no fim do mês | C33: =0+C31-C32 | D33: =C33+D31-D32 | E33: =D33+E31-E32 | F33: =E33+F31-F32 | G33: =F33+G31-G32 | H33: =G33+H31-H32 | I33: =H33+I31-I32 | J33: =I33+J31-J32 | K33: =J33+K31-K32 | ... CH33: =CG33+CH31-CH32
A35: Clientes e receita
A36: Clínicas ativas | C36: =C21+C27+C33 | D36: =D21+D27+D33 | E36: =E21+E27+E33 | F36: =F21+F27+F33 | G36: =G21+G27+G33 | H36: =H21+H27+H33 | I36: =I21+I27+I33 | J36: =J21+J27+J33 | ... CH36: =CH21+CH27+CH33
A37: Clínicas canceladas no mês | C37: =C20+C26+C32 | D37: =D20+D26+D32 | E37: =E20+E26+E32 | F37: =F20+F26+F32 | G37: =G20+G26+G32 | H37: =H20+H26+H32 | I37: =I20+I26+I32 | J37: =J20+J26+J32 | ... CH37: =CH20+CH26+CH32
A38: Mercado endereçável no mês | C38: =Premissas!$F$12+IF(C2>=Premissas!$F$13,Premissas!$F$15,0) | D38: =Premissas!$F$12+IF(D2>=Premissas!$F$13,Premissas!$F$15,0) | E38: =Premissas!$F$12+IF(E2>=Premissas!$F$13,Premissas!$F$15,0) | F38: =Premissas!$F$12+IF(F2>=Premissas!$F$13,Premissas!$F$15,0) | G38: =Premissas!$F$12+IF(G2>=Premissas!$F$13,Premissas!$F$15,0) | H38: =Premissas!$F$12+IF(H2>=Premissas!$F$13,Premissas!$F$15,0) | I38: =Premissas!$F$12+IF(I2>=Premissas!$F$13,Premissas!$F$15,0) | J38: =Premissas!$F$12+IF(J2>=Premissas!$F$13,Premissas!$F$15,0) | ... CH38: =Premissas!$F$12+IF(CH2>=Premissas!$F$13,Premissas!$F$15,0)
A39: Participação no mercado endereçável | C39: =C36/C38 | D39: =D36/D38 | E39: =E36/E38 | F39: =F36/F38 | G39: =G36/G38 | H39: =H36/H38 | I39: =I36/I38 | J39: =J36/J38 | ... CH39: =CH36/CH38
A40: Receita de mensalidades dos planos | C40: =C21*Premissas!$F$54+C27*Premissas!$F$60+C33*Premissas!$F$66 | D40: =D21*Premissas!$F$54+D27*Premissas!$F$60+D33*Premissas!$F$66 | E40: =E21*Premissas!$F$54+E27*Premissas!$F$60+E33*Premissas!$F$66 | F40: =F21*Premissas!$F$54+F27*Premissas!$F$60+F33*Premissas!$F$66 | G40: =G21*Premissas!$F$54+G27*Premissas!$F$60+G33*Premissas!$F$66 | H40: =H21*Premissas!$F$54+H27*Premissas!$F$60+H33*Premissas!$F$66 | I40: =I21*Premissas!$F$54+I27*Premissas!$F$60+I33*Premissas!$F$66 | J40: =J21*Premissas!$F$54+J27*Premissas!$F$60+J33*Premissas!$F$66 | ... CH40: =CH21*Premissas!$F$54+CH27*Premissas!$F$60+CH33*Premissas!$F$66
A41: Receita de expansão (médicos e unidades adicionais) | C41: =0 | D41: =C41*(1-IF(C36>0,D37/C36,0))+C40*Premissas!$F$52 | E41: =D41*(1-IF(D36>0,E37/D36,0))+D40*Premissas!$F$52 | F41: =E41*(1-IF(E36>0,F37/E36,0))+E40*Premissas!$F$52 | G41: =F41*(1-IF(F36>0,G37/F36,0))+F40*Premissas!$F$52 | H41: =G41*(1-IF(G36>0,H37/G36,0))+G40*Premissas!$F$52 | I41: =H41*(1-IF(H36>0,I37/H36,0))+H40*Premissas!$F$52 | J41: =I41*(1-IF(I36>0,J37/I36,0))+I40*Premissas!$F$52 | K41: =J41*(1-IF(J36>0,K37/J36,0))+J40*Premissas!$F$52 | ... CH41: =CG41*(1-IF(CG36>0,CH37/CG36,0))+CG40*Premissas!$F$52
A42: Receita de implantação | C42: =C19*Premissas!$F$55+C25*Premissas!$F$61+C31*Premissas!$F$67 | D42: =D19*Premissas!$F$55+D25*Premissas!$F$61+D31*Premissas!$F$67 | E42: =E19*Premissas!$F$55+E25*Premissas!$F$61+E31*Premissas!$F$67 | F42: =F19*Premissas!$F$55+F25*Premissas!$F$61+F31*Premissas!$F$67 | G42: =G19*Premissas!$F$55+G25*Premissas!$F$61+G31*Premissas!$F$67 | H42: =H19*Premissas!$F$55+H25*Premissas!$F$61+H31*Premissas!$F$67 | I42: =I19*Premissas!$F$55+I25*Premissas!$F$61+I31*Premissas!$F$67 | J42: =J19*Premissas!$F$55+J25*Premissas!$F$61+J31*Premissas!$F$67 | ... CH42: =CH19*Premissas!$F$55+CH25*Premissas!$F$61+CH31*Premissas!$F$67
A43: Receita bruta | C43: =C40+C41+C42 | D43: =D40+D41+D42 | E43: =E40+E41+E42 | F43: =F40+F41+F42 | G43: =G40+G41+G42 | H43: =H40+H41+H42 | I43: =I40+I41+I42 | J43: =J40+J41+J42 | ... CH43: =CH40+CH41+CH42
A44: Receita recorrente mensal (mensalidades + expansão) | C44: =C40+C41 | D44: =D40+D41 | E44: =E40+E41 | F44: =F40+F41 | G44: =G40+G41 | H44: =H40+H41 | I44: =I40+I41 | J44: =J40+J41 | ... CH44: =CH40+CH41
A45: Receita recorrente anualizada (MRR × 12) | C45: =C44*12 | D45: =D44*12 | E45: =E44*12 | F45: =F44*12 | G45: =G44*12 | H45: =H44*12 | I45: =I44*12 | J45: =J44*12 | ... CH45: =CH44*12
...

Sheet Cenarios
A1: Cenários e testes de estresse (valores gerados por sensibilidade_clinicas.py)
A3: Indicador | B3: Conservador | C3: Base | D3: Otimista
A4: Receita recorrente anualizada no ano 5 | B4: 12231293 | C4: 28891733 | D4: 67158967
A5: Receita recorrente anualizada no ano 7 | B5: 22843376 | C5: 57646412 | D5: 1.4969032e+08
A6: Mês de equilíbrio (EBITDA positivo daí em diante) | B6: não chega | C6: 53 | D6: 30
A7: Capital necessário (pior caixa acumulado) | B7: 42026404 | C7: 10834474 | D7: 4266071
A8: Margem bruta no ano 5 | B8: 0.4629496 | C8: 0.64834889 | D8: 0.75451947
A9: LTV/CAC ponderado pelo mix, com CAC total do ano 5 | B9: 1.3143151 | C9: 4.6001893 | D9: 14.575818
A10: Recuperação do CAC total, ponderada (meses) | B10: 21.295173 | C10: 8.9087062 | D10: 4.4966578
A11: CAC total no ano 5 | B11: 33257.063 | C11: 20550.306 | D11: 12658.85
A12: Mês em que a receita anualizada chega a R$ 50 mi | B12: não chega | C12: 78 | D12: 53
A13: Participação no mercado nesse mês | C13: 0.024847195 | D13: 0.013593309
A14: Clínicas ativas no ano 5 | B14: 235.72847 | C14: 509.9368 | D14: 1072.1884
A16: Testes de estresse (cenário base, uma mudança por vez, salvo indicação)
A17: Teste | B17: Receita recorrente anualizada no ano 5 | C17: Receita recorrente anualizada no ano 7 | D17: Mês de equilíbrio (EBITDA positivo daí em diante) | E17: Capital necessário (pior caixa acumulado) | F17: Margem bruta no ano 5 | G17: LTV/CAC ponderado pelo mix, com CAC total do ano 5 | H17: Recuperação do CAC total, ponderada (meses) | I17: CAC total no ano 5 | J17: Mês em que a receita anualizada chega a R$ 50 mi | K17: Participação no mercado nesse mês | L17: Clínicas ativas no ano 5
A18: Churn 50% maior em todos os planos | B18: 24053424 | C18: 45040122 | D18: 63 | E18: 12776473 | F18: 0.64755799 | G18: 3.0613112 | H18: 9.0379449 | I18: 20848.43 | J18: não chega | L18: 424.71746
A19: CAC 50% maior (mídia e venda ativa) | B19: 21713965 | C19: 43192050 | D19: 66 | E19: 15954067 | F19: 0.64837667 | G19: 3.4728448 | H19: 11.800624 | I19: 27221.285 | J19: não chega | L19: 383.20716
A20: Metade das clínicas por especialista | B20: 28891733 | C20: 57646412 | D20: 67 | E20: 17020240 | F20: 0.47747699 | G20: 3.3025606 | H20: 12.58105 | I20: 20550.306 | J20: 78 | K20: 0.024847195 | L20: 509.9368
A21: O dobro de clínicas por especialista | B21: 28891733 | C21: 57646412 | D21: 50 | E21: 9142706.4 | F21: 0.73378485 | G21: 5.2490036 | H21: 7.7740967 | I21: 20550.306 | J21: 78 | K21: 0.024847195 | L21: 509.9368
A22: Preços 20% menores | B22: 23113386 | C22: 46117129 | D22: 68 | E22: 17307173 | F22: 0.57313144 | G22: 3.2553403 | H22: 12.742427 | I22: 20550.306 | J22: não chega | L22: 509.9368
A23: Sem receita de expansão | B23: 26778325 | C23: 52232884 | D23: 55 | E23: 11499535 | F23: 0.65390378 | G23: 4.6001893 | H23: 8.9087062 | I23: 20550.306 | J23: 82 | K23: 0.02715017 | L23: 509.9368
A24: Sem clínicas odontológicas | B24: 19804377 | C24: 38811646 | D24: 63 | E24: 11507282 | F24: 0.64836444 | G24: 4.4183089 | H24: 9.2754345 | I24: 21396.263 | J24: não chega | L24: 348.29739
A25: Mercado de clínicas médicas no conservador e sem odontologia | B25: 19804377 | C25: 38811646 | D25: 63 | E25: 11507282 | F25: 0.64836444 | G25: 4.4183089 | H25: 9.2754345 | I25: 21396.263 | J25: não chega | L25: 348.29739
A26: CAC da pesquisa de clínicas (cerca de R$ 12 mil, 40% menor) | B26: 43247269 | C26: 86555135 | D26: 40 | E26: 6699780 | F26: 0.64832098 | G26: 6.8134214 | H26: 6.014854 | I26: 13874.865 | J26: 64 | K26: 0.025312628 | L26: 763.39609
A27: Churn e CAC 50% maiores juntos | B27: 18076968 | C27: 33732332 | D27: 79 | E27: 20316543 | F27: 0.64758598 | G27: 2.3088836 | H27: 11.983264 | I27: 27642.594 | J27: não chega | L27: 319.14417
A28: Só clínicas de 5 ou mais médicos (sem o Essencial; mercado pela metade) | B28: 39610068 | C28: 80113970 | D28: 41 | E28: 7382451.6 | F28: 0.66349095 | G28: 6.7214824 | H28: 6.5981926 | I28: 20475.731 | J28: 67 | K28: 0.038819707 | L28: 532.12464
A29: Só 5 ou mais médicos, com CAC 30% maior (venda mais longa) | B29: 32798250 | C29: 66210848 | D29: 50 | E29: 9083670.6 | F29: 0.66349956 | G29: 5.5842385 | H29: 7.9419307 | I29: 24645.664 | J29: 74 | K29: 0.038931488 | L29: 440.57679
A31: Condições mínimas: multiplicador sobre a premissa do cenário para passar no critério (uma variável por vez)
A32: Critério e variável | B32: No cenário base | C32: No conservador
A33: Margem de 70%: clínicas por especialista (× premissa) | B33: 1.44 | C33: não passa na grade
A34: Margem de 70%: preços (× premissa) | B34: 1.2 | C34: não passa na grade
A35: LTV/CAC de 3: churn máximo (× premissa) | B35: 1.54 | C35: não passa na grade
A36: LTV/CAC de 3: CAC máximo (× premissa) | B36: 1.92 | C36: não passa na grade
A37: Recuperação em 12 meses: CAC máximo (× premissa) | B37: 1.54 | C37: não passa na grade

Sheet Sensibilidade
A1: Sensibilidade no cenário base (valores gerados por script)
A3: Premissa (ordenada pelo impacto) | B3: Valor pessimista | C3: Valor otimista | D3: ARR ano 7 (pess.) | E3: ARR ano 7 (ot.) | F3: Capital (pess.) | G3: Capital (ot.) | H3: Margem ano 5 (pess. / ot.) | I3: LTV/CAC (pess. / ot.)
A4: CAC (×1,5 a ×0,67) | B4: 1.5 | C4: 0.67 | D4: 43192050 | E4: 79004349 | F4: 15954067 | G4: 7471590.8 | H4: 64.8% / 64.8% | I4: 3.5x / 6.2x
A5: Preços (×0,8 a ×1,2) | B5: 0.8 | C5: 1.2 | D5: 46117129 | E5: 69175694 | F5: 17307173 | G5: 8031472.5 | H5: 57.3% / 70.0% | I5: 3.3x / 5.9x
A6: Churn (todos os planos, ×0,67 a ×1,5) | B6: 1.5 | C6: 0.67 | D6: 45040122 | E6: 69421966 | F6: 12776473 | G6: 9739943.4 | H6: 64.8% / 64.9% | I6: 3.1x / 6.9x
A7: Clínicas por especialista (×0,67 a ×1,5) | B7: 0.67 | C7: 1.5 | D7: 57646412 | E7: 57646412 | F7: 13187199 | G7: 9552031.6 | H7: 56.4% / 70.5% | I7: 4.0x / 5.0x
A8: Receita de expansão (0% a 1% ao mês) | B8: 0 | C8: 0.01 | D8: 52232884 | E8: 61255430 | F8: 11499535 | G8: 10425254 | H8: 65.4% / 64.5% | I8: 4.6x / 4.6x
A9: Indicação (0,4% a 1,2% da base por mês) | B9: 0.004 | C9: 0.012 | D9: 53484425 | E9: 62362361 | F9: 11323903 | G9: 10355818 | H9: 64.8% / 64.8% | I9: 4.4x / 4.8x
A10: Custo do especialista (R$ 14 mil a R$ 10 mil) | B10: 14000 | C10: 10000 | D10: 57646412 | E10: 57646412 | F10: 11564804 | G10: 10153544 | H10: 62.0% / 67.7% | I10: 4.4x / 4.8x
A11: Custo de implantação (R$ 3.000 a R$ 1.000) | B11: 3000 | C11: 1000 | D11: 57646412 | E11: 57646412 | F11: 11505790 | G11: 10402974 | H11: 62.9% / 66.1% | I11: 4.5x / 4.6x
